Workbook

Sheet TUYẾN CHÍNH
C1: BẢNG CHẤM CÔNG LÁI TẢI TUYẾN CHÍNH T5.2026
C2: BSX | D2: Tải trọng | E2: Mã nv | F2: Họ tên | G2: Dự án | H2: 1 | I2: 2 | J2: 3 | K2: 4 | L2: 5 | M2: 6 | N2: 7 | O2: 8 | P2: 9 | Q2: 10 | R2: 11 | S2: 12 | T2: 13 | U2: 14 | V2: 15 | W2: 16 | X2: 17 | Y2: 18 | Z2: 19 | AA2: 20 | AB2: 21 | AC2: 22 | AD2: 23 | AE2: 24 | AF2: 25 | AG2: 26 | AH2: 27 | AI2: 28 | AJ2: 29 | AK2: 30 | AL2: 31 | AM2: Số công | AN2: Số chuyến | AP2: X | AQ2: Vận hành
H3: T6 | I3: T7 | J3: CN | K3: T2 | L3: T3 | M3: T4 | N3: T5 | O3: T6 | P3: T7 | Q3: CN | R3: T2 | S3: T3 | T3: T4 | U3: T5 | V3: T6 | W3: T7 | X3: CN | Y3: T2 | Z3: T3 | AA3: T4 | AB3: T5 | AC3: T6 | AD3: T7 | AE3: CN | AF3: T2 | AG3: T3 | AH3: T4 | AI3: T5 | AJ3: T6 | AK3: T7 | AL3: CN | AP3: C | AQ3: Chờ
A5: 1 | B5: 1 | C5: 29E12073 | D5: 15T | E5: XE00499 | F5: Trần Xuân Trường | H5: x | I5: x | J5: x | K5: x | L5: x | M5: x | N5: x | O5: x | P5: x | Q5: x | R5: x | S5: x | T5: x | U5: x | V5: x | W5: x | X5: x | Y5: x | Z5: x | AA5: x | AB5: x | AC5: x | AD5: x | AE5: x | AF5: x | AG5: x | AH5: x | AI5: x | AJ5: x | AK5: x | AL5: x | AM5: =COUNTIF(H5:AL5,"X")+COUNTIF(H5:AL5,"C") -> 31 | AP5: O | AQ5: Nghỉ
A6: 2 | B6: 1 | C6: 29E12073 | D6: 15T | E6: XE00934 | F6: Phan Văn Thành | H6: o | I6: x | J6: x | K6: x | L6: x | M6: x | N6: x | O6: x | P6: x | Q6: x | R6: o | S6: o | T6: o | U6: o | V6: o | W6: o | X6: o | Y6: o | Z6: o | AA6: o | AB6: o | AC6: o | AD6: o | AE6: o | AF6: o | AG6: o | AH6: o | AI6: o | AJ6: o | AK6: o | AL6: o | AM6: =COUNTIF(H6:AL6,"X")+COUNTIF(H6:AL6,"C") -> 9 | AO6: Có đơn xin NP
A7: 3 | B7: 1 | C7: 29E12047 | D7: 15T | E7: XE01506 | F7: Huỳnh Lê Trần Long | H7: x | I7: x | J7: x | K7: x | L7: x | M7: x | N7: x | O7: x | P7: x | Q7: x | R7: x | S7: x | T7: x | U7: x | V7: x | W7: x | X7: x | Y7: x | Z7: x | AA7: x | AB7: x | AC7: x | AD7: x | AE7: x | AF7: x | AG7: x | AH7: x | AI7: x | AJ7: x | AK7: x | AL7: x | AM7: =COUNTIF(H7:AL7,"X")+COUNTIF(H7:AL7,"C") -> 31
A8: 4 | B8: 1 | C8: 29E12047 | D8: 15T | E8: XE01507 | F8: Đặng Tuân | H8: x | I8: x | J8: x | K8: x | L8: x | M8: x | N8: x | O8: x | P8: x | Q8: x | R8: x | S8: x | T8: x | U8: x | V8: x | W8: x | X8: x | Y8: x | Z8: x | AA8: x | AB8: x | AC8: x | AD8: x | AE8: x | AF8: x | AG8: x | AH8: x | AI8: x | AJ8: x | AK8: x | AL8: x | AM8: =COUNTIF(H8:AL8,"X")+COUNTIF(H8:AL8,"C") -> 31
A9: 5 | B9: 1 | C9: 29K07924 | D9: 15T | E9: XE01102 | F9: Lê Thế Xuân | H9: x | I9: x | J9: x | K9: x | L9: x | M9: x | N9: x | O9: x | P9: x | Q9: x | R9: x | S9: x | T9: x | U9: x | V9: x | W9: x | X9: x | Y9: x | Z9: x | AA9: x | AB9: x | AC9: x | AD9: x | AE9: x | AF9: x | AG9: x | AH9: x | AI9: x | AJ9: x | AK9: x | AL9: x | AM9: =COUNTIF(H9:AL9,"X")+COUNTIF(H9:AL9,"C") -> 31
A10: 6 | B10: 1 | C10: 29K07924 | D10: 15T | E10: XE01315 | F10: Lê Xuân Tú | H10: x | I10: x | J10: x | K10: x | L10: x | M10: x | N10: x | O10: x | P10: x | Q10: x | R10: x | S10: x | T10: x | U10: x | V10: x | W10: x | X10: x | Y10: x | Z10: x | AA10: x | AB10: x | AC10: x | AD10: x | AE10: x | AF10: x | AG10: x | AH10: x | AI10: x | AJ10: x | AK10: x | AL10: x | AM10: =COUNTIF(H10:AL10,"X")+COUNTIF(H10:AL10,"C") -> 31
A11: 7 | B11: 1 | C11: 29E38345 | D11: 8T | E11: XE01551 | F11: Mai Tấn Toàn | H11: x | I11: x | J11: x | K11: x | L11: x | M11: x | N11: x | O11: x | P11: x | Q11: x | R11: x | S11: x | T11: x | U11: x | V11: x | W11: x | X11: x | Y11: x | Z11: x | AA11: x | AB11: x | AC11: x | AD11: x | AE11: x | AF11: x | AG11: x | AH11: x | AI11: x | AJ11: x | AK11: x | AL11: x | AM11: =COUNTIF(H11:AL11,"X")+COUNTIF(H11:AL11,"C") -> 31
A12: 8 | B12: 1 | C12: 29E38345 | D12: 8T | E12: XE01552 | F12: Nguyễn Khánh Phú | H12: x | I12: x | J12: x | K12: x | L12: x | M12: x | N12: x | O12: x | P12: x | Q12: x | R12: x | S12: x | T12: x | U12: x | V12: x | W12: x | X12: x | Y12: x | Z12: x | AA12: x | AB12: x | AC12: x | AD12: x | AE12: x | AF12: x | AG12: x | AH12: x | AI12: x | AJ12: x | AK12: x | AL12: x | AM12: =COUNTIF(H12:AL12,"X")+COUNTIF(H12:AL12,"C") -> 31
A13: 9 | B13: 1 | C13: 29H80501-29E08413 | D13: 15T-8T | E13: XE00873 | F13: Kiều Kim Tiến | H13: x | I13: x | J13: x | K13: x | L13: x | M13: x | N13: x | O13: x | P13: x | Q13: x | R13: x | S13: x | T13: x | U13: x | V13: x | W13: x | X13: x | Y13: x | Z13: x | AA13: x | AB13: x | AC13: x | AD13: x | AE13: x | AF13: x | AG13: x | AH13: C | AI13: C | AJ13: C | AK13: C | AL13: C | AM13: =COUNTIF(H13:AL13,"X")+COUNTIF(H13:AL13,"C") -> 31 | AN13: DC
A14: 10 | B14: 1 | C14: 29E08426 | D14: 15T | E14: XE01470 | F14: Trần Hữu Khánh | H14: x | I14: x | J14: x | K14: x | L14: x | M14: x | N14: x | O14: x | P14: x | Q14: x | R14: x | S14: x | T14: x | U14: x | V14: x | W14: C | X14: C | Y14: C | Z14: C | AA14: C | AB14: x | AC14: x | AD14: x | AE14: x | AF14: x | AG14: x | AH14: x | AI14: x | AJ14: x | AK14: x | AL14: X | AM14: =COUNTIF(H14:AL14,"X")+COUNTIF(H14:AL14,"C") -> 31
A15: 11 | C15: 29E08426 | D15: 15T | E15: XE01469 | F15: Nguyễn Bá Bảo | H15: x | I15: x | J15: x | K15: x | L15: x | M15: x | N15: x | O15: x | P15: x | Q15: x | R15: x | S15: x | T15: x | U15: x | V15: x | W15: C | X15: C | Y15: C | Z15: C | AA15: C | AB15: C | AC15: C | AD15: C | AE15: C | AF15: C | AG15: C | AH15: C | AI15: C | AJ15: C | AK15: C | AL15: C | AM15: =COUNTIF(H15:AL15,"X")+COUNTIF(H15:AL15,"C") -> 31
A16: 12 | B16: 1 | C16: 29E09603 | D16: 15T | E16: XE01390 | F16: Trương Cẩm Thành | H16: x | I16: x | J16: x | K16: x | L16: x | M16: x | N16: x | O16: x | P16: x | Q16: x | R16: x | S16: x | T16: x | U16: x | V16: x | W16: x | X16: x | Y16: x | Z16: x | AA16: x | AB16: x | AC16: x | AD16: x | AE16: x | AF16: x | AG16: x | AH16: x | AI16: x | AJ16: x | AK16: x | AL16: x | AM16: =COUNTIF(H16:AL16,"X")+COUNTIF(H16:AL16,"C") -> 31
A17: 13 | B17: 2 | C17: 29E08175 | D17: 15T | E17: XE01331 | F17: Bùi Văn Đào | H17: x | I17: x | J17: x | K17: x | L17: x | M17: x | N17: x | O17: x | P17: x | Q17: x | R17: x | S17: x | T17: x | U17: x | V17: x | W17: x | X17: x | Y17: x | Z17: x | AA17: x | AB17: x | AC17: x | AD17: x | AE17: x | AF17: x | AG17: x | AH17: x | AI17: x | AJ17: x | AK17: x | AL17: x | AM17: =COUNTIF(H17:AL17,"X")+COUNTIF(H17:AL17,"C") -> 31
A18: 14 | B18: 2 | C18: 29E00028 | D18: 8T | E18: XE01316 | F18: Nguyễn Ngọc Ân | H18: x | I18: C | J18: C | K18: C | L18: C | M18: C | N18: x | O18: x | P18: x | Q18: x | R18: x | S18: x | T18: x | U18: x | V18: x | W18: x | X18: x | Y18: x | Z18: x | AA18: x | AB18: x | AC18: x | AD18: x | AE18: x | AF18: x | AG18: x | AH18: x | AI18: x | AJ18: x | AK18: x | AL18: x | AM18: =COUNTIF(H18:AL18,"X")+COUNTIF(H18:AL18,"C") -> 31
A19: 15 | B19: 2 | C19: 29B20543 | D19: 8T | E19: XE01326 | F19: Nguyễn Đức Linh | H19: x | I19: x | J19: x | K19: x | L19: x | M19: x | N19: x | O19: x | P19: x | Q19: x | R19: x | S19: x | T19: x | U19: x | V19: x | W19: x | X19: x | Y19: x | Z19: x | AA19: x | AB19: x | AC19: x | AD19: x | AE19: x | AF19: x | AG19: x | AH19: x | AI19: x | AJ19: x | AK19: x | AL19: x | AM19: =COUNTIF(H19:AL19,"X")+COUNTIF(H19:AL19,"C") -> 31
A20: 16 | B20: 2 | C20: 29B20543 | D20: 8T | E20: XE01325 | F20: Nguyễn Công Thức | H20: x | I20: x | J20: x | K20: x | L20: x | M20: x | N20: x | O20: x | P20: x | Q20: x | R20: x | S20: x | T20: x | U20: x | V20: x | W20: x | X20: x | Y20: x | Z20: x | AA20: x | AB20: x | AC20: x | AD20: x | AE20: x | AF20: x | AG20: x | AH20: x | AI20: x | AJ20: x | AK20: x | AL20: x | AM20: =COUNTIF(H20:AL20,"X")+COUNTIF(H20:AL20,"C") -> 31
A21: 17 | B21: 2 | C21: 29E44326 | D21: 8T | E21: XE01098 | F21: Tạ Quốc Vương | H21: x | I21: x | J21: x | K21: x | L21: x | M21: x | N21: x | O21: x | P21: x | Q21: x | R21: x | S21: x | T21: x | U21: x | V21: x | W21: x | X21: x | Y21: x | Z21: x | AA21: x | AB21: x | AC21: x | AD21: x | AE21: x | AF21: x | AG21: x | AH21: x | AI21: x | AJ21: x | AK21: x | AL21: x | AM21: =COUNTIF(H21:AL21,"X")+COUNTIF(H21:AL21,"C") -> 31
A22: 18 | B22: 2 | C22: 29E44326 | D22: 8T | E22: XE01600 | F22: Nguyễn Đức Toàn | H22: x | I22: x | J22: x | K22: x | L22: x | M22: x | N22: x | O22: x | P22: x | Q22: x | R22: x | S22: x | T22: x | U22: x | V22: x | W22: x | X22: x | Y22: x | Z22: x | AA22: x | AB22: x | AC22: x | AD22: x | AE22: x | AF22: x | AG22: x | AH22: x | AI22: x | AJ22: x | AK22: x | AL22: x | AM22: =COUNTIF(H22:AL22,"X")+COUNTIF(H22:AL22,"C") -> 31
A23: 19 | B23: 2 | C23: 29E44369 | D23: 8T | E23: XE01434 | F23: Lê Quốc Quân | H23: x | I23: x | J23: x | K23: x | L23: x | M23: x | N23: Nghỉ nhà có đám hiếu | AJ23: x | AK23: x | AL23: x | AM23: =COUNTIF(H23:AL23,"X")+COUNTIF(H23:AL23,"C") -> 9
A24: 20 | B24: 2 | C24: 29E44369 | D24: 8T | E24: XE01433 | F24: Nguyễn Văn Chí | H24: x | I24: x | J24: x | K24: x | L24: x | M24: x | N24: x | O24: x | P24: x | Q24: x | R24: x | S24: x | T24: x | U24: x | V24: x | W24: x | X24: x | Y24: x | Z24: x | AA24: x | AB24: x | AC24: x | AD24: x | AE24: x | AF24: x | AG24: x | AH24: x | AI24: x | AJ24: x | AK24: x | AL24: x | AM24: =COUNTIF(H24:AL24,"X")+COUNTIF(H24:AL24,"C") -> 31
A25: 21 | B25: 2 | C25: 29E44377 | D25: 8T | E25: XE01417 | F25: Đặng Công Đức | H25: x | I25: x | J25: x | K25: x | L25: x | M25: x | N25: x | O25: x | P25: x | Q25: x | R25: x | S25: x | T25: x | U25: x | V25: x | W25: x | X25: x | Y25: x | Z25: x | AA25: x | AB25: x | AC25: x | AD25: x | AE25: x | AF25: x | AG25: x | AH25: x | AI25: x | AJ25: x | AK25: x | AL25: x | AM25: =COUNTIF(H25:AL25,"X")+COUNTIF(H25:AL25,"C") -> 31
A26: 22 | B26: 2 | C26: 29C37344-29G02349-29E09603-29E12401 | D26: 8T-15T | E26: XE01532 | F26: Phan Tấn Thành | H26: C | I26: C | J26: C | K26: C | L26: C | M26: C | N26: C | O26: x | P26: x | Q26: x | R26: x | S26: x | T26: x | U26: x | V26: x | W26: x | X26: x | Y26: x | Z26: x | AA26: x | AB26: x | AC26: x | AD26: x | AE26: x | AF26: x | AG26: x | AH26: x | AI26: x | AJ26: x | AK26: x | AL26: x | AM26: =COUNTIF(H26:AL26,"X")+COUNTIF(H26:AL26,"C") -> 31
A27: 23 | B27: 3 | C27: 29E54261 | D27: 8T | E27: XE01283 | F27: Trịnh Cao Phong | H27: x | I27: x | J27: x | K27: x | L27: x | M27: x | N27: x | O27: x | P27: x | Q27: x | R27: x | S27: x | T27: x | U27: x | V27: x | W27: x | X27: x | Y27: x | Z27: x | AA27: x | AB27: x | AC27: x | AD27: x | AE27: x | AF27: x | AG27: x | AH27: x | AI27: x | AJ27: x | AK27: x | AL27: x | AM27: =COUNTIF(H27:AL27,"X")+COUNTIF(H27:AL27,"C") -> 31
A28: 24 | B28: 3 | C28: 29E54261 | D28: 8T | E28: XE01541 | F28: Lê Thanh Sơn | H28: x | I28: x | J28: x | K28: x | L28: x | M28: x | N28: x | O28: x | P28: x | Q28: x | R28: x | S28: x | T28: x | U28: x | V28: x | W28: x | X28: x | Y28: x | Z28: x | AA28: x | AB28: x | AC28: x | AD28: x | AE28: x | AF28: x | AG28: x | AH28: x | AI28: x | AJ28: x | AK28: x | AL28: x | AM28: =COUNTIF(H28:AL28,"X")+COUNTIF(H28:AL28,"C") -> 31
A29: 25 | B29: 3 | C29: 29K06824 | D29: 8T | E29: XE01263 | F29: Nguyễn Trọng Đạt | H29: x | I29: x | J29: x | K29: x | L29: x | M29: x | N29: x | O29: x | P29: x | Q29: x | R29: x | S29: x | T29: x | U29: x | V29: x | W29: x | X29: x | Y29: x | Z29: x | AA29: x | AB29: x | AC29: x | AD29: x | AE29: x | AF29: x | AG29: x | AH29: x | AI29: x | AJ29: x | AK29: x | AL29: x | AM29: =COUNTIF(H29:AL29,"X")+COUNTIF(H29:AL29,"C") -> 31
A30: 26 | B30: 3 | C30: 29K06824 | D30: 8T | E30: XE01149 | F30: Phạm Văn Thưởng | H30: x | I30: x | J30: x | K30: x | L30: x | M30: x | N30: x | O30: x | P30: x | Q30: x | R30: x | S30: x | T30: x | U30: x | V30: x | W30: x | X30: x | Y30: x | Z30: x | AA30: x | AB30: x | AC30: x | AD30: x | AE30: x | AF30: x | AG30: x | AH30: x | AI30: x | AJ30: x | AK30: x | AL30: x | AM30: =COUNTIF(H30:AL30,"X")+COUNTIF(H30:AL30,"C") -> 31
A31: 27 | B31: 3 | C31: 29E12747 | D31: 8T | E31: XE01335 | F31: Phạm Thanh Tuấn | H31: x | I31: x | J31: x | K31: x | L31: x | M31: x | N31: x | O31: x | P31: x | Q31: x | R31: x | S31: x | T31: x | U31: x | V31: x | W31: x | X31: x | Y31: x | Z31: x | AA31: x | AB31: x | AC31: x | AD31: x | AE31: x | AF31: x | AG31: x | AH31: x | AI31: x | AJ31: x | AK31: x | AL31: x | AM31: =COUNTIF(H31:AL31,"X")+COUNTIF(H31:AL31,"C") -> 31
A32: 28 | B32: 3 | C32: 29E38126 | D32: 8T | E32: XE01609 | F32: Võ Văn Trỗi | H32: x | I32: x | J32: x | K32: x | L32: x | M32: x | N32: x | O32: x | P32: x | Q32: x | R32: x | S32: x | T32: x | U32: x | V32: x | W32: x | X32: x | Y32: x | Z32: x | AA32: x | AB32: x | AC32: x | AD32: x | AE32: x | AF32: x | AG32: x | AH32: x | AI32: x | AJ32: x | AK32: x | AL32: x | AM32: =COUNTIF(H32:AL32,"X")+COUNTIF(H32:AL32,"C") -> 31
A33: 29 | B33: 3 | C33: 29K13905 | D33: 8T | E33: XE01005 | F33: Nguyễn Quốc Bình | H33: O | I33: x | J33: x | K33: x | L33: x | M33: x | N33: x | O33: x | P33: x | Q33: x | R33: x | S33: x | T33: x | U33: x | V33: x | W33: x | X33: x | Y33: x | Z33: o | AA33: o | AB33: o | AC33: o | AD33: o | AE33: o | AF33: o | AG33: o | AH33: o | AI33: o | AJ33: o | AK33: o | AL33: o | AM33: =COUNTIF(H33:AL33,"X")+COUNTIF(H33:AL33,"C") -> 17
A34: 30 | B34: 3 | C34: 29K13905 | D34: 8T | E34: XE01164 | F34: Trịnh Văn Lực | H34: x | I34: x | J34: x | K34: x | L34: x | M34: x | N34: x | O34: x | P34: x | Q34: x | R34: x | S34: x | T34: x | U34: x | V34: x | W34: x | X34: x | Y34: x | Z34: x | AA34: x | AB34: x | AC34: x | AD34: x | AE34: x | AF34: x | AG34: x | AH34: x | AI34: x | AJ34: x | AK34: x | AL34: x | AM34: =COUNTIF(H34:AL34,"X")+COUNTIF(H34:AL34,"C") -> 31
A35: 31 | B35: 3 | C35: 29K13459 | D35: 8T | E35: XE01456 | F35: Hoàng Văn Lợi | H35: x | I35: x | J35: x | K35: x | L35: x | M35: x | N35: x | O35: x | P35: x | Q35: x | R35: x | S35: x | T35: x | U35: x | V35: x | W35: x | X35: x | Y35: x | Z35: x | AA35: x | AB35: x | AC35: x | AD35: x | AE35: x | AF35: x | AG35: x | AH35: x | AI35: x | AJ35: x | AK35: x | AL35: x | AM35: =COUNTIF(H35:AL35,"X")+COUNTIF(H35:AL35,"C") -> 31
... A51: 47 | B51: 5 | C51: 29E44369 | D51: 8T | E51: XE01281 | F51: Nguyễn Văn Toàn | H51: x | I51: x | J51: x | K51: x | L51: x | M51: x | N51: x | O51: x | P51: x | Q51: x | R51: x | S51: x | T51: x | U51: x | V51: x | W51: x | X51: x | Y51: x | Z51: x | AA51: x | AB51: x | AC51: x | AD51: x | AE51: x | AF51: x | AG51: x | AH51: x | AI51: x | AJ51: x | AK51: x | AL51: x | AM51: =COUNTIF(H51:AL51,"X")+COUNTIF(H51:AL51,"C") -> 31
A52: 48 | B52: 5 | C52: 29E54212 | D52: 8T | E52: XE01453 | F52: Lê Văn Khiêm | H52: x | I52: x | J52: x | K52: x | L52: x | M52: x | N52: x | O52: x | P52: o | Q52: o | R52: o | S52: o | T52: o | U52: o | V52: o | W52: Qua tuyến nhánh HCM | AM52: =COUNTIF(H52:AL52,"X")+COUNTIF(H52:AL52,"C") -> 8
A53: 49 | B53: 5 | C53: 29E12401 | D53: 15T | E53: XE01477 | F53: Cao Hoài Tiên | H53: x | I53: x | J53: x | K53: x | L53: x | M53: x | N53: x | O53: x | P53: x | Q53: x | R53: x | S53: x | T53: x | U53: x | V53: x | W53: x | X53: x | Y53: x | Z53: x | AA53: x | AB53: x | AC53: x | AD53: x | AE53: x | AF53: x | AG53: o | AH53: o | AI53: o | AJ53: o | AK53: o | AL53: o | AM53: =COUNTIF(H53:AL53,"X")+COUNTIF(H53:AL53,"C") -> 25 | AO53: Ktra lại lý do
A54: 50 | B54: 5 | C54: 29E12401 | D54: 15T | E54: XE01670 | F54: Bùi Ngọc Ninh | H54: x | I54: x | J54: x | K54: x | L54: x | M54: x | N54: x | O54: x | P54: x | Q54: x | R54: x | S54: x | T54: x | U54: x | V54: x | W54: x | X54: x | Y54: x | Z54: x | AA54: x | AB54: x | AC54: x | AD54: x | AE54: x | AF54: x | AG54: o | AH54: o | AI54: o | AJ54: o | AK54: o | AL54: o | AM54: =COUNTIF(H54:AL54,"X")+COUNTIF(H54:AL54,"C") -> 25 | AO54: Ktra lại lý do
A55: 51 | B55: 5 | C55: 29E44377 | D55: 8T | E55: XE01671 | F55: Huỳnh Xuân Nhân | H55: x | I55: x | J55: x | K55: x | L55: x | M55: x | N55: x | O55: x | P55: x | Q55: x | R55: x | S55: x | T55: x | U55: x | V55: x | W55: x | X55: x | Y55: x | Z55: x | AA55: x | AB55: x | AC55: x | AD55: x | AE55: x | AF55: x | AG55: x | AH55: x | AI55: x | AJ55: x | AK55: x | AL55: x | AM55: =COUNTIF(H55:AL55,"X")+COUNTIF(H55:AL55,"C") -> 31
A56: 52 | B56: 5 | C56: 29H80501-29E08413 | D56: 15T | E56: XE01672 | F56: Đỗ Văn Cường | H56: x | I56: x | J56: x | K56: x | L56: x | M56: x | N56: x | O56: x | P56: x | Q56: x | R56: x | S56: x | T56: x | U56: x | V56: x | W56: x | X56: x | Y56: x | Z56: x | AA56: x | AB56: x | AC56: x | AD56: x | AE56: x | AF56: x | AG56: x | AH56: C | AI56: C | AJ56: C | AK56: C | AL56: C | AM56: =COUNTIF(H56:AL56,"X")+COUNTIF(H56:AL56,"C") -> 31 | AN56: DC
...

Sheet TUYẾN NHÁNH HCM 
B1: BẢNG CHẤM CÔNG LÁI TẢI TUYẾN NHÁNH HCM T5.2026
B4: BSX | C4: Tải trọng | D4: Mã nv | E4: Họ tên | F4: 1 | G4: 2 | H4: 3 | I4: 4 | J4: 5 | K4: 6 | L4: 7 | M4: 8 | N4: 9 | O4: 10 | P4: 11 | Q4: 12 | R4: 13 | S4: 14 | T4: 15 | U4: 16 | V4: 17 | W4: 18 | X4: 19 | Y4: 20 | Z4: 21 | AA4: 22 | AB4: 23 | AC4: 24 | AD4: 25 | AE4: 26 | AF4: 27 | AG4: 28 | AH4: 29 | AI4: 30 | AJ4: 31 | AK4: Số công
F5: T6 | G5: T7 | H5: CN | I5: T2 | J5: T3 | K5: T4 | L5: T5 | M5: T6 | N5: T7 | O5: CN | P5: T2 | Q5: T3 | R5: T4 | S5: T5 | T5: T6 | U5: T7 | V5: CN | W5: T2 | X5: T3 | Y5: T4 | Z5: T5 | AA5: T6 | AB5: T7 | AC5: CN | AD5: T2 | AE5: T3 | AF5: T4 | AG5: T5 | AH5: T6 | AI5: T7 | AJ5: CN
A6: 1 | B6: 29E47562 | C6: {=IFERROR(INDEX(MNV!F:F,MATCH(B6,MNV!E:E,0)),"")} -> 2.4T lạnh | D6: XE01597 | E6: Hồ Khang Vĩ | F6: NL | G6: NL | I6: x | J6: x | K6: x | L6: x | M6: x | N6: x | P6: x | Q6: x | R6: x | S6: x | T6: x | U6: x | W6: x | X6: x | Y6: x | Z6: x | AA6: x | AB6: x | AD6: x | AE6: x | AF6: x | AG6: x | AH6: x | AI6: x | AK6: =COUNTIF(F6:AJ6,"X")+COUNTIF(F6:AJ6,"Chờ")+COUNTIF(F6:AJ6,"NL") -> 26
A7: 2 | B7: 29E48524 | C7: {=IFERROR(INDEX(MNV!F:F,MATCH(B7,MNV!E:E,0)),"")} -> 2.4T lạnh | D7: XE01665 | E7: Ừng Chánh Sang | F7: NL | G7: NL | I7: x | J7: x | K7: x | L7: x | M7: x | N7: x | P7: x | Q7: x | R7: x | S7: x | T7: x | U7: x | W7: x | X7: x | Y7: x | Z7: x | AA7: x | AB7: x | AD7: x | AE7: x | AF7: x | AG7: x | AH7: x | AI7: x | AK7: =COUNTIF(F7:AJ7,"X")+COUNTIF(F7:AJ7,"Chờ")+COUNTIF(F7:AJ7,"NL") -> 26
A8: 3 | B8: 29E49820 | C8: {=IFERROR(INDEX(MNV!F:F,MATCH(B8,MNV!E:E,0)),"")} -> 3.5T lạnh | D8: {=IFERROR(INDEX(MNV!A:A,MATCH(E8,MNV!B:B,0)),"")} -> XE01379 | E8: Lê Minh Vin | F8: NL | G8: NL | I8: x | J8: x | K8: x | L8: x | M8: x | N8: x | P8: x | Q8: x | R8: x | S8: x | T8: x | U8: x | W8: x | X8: x | Y8: x | Z8: x | AA8: x | AB8: x | AD8: x | AE8: x | AF8: x | AG8: x | AH8: x | AI8: x | AK8: =COUNTIF(F8:AJ8,"X")+COUNTIF(F8:AJ8,"Chờ")+COUNTIF(F8:AJ8,"NL") -> 26
A9: 4 | B9: 29K02514 | C9: {=IFERROR(INDEX(MNV!F:F,MATCH(B9,MNV!E:E,0)),"")} -> 2.4T lạnh | D9: XE01642 | E9: Nguyễn Xuân Lợi | F9: NL | G9: NL | I9: x | J9: x | K9: x | L9: x | M9: x | N9: x | P9: x | Q9: x | R9: x | S9: x | T9: x | U9: x | W9: x | X9: x | Y9: x | Z9: x | AA9: x | AB9: x | AD9: x | AE9: x | AF9: x | AG9: x | AH9: x | AI9: x | AK9: =COUNTIF(F9:AJ9,"X")+COUNTIF(F9:AJ9,"Chờ")+COUNTIF(F9:AJ9,"NL") -> 26
A10: 5 | D10: XE01453 | E10: Lê Văn Khiêm | F10: Bên tuyến chính BN | U10: x | W10: x | X10: x | Y10: x | Z10: x | AA10: x | AB10: x | AD10: x | AE10: x | AF10: x | AG10: x | AH10: x | AI10: x | AK10: =COUNTIF(F10:AJ10,"X")+COUNTIF(F10:AJ10,"Chờ")+COUNTIF(F10:AJ10,"NL") -> 13 | AL10: DC
A11: 6 | B11: Lái trung chuyển | D11: XE01666 | E11: Bùi Xuân Bằng | I11: x | J11: x | K11: x | L11: x | M11: x | N11: x | O11: x | P11: x | Q11: x | R11: x | S11: x | T11: x | U11: x | V11: x | W11: x | X11: x | Y11: x | Z11: x | AA11: x | AB11: x | AC11: x | AD11: x | AE11: x | AF11: x | AG11: x | AH11: x | AI11: x | AJ11: x | AK11: =COUNTIF(F11:AJ11,"X")+COUNTIF(F11:AJ11,"Chờ")+COUNTIF(F11:AJ11,"NL") -> 28
A12: 7 | B12: Lái trung chuyển | D12: XE01685 | E12: Huỳnh Y Bảo | Q12: x | R12: x | S12: x | T12: x | U12: x | V12: x | W12: x | X12: x | Y12: x | Z12: x | AA12: x | AB12: x | AC12: x | AD12: x | AE12: x | AF12: x | AG12: x | AH12: x | AI12: x | AJ12: x | AK12: =COUNTIF(F12:AJ12,"X")+COUNTIF(F12:AJ12,"Chờ")+COUNTIF(F12:AJ12,"NL") -> 20
A13: 7 | B13: Lái trung chuyển | C13: {=IFERROR(INDEX(MNV!F:F,MATCH(B13,MNV!E:E,0)),"")} | D13: {=IFERROR(INDEX(MNV!A:A,MATCH(E13,MNV!B:B,0)),"")} -> XE01420 | E13: Bùi Phi Hùng | I13: x | J13: x | K13: x | L13: x | M13: x | N13: x | O13: x | P13: x | Q13: x | R13: x | S13: x | T13: x | U13: x | V13: x | W13: x | X13: x | Y13: x | Z13: x | AA13: x | AB13: x | AD13: x | AE13: x | AF13: x | AG13: x | AH13: x | AI13: x | AK13: =COUNTIF(F13:AJ13,"X")+COUNTIF(F13:AJ13,"Chờ")+COUNTIF(F13:AJ13,"NL") -> 26
W14: PVTHH | AG14: Người lập
W19: Lương Văn Tùng | AG19: Hoàng Thu Nguyệt

Sheet TUYẾN NHÁNH HN
B1: BẢNG CHẤM CÔNG LÁI TẢI TUYẾN NHÁNH HN T5.2026
B2: BSX | C2: Tải trọng | D2: Mã nv | E2: Họ tên | F2: Dự án | G2: 1 | H2: 2 | I2: 3 | J2: 4 | K2: 5 | L2: 6 | M2: 7 | N2: 8 | O2: 9 | P2: 10 | Q2: 11 | R2: 12 | S2: 13 | T2: 14 | U2: 15 | V2: 16 | W2: 17 | X2: 18 | Y2: 19 | Z2: 20 | AA2: 21 | AB2: 22 | AC2: 23 | AD2: 24 | AE2: 25 | AF2: 26 | AG2: 27 | AH2: 28 | AI2: 29 | AJ2: 30 | AK2: 31 | AL2: Số công | AM2: X | AN2: Vận hành
G3: T6 | H3: T7 | I3: CN | J3: T2 | K3: T3 | L3: T4 | M3: T5 | N3: T6 | O3: T7 | P3: CN | Q3: T2 | R3: T3 | S3: T4 | T3: T5 | U3: T6 | V3: T7 | W3: CN | X3: T2 | Y3: T3 | Z3: T4 | AA3: T5 | AB3: T6 | AC3: T7 | AD3: CN | AE3: T2 | AF3: T3 | AG3: T4 | AH3: T5 | AI3: T6 | AJ3: T7 | AK3: CN | AM3: C | AN3: Chờ
A4: 1 | B4: 29H84991 | C4: 3.5T | D4: XE01466 | E4: Nguyễn Tuấn Anh | F4: AEON | G4: x | H4: x | I4: o | J4: x | K4: x | L4: x | M4: x | N4: x | O4: x | P4: o | Q4: x | R4: x | S4: x | T4: x | U4: x | V4: x | W4: o | X4: x | Y4: x | Z4: x | AA4: x | AB4: x | AC4: x | AD4: o | AE4: x | AF4: x | AG4: x | AH4: x | AI4: x | AJ4: x | AK4: x | AL4: =COUNTIF(G4:AK4,"X")+COUNTIF(G4:AK4,"C")+COUNTIF(G4:AK4,"NL") -> 27 | AM4: O | AN4: Nghỉ
A5: 2 | B5: 29K13511 | C5: 2.5T | D5: XE00768 | E5: Đinh Mai Sơn | F5: AEON | G5: x | H5: x | I5: o | J5: x | K5: x | L5: x | M5: x | N5: x | O5: x | P5: o | Q5: x | R5: x | S5: x | T5: x | U5: x | V5: x | W5: o | X5: x | Y5: x | Z5: x | AA5: x | AB5: x | AC5: x | AD5: o | AE5: x | AF5: x | AG5: x | AH5: x | AI5: x | AJ5: x | AK5: x | AL5: =COUNTIF(G5:AK5,"X")+COUNTIF(G5:AK5,"C")+COUNTIF(G5:AK5,"NL") -> 27
A6: 3 | B6: 29K13582 | C6: 2.5T | D6: XE01537 | E6: Trần Bá Lương | F6: AEON | G6: x | H6: x | I6: o | J6: x | K6: x | L6: x | M6: x | N6: x | O6: x | P6: o | Q6: x | R6: x | S6: x | T6: x | U6: x | V6: x | W6: o | X6: x | Y6: x | Z6: x | AA6: x | AB6: x | AC6: x | AD6: o | AE6: x | AF6: x | AG6: x | AH6: x | AI6: x | AJ6: x | AK6: x | AL6: =COUNTIF(G6:AK6,"X")+COUNTIF(G6:AK6,"C")+COUNTIF(G6:AK6,"NL") -> 27
A7: 4 | B7: 29H73703 | C7: 2.5T | D7: XE01653 | E7: Phạm Trung Kiên | F7: AEON | G7: x | H7: x | I7: o | J7: x | K7: x | L7: x | M7: x | N7: x | O7: x | P7: o | Q7: x | R7: x | S7: x | T7: x | U7: x | V7: x | W7: o | X7: x | Y7: x | Z7: x | AA7: x | AB7: x | AC7: x | AD7: o | AE7: x | AF7: x | AG7: x | AH7: x | AI7: x | AJ7: x | AK7: x | AL7: =COUNTIF(G7:AK7,"X")+COUNTIF(G7:AK7,"C")+COUNTIF(G7:AK7,"NL") -> 27
A8: 5 | B8: 29K06572 | C8: 2.5 lạnh | D8: XE00975 | E8: Nguyễn Văn Luận | F8: AEON | G8: x | H8: x | I8: o | J8: x | K8: x | L8: x | M8: x | N8: x | O8: x | P8: o | Q8: x | R8: x | S8: x | T8: x | U8: x | V8: x | W8: o | X8: x | Y8: x | Z8: x | AA8: x | AB8: x | AC8: x | AD8: o | AE8: x | AF8: x | AG8: x | AH8: x | AI8: x | AJ8: x | AK8: x | AL8: =COUNTIF(G8:AK8,"X")+COUNTIF(G8:AK8,"C")+COUNTIF(G8:AK8,"NL") -> 27
A9: 6 | B9: 29K06857 | C9: 2.5 lạnh | D9: XE01639 | E9: Nguyễn Việt Hùng | F9: DHG | G9: x | H9: x | I9: o | J9: x | K9: x | L9: x | M9: x | N9: x | O9: x | P9: o | Q9: x | R9: x | S9: x | T9: x | U9: x | V9: x | W9: o | X9: x | Y9: x | Z9: x | AA9: x | AB9: x | AC9: x | AD9: o | AE9: x | AF9: x | AG9: x | AH9: x | AI9: x | AJ9: x | AK9: x | AL9: =COUNTIF(G9:AK9,"X")+COUNTIF(G9:AK9,"C")+COUNTIF(G9:AK9,"NL") -> 27
A10: 7 | B10: 29E49680 | C10: 2.5 lạnh | D10: XE00977 | E10: Trần Trung Kiên | F10: DHG | G10: NL | H10: x | I10: o | J10: x | K10: x | L10: x | M10: x | N10: x | O10: x | P10: o | Q10: x | R10: x | S10: x | T10: x | U10: x | V10: x | W10: o | X10: x | Y10: x | Z10: x | AA10: x | AB10: x | AC10: x | AD10: o | AE10: x | AF10: x | AG10: x | AH10: x | AI10: x | AJ10: x | AK10: x | AL10: =COUNTIF(G10:AK10,"X")+COUNTIF(G10:AK10,"C")+COUNTIF(G10:AK10,"NL") -> 27
A11: 8 | B11: 29K06949 | C11: 2.5 lạnh | D11: XE01616 | E11: Ngô Công Định | F11: DHG | G11: NL | H11: x | I11: o | J11: x | K11: x | L11: x | M11: x | N11: x | O11: x | P11: o | Q11: x | R11: x | S11: x | T11: x | U11: x | V11: x | W11: o | X11: x | Y11: x | Z11: x | AA11: x | AB11: x | AC11: x | AD11: o | AE11: x | AF11: x | AG11: x | AH11: x | AI11: x | AJ11: x | AK11: x | AL11: =COUNTIF(G11:AK11,"X")+COUNTIF(G11:AK11,"C")+COUNTIF(G11:AK11,"NL") -> 27
A12: 9 | B12: 29E52540 | C12: 3.5 lạnh | D12: XE00730 | E12: Nguyễn Hữu Tùng | F12: DHG | G12: NL | H12: x | I12: o | J12: x | K12: x | L12: x | M12: x | N12: x | O12: x | P12: o | Q12: x | R12: x | S12: x | T12: x | U12: x | V12: x | W12: o | X12: x | Y12: x | Z12: x | AA12: x | AB12: x | AC12: x | AD12: o | AE12: x | AF12: x | AG12: x | AH12: x | AI12: x | AJ12: x | AK12: x | AL12: =COUNTIF(G12:AK12,"X")+COUNTIF(G12:AK12,"C")+COUNTIF(G12:AK12,"NL") -> 27
A13: 10 | B13: 29E61253 | C13: 1.5T lạnh | D13: XE01615 | E13: Nguyễn Hữu Tuấn | F13: TRUNG CHUYỂN | G13: x | H13: x | I13: x | J13: x | K13: x | L13: x | M13: x | N13: x | O13: x | P13: o | Q13: x | R13: x | S13: x | T13: x | U13: x | V13: x | W13: o | X13: o | Y13: o | Z13: o | AA13: o | AB13: o | AC13: o | AD13: o | AE13: o | AF13: o | AG13: o | AH13: o | AI13: o | AJ13: o | AK13: o | AL13: =COUNTIF(G13:AK13,"X")+COUNTIF(G13:AK13,"C")+COUNTIF(G13:AK13,"NL") -> 15
A14: 11 | B14: 29G02311 | C14: 6.5T | D14: XE00777 | E14: Hoàng Đức Mạnh | F14: TLTL | G14: NL | H14: o | I14: x | J14: x | K14: x | L14: x | M14: x | N14: x | O14: x | P14: x | Q14: x | R14: x | S14: x | T14: x | U14: x | V14: x | W14: o | X14: x | Y14: o | Z14: x | AA14: x | AB14: x | AC14: x | AD14: x | AE14: x | AF14: x | AG14: x | AH14: x | AI14: x | AJ14: x | AK14: x | AL14: =COUNTIF(G14:AK14,"X")+COUNTIF(G14:AK14,"C")+COUNTIF(G14:AK14,"NL") -> 28
A15: 12 | B15: 29B18964 | C15: 6.5T | D15: XE01004 | E15: Trần Văn Cương | F15: TLTL | G15: NL | H15: x | I15: o | J15: x | K15: x | L15: x | M15: x | N15: x | O15: x | P15: x | Q15: x | R15: o | S15: x | T15: x | U15: x | V15: x | W15: x | X15: x | Y15: x | Z15: x | AA15: x | AB15: x | AC15: x | AD15: x | AE15: x | AF15: x | AG15: x | AH15: x | AI15: x | AJ15: x | AK15: x | AL15: =COUNTIF(G15:AK15,"X")+COUNTIF(G15:AK15,"C")+COUNTIF(G15:AK15,"NL") -> 29
A16: 13 | B16: 29G02320 | C16: 6.5T | D16: XE00832 | E16: Hoàng Văn Chuyền | F16: TLTL | G16: NL | H16: x | I16: x | J16: x | K16: x | L16: x | M16: x | N16: x | O16: x | P16: x | Q16: x | R16: o | S16: x | T16: x | U16: x | V16: x | W16: o | X16: x | Y16: x | Z16: x | AA16: x | AB16: x | AC16: x | AD16: x | AE16: x | AF16: o | AG16: x | AH16: x | AI16: x | AJ16: x | AK16: x | AL16: =COUNTIF(G16:AK16,"X")+COUNTIF(G16:AK16,"C")+COUNTIF(G16:AK16,"NL") -> 28
A17: 14 | B17: 29G02319 | C17: 6.5T | D17: XE01620 | E17: Trần Phi Hùng (new 6/4) | F17: TLTL | G17: NL | H17: o | I17: o | J17: o | K17: o | L17: x | M17: x | N17: x | O17: o | P17: o | Q17: o | R17: o | S17: x | T17: x | U17: x | V17: x | W17: x | X17: x | Y17: o | Z17: x | AA17: x | AB17: x | AC17: x | AD17: x | AE17: x | AF17: x | AG17: x | AH17: x | AI17: x | AJ17: o | AK17: x | AL17: =COUNTIF(G17:AK17,"X")+COUNTIF(G17:AK17,"C")+COUNTIF(G17:AK17,"NL") -> 21
A18: 15 | B18: 29E12348 | C18: 6.5T | D18: XE00900 | E18: Đặng Văn Thắng | F18: TLTL | G18: NL | H18: x | I18: x | J18: x | K18: x | L18: x | M18: x | N18: x | O18: x | P18: 0 | Q18: x | R18: x | S18: x | T18: x | U18: x | V18: x | W18: x | X18: x | Y18: x | Z18: x | AA18: x | AB18: x | AC18: x | AD18: o | AE18: x | AF18: x | AG18: x | AH18: x | AI18: x | AJ18: x | AK18: x | AL18: =COUNTIF(G18:AK18,"X")+COUNTIF(G18:AK18,"C")+COUNTIF(G18:AK18,"NL") -> 29
A19: 16 | B19: 29E08058 | C19: 6.5T | D19: XE01641 | E19: Nguyễn Duy Trung (new 13/4) | F19: TLTL | G19: NL | H19: x | I19: o | J19: x | K19: x | L19: x | M19: x | N19: x | O19: x | P19: o | Q19: x | R19: x | S19: x | T19: x | U19: x | V19: x | W19: o | X19: x | Y19: x | Z19: x | AA19: x | AB19: x | AC19: x | AD19: x | AE19: x | AF19: x | AG19: x | AH19: x | AI19: x | AJ19: x | AK19: x | AL19: =COUNTIF(G19:AK19,"X")+COUNTIF(G19:AK19,"C")+COUNTIF(G19:AK19,"NL") -> 28 | AM19: DC
A20: 17 | B20: 29K13742 | C20: 8T bạt | D20: XE00847 | E20: Mai Văn Toản | F20: TLTL | G20: NL | H20: x | I20: x | J20: x | K20: x | L20: x | M20: x | N20: x | O20: x | P20: x | Q20: x | R20: o | S20: x | T20: x | U20: x | V20: x | W20: x | X20: x | Y20: o | Z20: x | AA20: x | AB20: x | AC20: x | AD20: x | AE20: x | AF20: o | AG20: x | AH20: x | AI20: x | AJ20: x | AK20: x | AL20: =COUNTIF(G20:AK20,"X")+COUNTIF(G20:AK20,"C")+COUNTIF(G20:AK20,"NL") -> 28
A21: 18 | B21: 29K13754 | C21: 8T bạt | D21: XE00449 | E21: Phạm Văn Hải A | F21: TLTL | G21: NL | H21: x | I21: x | J21: x | K21: o | L21: x | M21: x | N21: x | O21: x | P21: x | Q21: x | R21: o | S21: x | T21: x | U21: x | V21: x | W21: o | X21: x | Y21: x | Z21: x | AA21: x | AB21: x | AC21: x | AD21: x | AE21: x | AF21: o | AG21: x | AH21: x | AI21: x | AJ21: x | AK21: x | AL21: =COUNTIF(G21:AK21,"X")+COUNTIF(G21:AK21,"C")+COUNTIF(G21:AK21,"NL") -> 27
A22: 19 | B22: 29K13697 | C22: 8T bạt | D22: XE00891 | E22: Phạm Thái Nhân | F22: TLTL | G22: NL | H22: x | I22: x | J22: x | K22: o | L22: x | M22: x | N22: x | O22: x | P22: x | Q22: x | R22: o | S22: x | T22: x | U22: x | V22: x | W22: x | X22: x | Y22: x | Z22: x | AA22: x | AB22: x | AC22: x | AD22: x | AE22: x | AF22: o | AG22: x | AH22: x | AI22: x | AJ22: o | AK22: x | AL22: =COUNTIF(G22:AK22,"X")+COUNTIF(G22:AK22,"C")+COUNTIF(G22:AK22,"NL") -> 27
A23: 20 | B23: 29K06935 | C23: 8T | D23: XE00547 | E23: Mai Văn Long | F23: TLTL | G23: NL | H23: x | I23: o | J23: x | K23: x | L23: x | M23: x | N23: x | O23: x | P23: o | Q23: x | R23: x | S23: x | T23: x | U23: x | V23: x | W23: x | X23: x | Y23: x | Z23: x | AA23: x | AB23: x | AC23: x | AD23: o | AE23: x | AF23: x | AG23: x | AH23: x | AI23: x | AJ23: x | AK23: x | AL23: =COUNTIF(G23:AK23,"X")+COUNTIF(G23:AK23,"C")+COUNTIF(G23:AK23,"NL") -> 28
A24: 21 | B24: 29K06374 | C24: 8T | D24: XE00447 | E24: Lê Văn Giang | F24: TLTL | G24: NL | H24: x | I24: x | J24: x | K24: o | L24: x | M24: x | N24: x | O24: x | P24: x | Q24: x | R24: o | S24: x | T24: x | U24: x | V24: x | W24: x | X24: x | Y24: o | Z24: x | AA24: x | AB24: x | AC24: x | AD24: x | AE24: x | AF24: o | AG24: x | AH24: x | AI24: x | AJ24: x | AK24: x | AL24: =COUNTIF(G24:AK24,"X")+COUNTIF(G24:AK24,"C")+COUNTIF(G24:AK24,"NL") -> 27
A25: 22 | B25: 29E38311 | C25: 8T | D25: XE00953 | E25: Mai Văn Ngọc | F25: TLTL | G25: NL | H25: x | I25: x | J25: x | K25: x | L25: x | M25: x | N25: x | O25: x | P25: x | Q25: x | R25: x | S25: x | T25: x | U25: x | V25: x | W25: o | X25: x | Y25: o | Z25: x | AA25: x | AB25: x | AC25: x | AD25: x | AE25: x | AF25: x | AG25: x | AH25: x | AI25: x | AJ25: x | AK25: o | AL25: =COUNTIF(G25:AK25,"X")+COUNTIF(G25:AK25,"C")+COUNTIF(G25:AK25,"NL") -> 28
A26: 23 | B26: 29E09530 | C26: 15 bạt | D26: XE00779 | E26: Nguyễn Tiến Công | F26: TLTL | G26: NL | H26: x | I26: x | J26: x | K26: o | L26: x | M26: x | N26: x | O26: x | P26: x | Q26: x | R26: x | S26: x | T26: x | U26: x | V26: x | W26: x | X26: x | Y26: o | Z26: x | AA26: x | AB26: x | AC26: x | AD26: x | AE26: x | AF26: x | AG26: x | AH26: x | AI26: x | AJ26: x | AK26: x | AL26: =COUNTIF(G26:AK26,"X")+COUNTIF(G26:AK26,"C")+COUNTIF(G26:AK26,"NL") -> 29
W27: PVTHH | AG27: Người lập
W32: Lương Văn Tùng | AG32: Hoàng Thu Nguyệt

Sheet Bảo vệ
B1: BẢNG CHẤM CÔNG BẢO VỆ BÃI BINH DƯƠNG- HÀ NỘI T5-2026
B2: Mã nv | C2: Họ tên | D2: 1 | E2: 2 | F2: 3 | G2: 4 | H2: 5 | I2: 6 | J2: 7 | K2: 8 | L2: 9 | M2: 10 | N2: 11 | O2: 12 | P2: 13 | Q2: 14 | R2: 15 | S2: 16 | T2: 17 | U2: 18 | V2: 19 | W2: 20 | X2: 21 | Y2: 22 | Z2: 23 | AA2: 24 | AB2: 25 | AC2: 26 | AD2: 27 | AE2: 28 | AF2: 29 | AG2: 30 | AH2: 31 | AI2: Số công
D3: T6 | E3: T7 | F3: CN | G3: T2 | H3: T3 | I3: T4 | J3: T5 | K3: T6 | L3: T7 | M3: CN | N3: T2 | O3: T3 | P3: T4 | Q3: T5 | R3: T6 | S3: T7 | T3: CN | U3: T2 | V3: T3 | W3: T4 | X3: T5 | Y3: T6 | Z3: T7 | AA3: CN | AB3: T2 | AC3: T3 | AD3: T4 | AE3: T5 | AF3: T6 | AG3: T7 | AH3: CN
A4: 3 | B4: XE-1512 | C4: Tồng Văn Lâm | D4: x | E4: x | F4: x | G4: x | H4: x | I4: x | J4: x | K4: x | L4: x | M4: x | N4: x | O4: x | P4: x | Q4: x | R4: x | S4: x | T4: x | U4: x | V4: x | W4: x | X4: x | Y4: x | Z4: x | AA4: x | AB4: x | AC4: x | AD4: x | AE4: x | AF4: x | AG4: x | AH4: x | AI4: =COUNTIF(D4:AH4,"X")+COUNTIF(D4:AH4,"C") -> 31
A5: 4 | B5: XE01513 | C5: Huỳnh Ngọc út | D5: x | E5: x | F5: x | G5: x | H5: x | I5: x | J5: x | K5: x | L5: x | M5: x | N5: x | O5: x | P5: x | Q5: x | R5: x | S5: x | T5: x | U5: x | V5: x | W5: x | X5: x | Y5: x | Z5: x | AA5: x | AB5: x | AC5: x | AD5: x | AE5: x | AF5: x | AG5: x | AH5: x | AI5: =COUNTIF(D5:AH5,"X")+COUNTIF(D5:AH5,"C") -> 31
A6: 5 | AI6: =COUNTIF(D6:AH6,"X")+COUNTIF(D6:AH6,"C") -> 0
T7: PVTHH | AD7: Người lập
T12: Lương Văn Tùng | AD12: Hoàng Thu Nguyệt

Sheet LÁI CONT
B1: BẢNG CHẤM CÔNG LÁI CONT T5.2026
B4: BSX | C4: Tải trọng | D4: Mã nv | E4: Họ tên | F4: 1 | G4: 2 | H4: 3 | I4: 4 | J4: 5 | K4: 6 | L4: 7 | M4: 8 | N4: 9 | O4: 10 | P4: 11 | Q4: 12 | R4: 13 | S4: 14 | T4: 15 | U4: 16 | V4: 17 | W4: 18 | X4: 19 | Y4: 20 | Z4: 21 | AA4: 22 | AB4: 23 | AC4: 24 | AD4: 25 | AE4: 26 | AF4: 27 | AG4: 28 | AH4: 29 | AI4: 30 | AJ4: 31 | AK4: Số công | AM4: X | AN4: Vận hành
F5: T6 | G5: T7 | H5: CN | I5: T2 | J5: T3 | K5: T4 | L5: T5 | M5: T6 | N5: T7 | O5: CN | P5: T2 | Q5: T3 | R5: T4 | S5: T5 | T5: T6 | U5: T7 | V5: CN | W5: T2 | X5: T3 | Y5: T4 | Z5: T5 | AA5: T6 | AB5: T7 | AC5: CN | AD5: T2 | AE5: T3 | AF5: T4 | AG5: T5 | AH5: T6 | AI5: T7 | AJ5: CN | AM5: C | AN5: Chờ
A6: 1 | B6: 29E12436 | C6: Cont 50' | D6: XE00865 | E6: Phạm Văn Khâm | F6: x | G6: x | H6: x | I6: x | J6: x | K6: x | L6: x | M6: C | N6: C | O6: C | P6: C | Q6: C | R6: C | S6: C | T6: C | U6: C | V6: C | W6: C | X6: x | Y6: x | Z6: x | AA6: x | AB6: x | AC6: x | AD6: x | AE6: x | AF6: x | AG6: x | AH6: C | AI6: x | AJ6: x | AK6: =COUNTIF(F6:AJ6,"X")+COUNTIF(F6:AJ6,"C") -> 31 | AM6: O | AN6: Nghỉ phép
A7: 2 | B7: 29E12436 | C7: Cont 50' | D7: XE00985 | E7: Vũ Văn Quân | F7: x | G7: x | H7: x | I7: x | J7: x | K7: x | L7: x | M7: C | N7: C | O7: C | P7: C | Q7: C | R7: C | S7: C | T7: C | U7: C | V7: C | W7: C | X7: x | Y7: x | Z7: x | AA7: x | AB7: x | AC7: x | AD7: x | AE7: x | AF7: x | AG7: x | AH7: C | AI7: x | AJ7: x | AK7: =COUNTIF(F7:AJ7,"X")+COUNTIF(F7:AJ7,"C") -> 31
A8: 3 | B8: 29E14424 | C8: Cont 50' | D8: XE01034 | E8: Mã Đức Diễn | F8: C | G8: C | H8: C | I8: C | J8: C | K8: C | L8: C | M8: C | N8: C | O8: C | P8: C | Q8: C | R8: C | S8: C | T8: C | U8: x | V8: x | W8: x | X8: x | Y8: x | Z8: x | AA8: x | AB8: x | AC8: C | AD8: x | AE8: x | AF8: x | AG8: x | AH8: x | AI8: x | AJ8: x | AK8: =COUNTIF(F8:AJ8,"X")+COUNTIF(F8:AJ8,"C") -> 31
A9: 4 | B9: 29E14424 | C9: Cont 50' | D9: XE01064 | E9: Phạm Tuấn Sơn | F9: C | G9: C | H9: C | I9: C | J9: C | K9: C | L9: C | M9: C | N9: C | O9: C | P9: C | Q9: C | R9: C | S9: C | T9: C | U9: x | V9: x | W9: x | X9: x | Y9: x | Z9: x | AA9: x | AB9: x | AC9: C | AD9: x | AE9: x | AF9: x | AG9: x | AH9: x | AI9: x | AJ9: x | AK9: =COUNTIF(F9:AJ9,"X")+COUNTIF(F9:AJ9,"C") -> 31
A10: 5 | B10: 29E35397 | C10: Cont 50' | D10: XE00893 | E10: Vũ Ngọc Thường | F10: C | G10: C | H10: C | I10: C | J10: C | K10: x | L10: x | M10: x | N10: C | O10: C | P10: C | Q10: C | R10: x | S10: x | T10: x | U10: C | V10: C | W10: C | X10: C | Y10: C | Z10: C | AA10: x | AB10: x | AC10: x | AD10: x | AE10: C | AF10: x | AG10: x | AH10: x | AI10: C | AJ10: x | AK10: =COUNTIF(F10:AJ10,"X")+COUNTIF(F10:AJ10,"C") -> 31
A11: 6 | B11: 29E35397 | C11: Cont 50' | D11: XE01021 | E11: Vũ Văn Tỉnh | F11: C | G11: C | H11: C | I11: C | J11: C | K11: x | L11: x | M11: x | N11: C | O11: C | P11: C | Q11: C | R11: x | S11: x | T11: x | U11: C | V11: C | W11: C | X11: C | Y11: C | Z11: C | AA11: x | AB11: x | AC11: x | AD11: x | AE11: C | AF11: x | AG11: x | AH11: x | AI11: C | AJ11: x | AK11: =COUNTIF(F11:AJ11,"X")+COUNTIF(F11:AJ11,"C") -> 31
A12: 7 | B12: 29E12120 | C12: Cont 50' | D12: XE00853 | E12: Lê Thanh Đang | F12: C | G12: C | H12: C | I12: C | J12: C | K12: C | L12: C | M12: C | N12: C | O12: C | P12: C | Q12: C | R12: x | S12: x | T12: x | U12: x | V12: x | W12: x | X12: x | Y12: x | Z12: C | AA12: C | AB12: x | AC12: x | AD12: x | AE12: x | AF12: x | AG12: x | AH12: x | AI12: x | AJ12: C | AK12: =COUNTIF(F12:AJ12,"X")+COUNTIF(F12:AJ12,"C") -> 31
A13: 8 | B13: 29E12120 | C13: Cont 50' | D13: XE01303 | E13: Đào Văn Hùng | F13: C | G13: C | H13: C | I13: C | J13: C | K13: C | L13: C | M13: C | N13: C | O13: C | P13: C | Q13: C | R13: x | S13: x | T13: x | U13: x | V13: x | W13: x | X13: x | Y13: x | Z13: C | AA13: C | AB13: x | AK13: =COUNTIF(F13:AJ13,"X")+COUNTIF(F13:AJ13,"C") -> 23
A14: 9 | B14: 29E35064 | C14: Cont 50' | D14: XE01303 | E14: Đào Văn Hùng | AC14: x | AD14: x | AE14: x | AF14: C | AG14: x | AH14: x | AI14: x | AJ14: C | AK14: =COUNTIF(F14:AJ14,"X")+COUNTIF(F14:AJ14,"C") -> 8
A15: 10 | B15: 29E12333 | C15: Cont 50' | D15: XE00952 | E15: Nguyễn Văn Mạnh | F15: C | G15: C | H15: C | I15: C | J15: C | K15: x | L15: x | M15: x | N15: C | O15: C | P15: x | Q15: x | R15: x | S15: C | T15: C | U15: C | V15: C | W15: C | X15: C | Y15: C | Z15: x | AA15: x | AB15: x | AC15: x | AD15: x | AE15: x | AF15: x | AG15: x | AH15: x | AI15: x | AJ15: x | AK15: =COUNTIF(F15:AJ15,"X")+COUNTIF(F15:AJ15,"C") -> 31
A16: 11 | B16: 29E12333 | C16: Cont 50' | D16: XE01308 | E16: Phạm Văn Phố | F16: C | G16: C | H16: C | I16: C | J16: C | K16: x | L16: x | M16: x | N16: C | O16: C | P16: x | Q16: x | R16: x | S16: C | T16: C | U16: C | V16: C | W16: C | X16: C | Y16: C | Z16: x | AA16: x | AB16: x | AC16: x | AD16: x | AE16: x | AF16: x | AG16: x | AH16: x | AI16: x | AJ16: x | AK16: =COUNTIF(F16:AJ16,"X")+COUNTIF(F16:AJ16,"C") -> 31
A17: 12 | B17: 29E12143 | C17: Cont 50' | D17: XE00894 | E17: Phạm Ngọc Cần | F17: x | G17: x | H17: x | I17: x | J17: x | K17: x | L17: x | M17: x | N17: C | O17: C | P17: C | Q17: C | R17: C | S17: C | T17: C | U17: C | V17: C | W17: C | X17: x | Y17: x | Z17: x | AA17: x | AB17: x | AC17: x | AD17: x | AE17: Nghỉ việc | AK17: =COUNTIF(F17:AJ17,"X")+COUNTIF(F17:AJ17,"C") -> 25
A18: 13 | B18: 29E12143 | C18: Cont 50' | D18: XE00855 | E18: Đỗ Văn Nam | F18: x | G18: x | H18: x | I18: x | J18: x | K18: x | L18: x | M18: x | N18: C | O18: C | P18: C | Q18: C | R18: C | S18: C | T18: C | U18: C | V18: C | W18: C | X18: x | Y18: x | Z18: x | AA18: x | AB18: x | AC18: x | AD18: x | AK18: =COUNTIF(F18:AJ18,"X")+COUNTIF(F18:AJ18,"C") -> 25
A19: 14 | B19: 29E12143 | C19: Cont 50' | D19: XE00855 | E19: Đỗ Văn Nam | AE19: C | AF19: x | AG19: x | AH19: x | AI19: x | AJ19: C | AK19: =COUNTIF(F19:AJ19,"X")+COUNTIF(F19:AJ19,"C") -> 6
A20: 15 | B20: 29E14310 | C20: Cont 50' | D20: XE00907 | E20: Hoả Văn Lâm | F20: C | G20: C | H20: C | I20: C | J20: C | K20: C | L20: C | M20: C | N20: C | O20: C | P20: C | Q20: C | R20: C | S20: x | T20: x | U20: x | V20: C | W20: C | X20: x | Y20: x | Z20: x | AA20: C | AB20: C | AC20: C | AD20: C | AE20: x | AF20: x | AG20: x | AH20: x | AI20: x | AJ20: x | AK20: =COUNTIF(F20:AJ20,"X")+COUNTIF(F20:AJ20,"C") -> 31
A21: 16 | B21: 29E14310 | C21: Cont 50' | D21: XE00908 | E21: Hoả Văn Quyết | F21: C | G21: C | H21: C | I21: C | J21: C | K21: C | L21: C | M21: C | N21: C | O21: C | P21: C | Q21: C | R21: C | S21: x | T21: x | U21: x | V21: C | W21: C | X21: x | Y21: x | Z21: x | AA21: C | AB21: C | AC21: C | AD21: C | AE21: x | AF21: x | AG21: x | AH21: x | AI21: x | AJ21: x | AK21: =COUNTIF(F21:AJ21,"X")+COUNTIF(F21:AJ21,"C") -> 31
A22: 17 | B22: 29E12420 | C22: Cont 50' | D22: XE00843 | E22: Hà Nguyên Dậu | F22: x | G22: x | H22: x | I22: x | J22: C | K22: C | L22: C | M22: C | N22: C | O22: C | P22: C | Q22: C | R22: C | S22: C | T22: C | U22: C | V22: x | W22: x | X22: x | Y22: C | Z22: x | AA22: x | AB22: x | AC22: x | AD22: x | AE22: x | AF22: C | AG22: C | AH22: x | AI22: x | AJ22: x | AK22: =COUNTIF(F22:AJ22,"X")+COUNTIF(F22:AJ22,"C") -> 31
A23: 18 | B23: 29E12420 | C23: Cont 50' | D23: XE00844 | E23: Nguyễn Thanh Bình B | F23: x | G23: x | H23: x | I23: x | J23: C | K23: C | L23: C | M23: C | N23: C | O23: C | P23: C | Q23: C | R23: C | S23: C | T23: C | U23: C | V23: x | W23: x | X23: x | Y23: C | Z23: x | AA23: x | AB23: x | AC23: x | AD23: x | AE23: x | AF23: C | AG23: C | AH23: x | AI23: x | AJ23: x | AK23: =COUNTIF(F23:AJ23,"X")+COUNTIF(F23:AJ23,"C") -> 31
A24: 19 | B24: 29E14214 | C24: Cont 50' | D24: XE00909 | E24: Trần Xuân Thoả | F24: x | G24: x | H24: x | I24: x | J24: x | K24: x | L24: x | M24: C | N24: C | O24: C | P24: C | Q24: C | R24: C | S24: C | T24: C | U24: C | V24: C | W24: C | X24: x | Y24: x | Z24: x | AA24: x | AB24: x | AC24: C | AD24: x | AE24: x | AF24: x | AG24: x | AH24: x | AI24: C | AJ24: C | AK24: =COUNTIF(F24:AJ24,"X")+COUNTIF(F24:AJ24,"C") -> 31
A25: 20 | B25: 29E14214 | C25: Cont 50' | D25: XE00910 | E25: Đỗ Ngọc Chiến | F25: x | G25: x | H25: x | I25: x | J25: x | K25: x | L25: x | M25: C | N25: C | O25: C | P25: C | Q25: C | R25: C | S25: C | T25: C | U25: C | V25: C | W25: C | X25: x | Y25: x | Z25: x | AA25: x | AB25: x | AC25: C | AD25: x | AE25: x | AF25: x | AG25: x | AH25: x | AI25: C | AJ25: C | AK25: =COUNTIF(F25:AJ25,"X")+COUNTIF(F25:AJ25,"C") -> 31
A26: 21 | B26: 29E35164 | C26: Cont 50' | D26: XE00854 | E26: Phạm Quốc Toàn | F26: C | G26: C | H26: C | I26: C | J26: C | K26: x | L26: x | M26: x | N26: x | O26: x | P26: x | Q26: x | R26: x | S26: x | T26: x | U26: x | V26: x | W26: x | X26: x | Y26: x | Z26: x | AA26: x | AB26: x | AC26: x | AD26: x | AE26: x | AF26: C | AG26: C | AH26: x | AI26: x | AJ26: C | AK26: =COUNTIF(F26:AJ26,"X")+COUNTIF(F26:AJ26,"C") -> 31
A27: 22 | B27: 29E35164 | C27: Cont 50' | D27: XE00991 | E27: Đào Ngọc Ngà | F27: C | G27: C | H27: C | I27: C | J27: C | K27: x | L27: x | M27: x | N27: x | O27: x | P27: x | Q27: x | R27: x | S27: x | T27: x | U27: x | V27: x | W27: x | X27: x | Y27: x | Z27: x | AA27: x | AB27: x | AC27: x | AD27: x | AE27: x | AF27: C | AG27: C | AH27: x | AI27: x | AJ27: C | AK27: =COUNTIF(F27:AJ27,"X")+COUNTIF(F27:AJ27,"C") -> 31
A28: 23 | B28: 29E35064 | C28: Cont 50' | D28: XE01443 | E28: Trần Quang Trung | F28: C | G28: C | H28: C | I28: C | J28: C | K28: C | L28: C | M28: C | N28: C | O28: C | P28: C | Q28: C | R28: x | S28: x | T28: x | U28: x | V28: x | W28: x | X28: x | Y28: x | Z28: x | AA28: x | AB28: x | AC28: C | AD28: Nghỉ việc | AK28: =COUNTIF(F28:AJ28,"X")+COUNTIF(F28:AJ28,"C") -> 24
A29: 24 | B29: 29E35064 | C29: Cont 50' | D29: XE01444 | E29: Trần Xuân Quảng | F29: C | G29: C | H29: C | I29: C | J29: C | K29: C | L29: C | M29: C | N29: C | O29: C | P29: C | Q29: C | R29: x | S29: x | T29: x | U29: x | V29: x | W29: x | X29: x | Y29: x | Z29: x | AA29: x | AB29: x | AC29: C | AD29: Nghỉ việc | AK29: =COUNTIF(F29:AJ29,"X")+COUNTIF(F29:AJ29,"C") -> 24
A30: 25 | B30: 29E12412 | C30: Cont 50' | D30: XE01539 | E30: Nguyễn Ngọc Tịnh | F30: C | G30: C | H30: C | I30: C | J30: C | K30: C | L30: C | M30: C | N30: C | O30: C | P30: C | Q30: C | R30: C | S30: x | T30: x | U30: x | V30: x | W30: x | X30: x | Y30: x | Z30: x | AA30: x | AB30: x | AK30: =COUNTIF(F30:AJ30,"X")+COUNTIF(F30:AJ30,"C") -> 23
A31: 26 | B31: 29E35064 | C31: Cont 50' | D31: XE01539 | E31: Nguyễn Ngọc Tịnh | AC31: x | AD31: x | AE31: x | AF31: C | AG31: C | AH31: x | AI31: x | AJ31: C | AK31: =COUNTIF(F31:AJ31,"X")+COUNTIF(F31:AJ31,"C") -> 8
A32: 27 | B32: 29E12412 | C32: Cont 50' | D32: XE00858 | E32: Đỗ Ngọc Thông | F32: C | G32: C | H32: C | I32: C | J32: C | K32: C | L32: C | M32: C | N32: C | O32: C | Q32: C | R32: C | S32: x | T32: x | U32: x | V32: x | W32: x | X32: x | Y32: x | Z32: x | AA32: x | AB32: x | AC32: x | AD32: x | AE32: x | AF32: x | AG32: C | AH32: C | AI32: C | AJ32: C | AK32: =COUNTIF(F32:AJ32,"X")+COUNTIF(F32:AJ32,"C") -> 30
A33: 28 | B33: 29E12143 | C33: Cont 50' | D33: XE01709 | E33: Phạm Văn Thiêm | AE33: C | AF33: x | AG33: x | AH33: x | AI33: x | AJ33: C | AK33: =COUNTIF(F33:AJ33,"X")+COUNTIF(F33:AJ33,"C") -> 6
W41: PVTHH | AG41: Người lập
W46: Lương Văn Tùng | AG46: Hoàng Thu Nguyệt

Sheet MNV
A1: Mã NV | B1: Lái xe
A2: XE00979 | B2: Lê Đình Ngũ | E2: BKS | F2: Loại xe
A3: XE00975 | B3: Nguyễn Văn Luận
A4: XE00977 | B4: Trần Trung Kiên | E4: 29H73703 | F4: 2.5T
A5: XE00768 | B5: Đinh Mai Sơn | E5: 29K13511 | F5: 2.5T
A6: XE00777 | B6: Hoàng Đức Mạnh | E6: 29H84991 | F6: 3.5T
A7: XE00730 | B7: Nguyễn Hữu Tùng | E7: 29G02319 | F7: 6.5T
A8: XE00953 | B8: Mai Văn Ngọc | E8: 29G02311 | F8: 6.5T
A9: XE00832 | B9: Hoàng Văn Chuyền | E9: 29E08058 | F9: 6.5T
A10: XE00900 | B10: Đặng Văn Thắng | E10: 29B18964 | F10: 6.5T
A11: XE01004 | B11: Trần Văn Cương | E11: 29G02320 | F11: 6.5T
A12: XE00447 | B12: Lê Văn Giang | E12: 29E12348 | F12: 6.5T
A13: XE00615 | B13: Nguyễn Trọng Tấn | E13: 29K06711 | F13: 5.5T
A14: XE00449 | B14: Phạm Văn Hải A | E14: 29K06374 | F14: 8T
A15: XE00847 | B15: Mai Văn Toản | E15: 29K13742 | F15: 8T
... A56: XE01102 | B56: Lê Thế Xuân | E56: 29E12420 | F56: Cont 50F
A57: XE00705 | B57: Hoàng Minh Thịnh | F57: Mooc
A58: XE00671 | B58: Lê Mạnh Cường | E58: 29E12143 | F58: Cont 50F
A59: XE00817 | B59: Phạm Hồng Thái | F59: Mooc
A60: XE00895 | B60: Lê Văn Tuyền | E60: 29E12333 | F60: Cont 50F
A61: XE00701 | B61: Nguyễn Minh Hiếu | F61: Mooc
A62: XE00818 | B62: Trần Văn Thanh | E62: 29E12412 | F62: Cont 50F
A63: XE01112 | B63: Trần Văn Cao | F63: Mooc
A64: XE01149 | B64: Phạm Văn Thưởng | E64: 29E12120 | F64: Cont 50F
A65: XE01151 | B65: Trịnh Đức Trọng | F65: Mooc
A66: XE01164 | B66: Trịnh Văn Lực | E66: 29E12436 | F66: Cont 50F
A67: XE01175 | B67: Vũ Văn Quân B | F67: Mooc
A68: XE01183 | B68: Ngô Văn Lợi | E68: 29E14424 | F68: Cont 50F
A69: XE01186 | B69: Chu Phú Thao | F69: Mooc
A70: XE01198 | B70: Nguyễn Đức Dương | E70: 29E14214 | F70: Cont 50F
A71: XE01199 | B71: Bùi Văn Khánh | F71: Mooc
A72: XE01205 | B72: Phùng Hải Đăng | E72: 29E14310 | F72: Cont 50F
A73: XE01212 | B73: Nguyễn Đức Mạnh | F73: Mooc
A74: XE01215 | B74: Lê Văn Đông | E74: 29E35397 | F74: Cont 50F
A75: XE01244 | B75: Nguyễn Thừa Vinh | F75: Mooc
A76: XE01245 | B76: Trần Công Vương | E76: 29E35164 | F76: Cont 50F
A77: XE01246 | B77: Cao Văn Dương | F77: Mooc
A78: XE01250 | B78: Nguyễn Văn Trung | E78: 29E35064 | F78: Cont 50F
A79: XE01247 | B79: Vũ Văn Tường | F79: Mooc
A80: XE00862 | B80: Lại Hợp Huấn | E80: 29E00028 | F80: 8T
...
