Workbook

Sheet Tong hop
A3: Row Labels | B3: Mã nhân viên | C3: BSX | D3: DỰ ÁN | E3: Trọng Tải | F3: Sum of DT tính lương lái xe
A4: Bùi Phi Hùng | B4: XE01420 | C4: 29K06711 | D4: Đại Đồng Tiến | E4: 5.5T | F4: 4644000
D5: Arttek | E5: 5.5T | F5: 2000000
C6: 29E59034 | D6: Hoàng Nam | E6: 2T5 | F6: 3500000
A7: Bùi Văn Đào | B7: XE01331 | C7: 29E08175 | D7: Hàng ngoài | E7: 15T | F7: 15147500
D8: Hoàng Nam | E8: 15T | F8: 6957500
D9: VTP Lâm Đồng | E9: 15T | F9: 4156000
D10: Hoàng Minh | E10: 15T | F10: 28047500
D11: Hưng Thịnh | E11: 15T | F11: 21000000
D12: TTC | E12: 15T | F12: 1050000
D13: VTP Đà Nẵng | E13: 15T | F13: 896000
D14: Nguyễn Hoàng | E14: 15T | F14: 1144000
D15: VTP HCM | E15: 15T | F15: 28870000
A16: Đào Ngọc Ngà | B16: XE00991 | C16: 29E35164 | D16: Viettel Log | E16: Cont 50F | F16: 13000000
D17: Trái cây Bích Ngân | E17: Cont 50F | F17: 79000000
D18: Thuốc lá Thăng Long | E18: Cont 50F | F18: 19693206
D19: Vận tải Á Đông | E19: Cont 50F | F19: 12500000
A20: Đào Văn Hùng | B20: XE01303 | C20: 29E35064 | D20: Viettel Log | E20: Cont 50F | F20: 11750000
C21: 29E12120 | D21: Dược HG cont | E21: Cont 50F | F21: 29978000
D22: Trái cây Bích Ngân | E22: Cont 50F | F22: 39225000
D23: Thuốc lá Thăng Long | E23: Cont 50F | F23: 20983644
A24: Đặng Công Đức | B24: XE01417 | C24: 29E44377 | D24: Hàng ngoài | E24: 7.1t | F24: 48500000
D25: VTP Lâm Đồng | E25: 7.1t | F25: 600000
D26: Hoàng Minh | E26: 7.1t | F26: 31250000
D27: OPL | E27: 7.1t | F27: 7250000
D28: Hưng Thịnh | E28: 7.1t | F28: 9750000
D29: VTP HCM | E29: 7.1t | F29: 28000000
D30: Thần Đèn | E30: 7.1t | F30: 1497600
A31: Đặng Văn Thắng | B31: XE00900 | C31: 29G02319 | D31: Xe đạp Thống Nhất | E31: 6.5T | F31: 2363192
C32: 29E12348 | D32: Xe đạp Thống Nhất | E32: 6.5T | F32: 17183424
D33: Thuốc lá Thăng Long | E33: 6.5T | F33: 1239256
C34: 29E38311 | D34: Xe đạp Thống Nhất | E34: 8T | F34: 3396093
D35: Thuốc lá Thăng Long | E35: 8T | F35: 9744596
D36: DHL | E36: 8T | F36: 3078000
A37: Đinh Mai Sơn | B37: XE00768 | C37: 29K13511 | D37: VTP Aeon | E37: 2.5T | F37: 48582206
A38: Đỗ Ngọc Chiến | B38: XE00910 | C38: 29E14214 | D38: VTP Đà Nẵng | E38: Cont 50F | F38: 6000000
D39: Viettel Log | E39: Cont 50F | F39: 11750000
D40: Dược HG cont | E40: Cont 50F | F40: 61419000
D41: FTC | E41: Cont 50F | F41: 9950000
A42: Đỗ Ngọc Thông | B42: XE00858 | C42: 29E12412 | D42: Viettel Log | E42: Cont 50F | F42: 36000000
...

Sheet trong tai
A3: Trọng Tải | B3: Lái xe | C3: Mã nhân viên | D3: BSX | E3: DỰ ÁN | F3: Sum of DT tính lương lái xe
B4: Lái xe vendor | D4: 60H33681 | E4: Ninja | F4: 21000000
B5: Lái xe vendor | D5: 20G00154 | E5: Ninja | F5: 21000000
B6: Lái xe vendor | D6: 29H79260 | E6: OPL | F6: 14500000
B7: Lái xe vendor | D7: 29E26651 | E7: Trung Chính | F7: 18000000
B8: Lái xe vendor | D8: 29K11345 | E8: Trung Chính | F8: 18000000
B9: Lái xe vendor Total | F9: 92500000
A10: Sum | F10: 92500000
A11: 3T5 Lạnh | B11: Lê Minh Vin | C11: XE01379 | D11: 29E49820 | E11: VTP Đăklăk | F11: 10000000
B12: Lê Minh Vin | E12: DHG Nam | F12: 88428000
B13: Lê Minh Vin Total | F13: 98428000
B14: Nguyễn Hữu Tùng | C14: XE00730 | D14: 29E52540 | E14: DHG Bắc | F14: 71990000
B15: Nguyễn Hữu Tùng | E15: VTP Aeon | F15: 6471193
B16: Nguyễn Hữu Tùng Total | F16: 78461193
A17: 3T5 Lạnh Sum | F17: 176889193
A18: 1.5T | B18: Trần Văn Phú | C18: XE00842 | D18: 29G02346 | E18: CPN | F18: 13156000
B19: Trần Văn Phú | D19: 29H74340 | E19: CPN | F19: 84483000
B20: Trần Văn Phú | D20: 29G02330 | E20: CPN | F20: 4550000
B21: Trần Văn Phú Total | F21: 102189000
B22: Huỳnh Y Bảo | C22: XE01685 | D22: 29G02314 | E22: OPL | F22: 2200000
B23: Huỳnh Y Bảo Total | F23: 2200000
A24: 1.5T Sum | F24: 104389000
A25: 15T | B25: Bùi Văn Đào | C25: XE01331 | D25: 29E08175 | E25: Hàng ngoài | F25: 15147500
B26: Bùi Văn Đào | E26: Hoàng Nam | F26: 6957500
B27: Bùi Văn Đào | E27: VTP Lâm Đồng | F27: 4156000
B28: Bùi Văn Đào | E28: Hoàng Minh | F28: 28047500
B29: Bùi Văn Đào | E29: Hưng Thịnh | F29: 21000000
B30: Bùi Văn Đào | E30: TTC | F30: 1050000
B31: Bùi Văn Đào | E31: VTP Đà Nẵng | F31: 896000
B32: Bùi Văn Đào | E32: Nguyễn Hoàng | F32: 1144000
B33: Bùi Văn Đào | E33: VTP HCM | F33: 28870000
B34: Bùi Văn Đào Total | F34: 107268500
B35: Kiều Kim Tiến | C35: XE00873 | D35: 29E08413 | E35: Hoàng Minh | F35: 9750000
B36: Kiều Kim Tiến | E36: VTP HCM | F36: 6675000
B37: Kiều Kim Tiến | E37: VTP Đồng Nai | F37: 9000000
B38: Kiều Kim Tiến Total | F38: 25425000
B39: Lê Thế Xuân | C39: XE01102 | D39: 29K07924 | E39: Hoàng Minh | F39: 73211112
B40: Lê Thế Xuân | E40: VTP Đà Nẵng | F40: 17500000
B41: Lê Thế Xuân | E41: Nongshim | F41: 6637500
B42: Lê Thế Xuân | E42: VTP HCM | F42: 775000
...

Sheet Du an
A3: Row Labels | B3: Lái xe | C3: Mã nhân viên | D3: BSX | E3: Trọng Tải | F3: Sum of DT tính lương lái xe
A4: Đại Đồng Tiến | B4: Bùi Phi Hùng | C4: XE01420 | D4: 29K06711 | E4: 5.5T | F4: 4644000
B5: Nguyễn Quốc Bình | C5: XE01005 | D5: 29K13905 | E5: 8T | F5: 6642000
B6: Trịnh Văn Lực | C6: XE01164 | D6: 29K13905 | E6: 8T | F6: 6642000
A7: Đại Đồng Tiến Sum | F7: 17928000
A8: Hàng ngoài | B8: Bùi Văn Đào | C8: XE01331 | D8: 29E08175 | E8: 15T | F8: 15147500
B9: Đặng Công Đức | C9: XE01417 | D9: 29E44377 | E9: 7.1t | F9: 48500000
B10: Hà Nguyên Dậu | C10: XE00843 | D10: 29E12420 | E10: Cont 50F | F10: 8500000
B11: Hoàng Văn Lợi | C11: XE01456 | D11: 29K13459 | E11: 8T | F11: 2750000
B12: Lê Quốc Quân | C12: XE01434 | D12: 29E44369 | E12: 7.1t | F12: 1950000
B13: Nguyễn Công Binh | C13: XE01418 | D13: 29E44377 | E13: 7.1t | F13: 9500000
B14: Nguyễn Công Thức | C14: XE01325 | D14: 29B20543 | E14: 7.1t | F14: 14750000
B15: Nguyễn Đức Linh | C15: XE01326 | D15: 29B20543 | E15: 7.1t | F15: 14750000
B16: Nguyễn Hữu Hưởng | C16: XE01304 | D16: 29K06820 | E16: 8T | F16: 2220000
B17: Nguyễn Ngọc Ân | C17: XE01316 | D17: 29E00028 | E17: 8T | F17: 20500000
B18: Nguyễn Thanh Bình | C18: XE00844 | D18: 29E12420 | E18: Cont 50F | F18: 8500000
B19: Nguyễn Văn Chí | C19: XE01433 | D19: 29E44369 | E19: 7.1t | F19: 1950000
B20: Phạm Thanh Tuấn | C20: XE01335 | D20: 29E12747 | E20: 8T | F20: 2500000
... B39: Trần Phúc Đạt | C39: XE01527 | D39: 29E38331 | E39: 8T | F39: 1500000
D40: 29G02349 | E40: 8T | F40: 1500000
B41: Lê Văn Hoàng | C41: XE01534 | D41: 29E00028 | E41: 8T | F41: 20500000
B42: Phan Tấn Thành | C42: XE01532 | D42: 29C37344 | E42: 8T | F42: 2000000
B43: Võ Minh Liệp | C43: XE01543 | D43: 29H70193 | E43: 8T | F43: 7225000
B44: Nguyễn Khánh Phú | C44: XE01552 | D44: 29E38345 | E44: 8T | F44: 8700000
B45: Mai Tấn Toàn | C45: XE01551 | D45: 29E38345 | E45: 8T | F45: 8700000
B46: Lê Thanh Sơn | C46: XE01541 | D46: 29E54261 | E46: 7.1t | F46: 5000000
B47: Cao Tuấn Anh | C47: XE01590 | D47: 29E38159 | E47: 8T | F47: 9350000
B48: Cao Phong Anh | C48: XE01591 | D48: 29E38159 | E48: 8T | F48: 9350000
B49: Nguyễn Thanh Nhân | C49: XE01574 | D49: 29E38331 | E49: 8T | F49: 1500000
D50: 29G02349 | E50: 8T | F50: 1500000
B51: Nguyễn Minh Trọng | C51: XE01599 | D51: 29K13459 | E51: 8T | F51: 2750000
B52: Nguyễn Duy Tuấn | C52: XE01548 | D52: 29C37344 | E52: 8T | F52: 7500000
B53: Ngô Hoàng Vũ | C53: XE01549 | D53: 29C37344 | E53: 8T | F53: 7500000
B54: Nguyễn Văn Chiến | C54: XE01582 | D54: 29E38128 | E54: 8T | F54: 16400000
B55: Nguyễn Văn Thắng | C55: XE01583 | D55: 29E38128 | E55: 8T | F55: 16400000
B56: Nguyễn Đức Toàn | C56: XE01600 | D56: 29E44326 | E56: 7.1t | F56: 1500000
B57: Trần Bá Lương | C57: XE01537 | D57: 29K13582 | E57: 2.5T | F57: 360000
B58: Huỳnh Xuân Nhân | C58: XE01671 | D58: 29E44377 | E58: 7.1t | F58: 39000000
B59: Lý Hồng Ngà | C59: XE01622 | D59: 29H70193 | E59: 8T | F59: 7225000
B60: Cao Hoài Tiên | C60: XE01477 | D60: 29E12401 | E60: 15T | F60: 10500000
...

Sheet Lai xe
A3: Row Labels | B3: Mã nhân viên | C3: BSX | D3: Trọng Tải | E3: DỰ ÁN | F3: Sum of DT tính lương lái xe
A4: Bùi Phi Hùng | B4: XE01420 | C4: 29K06711 | D4: 5.5T | E4: Đại Đồng Tiến | F4: 4644000
E5: Arttek | F5: 2000000
C6: 29E59034 | D6: 2T5 | E6: Hoàng Nam | F6: 3500000
A7: Bùi Phi Hùng Sum | F7: 10144000
A8: Bùi Văn Đào | B8: XE01331 | C8: 29E08175 | D8: 15T | E8: Hàng ngoài | F8: 15147500
E9: Hoàng Nam | F9: 6957500
E10: VTP Lâm Đồng | F10: 4156000
E11: Hoàng Minh | F11: 28047500
E12: Hưng Thịnh | F12: 21000000
E13: TTC | F13: 1050000
E14: VTP Đà Nẵng | F14: 896000
E15: Nguyễn Hoàng | F15: 1144000
E16: VTP HCM | F16: 28870000
A17: Bùi Văn Đào Sum | F17: 107268500
A18: Đào Ngọc Ngà | B18: XE00991 | C18: 29E35164 | D18: Cont 50F | E18: Viettel Log | F18: 13000000
E19: Trái cây Bích Ngân | F19: 79000000
E20: Thuốc lá Thăng Long | F20: 19693206
E21: Vận tải Á Đông | F21: 12500000
A22: Đào Ngọc Ngà Sum | F22: 124193206
A23: Đào Văn Hùng | B23: XE01303 | C23: 29E12120 | D23: Cont 50F | E23: Dược HG cont | F23: 29978000
E24: Trái cây Bích Ngân | F24: 39225000
E25: Thuốc lá Thăng Long | F25: 20983644
C26: 29E35064 | D26: Cont 50F | E26: Viettel Log | F26: 11750000
A27: Đào Văn Hùng Sum | F27: 101936644
A28: Đặng Công Đức | B28: XE01417 | C28: 29E44377 | D28: 7.1t | E28: Hàng ngoài | F28: 48500000
E29: VTP Lâm Đồng | F29: 600000
E30: Hoàng Minh | F30: 31250000
E31: OPL | F31: 7250000
E32: Hưng Thịnh | F32: 9750000
E33: VTP HCM | F33: 28000000
E34: Thần Đèn | F34: 1497600
A35: Đặng Công Đức Sum | F35: 126847600
A36: Đặng Văn Thắng | B36: XE00900 | C36: 29E12348 | D36: 6.5T | E36: Xe đạp Thống Nhất | F36: 17183424
E37: Thuốc lá Thăng Long | F37: 1239256
C38: 29E38311 | D38: 8T | E38: Xe đạp Thống Nhất | F38: 3396093
E39: Thuốc lá Thăng Long | F39: 9744596
E40: DHL | F40: 3078000
C41: 29G02319 | D41: 6.5T | E41: Xe đạp Thống Nhất | F41: 2363192
A42: Đặng Văn Thắng Sum | F42: 37004561
...

Sheet Doanh thu
A1: BẢNG TỔNG HỢP DOANH THU CHI TIẾT CÁC DỰ ÁN T5.2026_P.VTHH | O1: Hệ số | P1: 1
L2: =SUBTOTAL(9,L4:L29910) -> 8.7742717e+09 | M2: =SUBTOTAL(9,M4:M29910) -> 212906000 | N2: =SUBTOTAL(9,N4:N29910) -> 8.5613657e+09 | O2: =SUBTOTAL(9,O4:O29910) -> 8.5613657e+09 | S2: =SUBTOTAL(9,S4:S29910) -> 1.5895222e+08
A3: STT | B3: Ngày đi | C3: Ngày về | D3: DỰ ÁN | E3: KH CỤ THỂ | F3: Tuyến Vận chuyển | G3: Điểm lấy hàng | H3: Điểm giao hàng | I3: BSX | J3: Lái xe | K3: NVT | L3: Doanh thu trước thuế (gồm toàn bộ CP) | M3: Chi phí (bốc xếp, sang tải…) | N3: DT bao gồm CP xăng dầu | O3: DT tính lương lái xe | P3: Mã nhân viên | Q3: Trọng Tải | R3: Ghi chú | S3: Chiết khấu
A4: 1 | B4: 46154 | D4: AK FOOD | E4: AK FOOD | F4: Tuyến chính | G4: Hồ Chí Minh | H4: Hà Nội | I4: 29E12747 | J4: Phạm Thanh Tuấn | K4: XEVN | L4: 3467300 | M4: 120000 | N4: =L4-M4 -> 3347300 | O4: =N4/$P$1 -> 3347300 | P4: =IFERROR(VLOOKUP(J4,'Mã NV'!$B:$C,2,0),"") -> XE01335 | Q4: =IFERROR(VLOOKUP(I4,'Mã NV'!$J:$K,2,0),"") -> 8T
A5: =A4+1 -> 2 | B5: 46154 | D5: AK FOOD | E5: AK FOOD | F5: Tuyến chính | G5: Hồ Chí Minh | H5: Hà Nội | I5: 29E12747 | J5: Nguyễn Thanh Lâm | K5: XEVN | L5: 3467300 | M5: 120000 | N5: =L5-M5 -> 3347300 | O5: =N5/$P$1 -> 3347300 | P5: =IFERROR(VLOOKUP(J5,'Mã NV'!$B:$C,2,0),"") -> XE01644 | Q5: =IFERROR(VLOOKUP(I5,'Mã NV'!$J:$K,2,0),"") -> 8T
A6: =A5+1 -> 3 | B6: 46156 | D6: AK FOOD | E6: AK FOOD | F6: Trung chuyển | G6: Hồ Chí Minh | H6: Hà Nội | I6: 29K13582 | J6: Trần Bá Lương | K6: XEVN | L6: 1733650 | M6: 60000 | N6: 1673650 | O6: =N6/$P$1 -> 1673650 | P6: =IFERROR(VLOOKUP(J6,'Mã NV'!$B:$C,2,0),"") -> XE01537 | Q6: =IFERROR(VLOOKUP(I6,'Mã NV'!$J:$K,2,0),"") -> 2.5T
A7: =A6+1 -> 4 | B7: 46160 | D7: Bảo Hoàng | E7: Bảo Hoàng (KD Đức) | F7: Tuyến chính | G7: Hà Nội | H7: Đà Nẵng + Hồ Chí Minh | I7: 29H70193 | J7: Võ Minh Liệp | K7: XEVN | L7: 1000000 | M7: 0 | N7: =L7-M7 -> 1000000 | O7: =N7/$P$1 -> 1000000 | P7: =IFERROR(VLOOKUP(J7,'Mã NV'!$B:$C,2,0),"") -> XE01543 | Q7: =IFERROR(VLOOKUP(I7,'Mã NV'!$J:$K,2,0),"") -> 8T
A8: =A7+1 -> 5 | B8: 46160 | D8: Bảo Hoàng | E8: Bảo Hoàng (KD Đức) | F8: Tuyến chính | G8: Hà Nội | H8: Đà Nẵng + Hồ Chí Minh | I8: 29H70193 | J8: Lý Hồng Ngà | K8: XEVN | L8: 1000000 | M8: 0 | N8: =L8-M8 -> 1000000 | O8: =N8/$P$1 -> 1000000 | P8: =IFERROR(VLOOKUP(J8,'Mã NV'!$B:$C,2,0),"") -> XE01622 | Q8: =IFERROR(VLOOKUP(I8,'Mã NV'!$J:$K,2,0),"") -> 8T
A9: =A8+1 -> 6 | B9: 46163 | D9: Bảo Hoàng | E9: Bảo Hoàng | F9: Tuyến chính | G9: Hà Nội | H9: Hô Chí Minh | I9: 29C37344 | J9: Phan Tấn Thành | K9: XEVN | L9: 1750000 | M9: 0 | N9: =L9-M9 -> 1750000 | O9: =N9/$P$1 -> 1750000 | P9: =IFERROR(VLOOKUP(J9,'Mã NV'!$B:$C,2,0),"") -> XE01532 | Q9: =IFERROR(VLOOKUP(I9,'Mã NV'!$J:$K,2,0),"") -> 8T
A10: =A9+1 -> 7 | B10: 46163 | D10: Bảo Hoàng | E10: Bảo Hoàng | F10: Tuyến chính | G10: Hà Nội | H10: Hô Chí Minh | I10: 29C37344 | J10: Đinh Văn Phấn | K10: XEVN | L10: 1750000 | M10: 0 | N10: =L10-M10 -> 1750000 | O10: =N10/$P$1 -> 1750000 | P10: =IFERROR(VLOOKUP(J10,'Mã NV'!$B:$C,2,0),"") | Q10: =IFERROR(VLOOKUP(I10,'Mã NV'!$J:$K,2,0),"") -> 8T
A11: =A10+1 -> 8 | B11: 46167 | D11: Bảo Hoàng | E11: Bảo Hoàng | F11: Tuyến chính | G11: Hà Nội | H11: Quảng Trị | I11: 29E08413 | J11: Trần Hữu Khánh | K11: XEVN | L11: 1200000 | M11: 0 | N11: =L11-M11 -> 1200000 | O11: =N11/$P$1 -> 1200000 | P11: =IFERROR(VLOOKUP(J11,'Mã NV'!$B:$C,2,0),"") -> XE01470 | Q11: =IFERROR(VLOOKUP(I11,'Mã NV'!$J:$K,2,0),"") -> 15T
A12: =A11+1 -> 9 | B12: 46167 | D12: Bảo Hoàng | E12: Bảo Hoàng | F12: Tuyến chính | G12: Hà Nội | H12: Quảng Trị | I12: 29E08413 | J12: Phạm Ngọc Ẩn | K12: XEVN | L12: 1200000 | M12: 0 | N12: =L12-M12 -> 1200000 | O12: =N12/$P$1 -> 1200000 | P12: =IFERROR(VLOOKUP(J12,'Mã NV'!$B:$C,2,0),"") -> XE01690 | Q12: =IFERROR(VLOOKUP(I12,'Mã NV'!$J:$K,2,0),"") -> 15T
A13: =A12+1 -> 10 | B13: 46155 | D13: Dược GMP EU | E13: Dược GMP EU | F13: Tuyến chính | G13: Hà Nội | H13: Hưng Yên | I13: 29E61253 | J13: Nguyễn Hữu Tuấn | K13: XEVN | L13: 1199968 | M13: 0 | N13: =L13-M13 -> 1199968 | O13: =N13/$P$1 -> 1199968 | P13: =IFERROR(VLOOKUP(J13,'Mã NV'!$B:$C,2,0),"") -> XE01615 | Q13: =IFERROR(VLOOKUP(I13,'Mã NV'!$J:$K,2,0),"") -> 2T5
A14: =A13+1 -> 11 | B14: 46147 | D14: Dược HG cont | E14: Dược HG cont | F14: Tuyến chính | G14: Cần Thơ | H14: Nghệ An + Hưng Yên | I14: 29E14214 | J14: Trần Xuân Thỏa | K14: XEVN | L14: 33341000 | M14: 1900000 | N14: =L14-M14 -> 31441000 | O14: =N14/$P$1 -> 31441000 | P14: =IFERROR(VLOOKUP(J14,'Mã NV'!$B:$C,2,0),"") -> XE00909 | Q14: =IFERROR(VLOOKUP(I14,'Mã NV'!$J:$K,2,0),"") -> Cont 50F | S14: =L14*5% -> 1667050
A15: =A14+1 -> 12 | B15: 46147 | D15: Dược HG cont | E15: Dược HG cont | F15: Tuyến chính | G15: Cần Thơ | H15: Nghệ An + Hưng Yên | I15: 29E14214 | J15: Đỗ Ngọc Chiến | K15: XEVN | L15: 33341000 | M15: 1900000 | N15: =L15-M15 -> 31441000 | O15: =N15/$P$1 -> 31441000 | P15: =IFERROR(VLOOKUP(J15,'Mã NV'!$B:$C,2,0),"") -> XE00910 | Q15: =IFERROR(VLOOKUP(I15,'Mã NV'!$J:$K,2,0),"") -> Cont 50F | S15: =L15*5% -> 1667050
A16: =A15+1 -> 13 | B16: 46153 | D16: Dược HG cont | E16: Dược HG cont | F16: Tuyến chính | G16: Cần Thơ | H16: Nghệ An + Hưng Yên | I16: 29E12333 | J16: Phạm Văn Phố | K16: XEVN | L16: 33341000 | M16: 1900000 | N16: =L16-M16 -> 31441000 | O16: =N16/$P$1 -> 31441000 | P16: =IFERROR(VLOOKUP(J16,'Mã NV'!$B:$C,2,0),"") -> XE01308 | Q16: =IFERROR(VLOOKUP(I16,'Mã NV'!$J:$K,2,0),"") -> Cont 50F | S16: =L16*5% -> 1667050
A17: =A16+1 -> 14 | B17: 46153 | D17: Dược HG cont | E17: Dược HG cont | F17: Tuyến chính | G17: Cần Thơ | H17: Nghệ An + Hưng Yên | I17: 29E12333 | J17: Nguyễn Văn Mạnh | K17: XEVN | L17: 33341000 | M17: 1900000 | N17: =L17-M17 -> 31441000 | O17: =N17/$P$1 -> 31441000 | P17: =IFERROR(VLOOKUP(J17,'Mã NV'!$B:$C,2,0),"") -> XE00952 | Q17: =IFERROR(VLOOKUP(I17,'Mã NV'!$J:$K,2,0),"") -> Cont 50F | S17: =L17*5% -> 1667050
A18: =A17+1 -> 15 | B18: 46155 | D18: Dược HG cont | E18: Dược HG cont | F18: Tuyến chính | G18: Cần Thơ | H18: Nghệ An + Hưng Yên | I18: 29E35397 | J18: Vũ Văn Tỉnh | K18: XEVN | L18: 33341000 | M18: 1900000 | N18: =L18-M18 -> 31441000 | O18: =N18/$P$1 -> 31441000 | P18: =IFERROR(VLOOKUP(J18,'Mã NV'!$B:$C,2,0),"") -> XE01021 | Q18: =IFERROR(VLOOKUP(I18,'Mã NV'!$J:$K,2,0),"") -> Cont 50F | S18: =L18*5% -> 1667050
A19: =A18+1 -> 16 | B19: 46155 | D19: Dược HG cont | E19: Dược HG cont | F19: Tuyến chính | G19: Cần Thơ | H19: Nghệ An + Hưng Yên | I19: 29E35397 | J19: Vũ Ngọc Thường | K19: XEVN | L19: 33341000 | M19: 1900000 | N19: =L19-M19 -> 31441000 | O19: =N19/$P$1 -> 31441000 | P19: =IFERROR(VLOOKUP(J19,'Mã NV'!$B:$C,2,0),"") -> XE00893 | Q19: =IFERROR(VLOOKUP(I19,'Mã NV'!$J:$K,2,0),"") -> Cont 50F | S19: =L19*5% -> 1667050
A20: =A19+1 -> 17 | B20: 46161 | D20: Dược HG cont | E20: Dược HG cont | F20: Tuyến chính | G20: Cần Thơ | H20: hưng Yên | I20: 29E14310 | J20: Hỏa Văn Lâm | K20: XEVN | L20: 31878000 | M20: 1900000 | N20: =L20-M20 -> 29978000 | O20: =N20/$P$1 -> 29978000 | P20: =IFERROR(VLOOKUP(J20,'Mã NV'!$B:$C,2,0),"") -> XE00907 | Q20: =IFERROR(VLOOKUP(I20,'Mã NV'!$J:$K,2,0),"") -> Cont 50F | S20: =L20*5% -> 1593900
A21: =A20+1 -> 18 | B21: 46161 | D21: Dược HG cont | E21: Dược HG cont | F21: Tuyến chính | G21: Cần Thơ | H21: hưng Yên | I21: 29E14310 | J21: Hỏa Văn Quyết | K21: XEVN | L21: 31878000 | M21: 1900000 | N21: =L21-M21 -> 29978000 | O21: =N21/$P$1 -> 29978000 | P21: =IFERROR(VLOOKUP(J21,'Mã NV'!$B:$C,2,0),"") -> XE00908 | Q21: =IFERROR(VLOOKUP(I21,'Mã NV'!$J:$K,2,0),"") -> Cont 50F | S21: =L21*5% -> 1593900
A22: =A21+1 -> 19 | B22: 46164 | D22: Dược HG cont | E22: Dược HG cont | F22: Tuyến chính | G22: Cần Thơ | H22: Nghệ An + Hưng Yên | I22: 29E12143 | J22: Đỗ Văn Nam | K22: XEVN | L22: 33341000 | M22: 1900000 | N22: =L22-M22 -> 31441000 | O22: =N22/$P$1 -> 31441000 | P22: =IFERROR(VLOOKUP(J22,'Mã NV'!$B:$C,2,0),"") -> XE00855 | Q22: =IFERROR(VLOOKUP(I22,'Mã NV'!$J:$K,2,0),"") -> Cont 50F | S22: =L22*5% -> 1667050
A23: =A22+1 -> 20 | B23: 46164 | D23: Dược HG cont | E23: Dược HG cont | F23: Tuyến chính | G23: Cần Thơ | H23: Nghệ An + Hưng Yên | I23: 29E12143 | J23: Phạm Ngọc Cần | K23: XEVN | L23: 33341000 | M23: 1900000 | N23: =L23-M23 -> 31441000 | O23: =N23/$P$1 -> 31441000 | P23: =IFERROR(VLOOKUP(J23,'Mã NV'!$B:$C,2,0),"") -> XE00894 | Q23: =IFERROR(VLOOKUP(I23,'Mã NV'!$J:$K,2,0),"") -> Cont 50F | S23: =L23*5% -> 1667050
A24: =A23+1 -> 21 | B24: 46167 | D24: Dược HG cont | E24: Dược HG cont | F24: Tuyến chính | G24: Cần Thơ | H24: Hưng Yên | I24: 29E14214 | J24: Trần Xuân Thỏa | K24: XEVN | L24: 31878000 | M24: 1900000 | N24: =L24-M24 -> 29978000 | O24: =N24/$P$1 -> 29978000 | P24: =IFERROR(VLOOKUP(J24,'Mã NV'!$B:$C,2,0),"") -> XE00909 | Q24: =IFERROR(VLOOKUP(I24,'Mã NV'!$J:$K,2,0),"") -> Cont 50F | S24: =L24*5% -> 1593900
A25: =A24+1 -> 22 | B25: 46167 | D25: Dược HG cont | E25: Dược HG cont | F25: Tuyến chính | G25: Cần Thơ | H25: Hưng Yên | I25: 29E14214 | J25: Đỗ Ngọc Chiến | K25: XEVN | L25: 31878000 | M25: 1900000 | N25: =L25-M25 -> 29978000 | O25: =N25/$P$1 -> 29978000 | P25: =IFERROR(VLOOKUP(J25,'Mã NV'!$B:$C,2,0),"") -> XE00910 | Q25: =IFERROR(VLOOKUP(I25,'Mã NV'!$J:$K,2,0),"") -> Cont 50F | S25: =L25*5% -> 1593900
... A29: =A28+1 -> 26 | B29: 46170 | D29: Dược HG cont | E29: Dược HG cont | F29: Tuyến chính | G29: Cần Thơ | H29: Hưng Yên | I29: 29E12120 | J29: Đào Văn Hùng | K29: XEVN | L29: 31878000 | M29: 1900000 | N29: =L29-M29 -> 29978000 | O29: =N29/$P$1 -> 29978000 | P29: =IFERROR(VLOOKUP(J29,'Mã NV'!$B:$C,2,0),"") -> XE01303 | Q29: =IFERROR(VLOOKUP(I29,'Mã NV'!$J:$K,2,0),"") -> Cont 50F | S29: =L29*5% -> 1593900
A30: =A29+1 -> 27 | B30: 46155 | D30: FTC | E30: FTC | F30: Tuyến chính | G30: Hải Phòng | H30: Gia Lai | I30: 29H80501 | J30: Nguyễn Duy Tuấn | K30: XEVN | L30: 9600000 | M30: 100000 | N30: =L30-M30 -> 9500000 | O30: =N30/$P$1 -> 9500000 | P30: =IFERROR(VLOOKUP(J30,'Mã NV'!$B:$C,2,0),"") -> XE01548 | Q30: =IFERROR(VLOOKUP(I30,'Mã NV'!$J:$K,2,0),"") -> 7.1t | S30: =L30*2% -> 192000
A31: =A30+1 -> 28 | B31: 46155 | D31: FTC | E31: FTC | F31: Tuyến chính | G31: Hải Phòng | H31: Gia Lai | I31: 29H80501 | J31: Ngô Hoàng Vũ | K31: XEVN | L31: 9600000 | M31: 100000 | N31: =L31-M31 -> 9500000 | O31: =N31/$P$1 -> 9500000 | P31: =IFERROR(VLOOKUP(J31,'Mã NV'!$B:$C,2,0),"") -> XE01549 | Q31: =IFERROR(VLOOKUP(I31,'Mã NV'!$J:$K,2,0),"") -> 7.1t | S31: =L31*2% -> 192000
A32: =A31+1 -> 29 | B32: 46161 | D32: FTC | E32: FTC | F32: Tuyến chính | G32: Hải Dương | H32: Hồ Chí Minh | I32: 29E12143 | J32: Đỗ Văn Nam | K32: XEVN | L32: 12050000 | M32: 50000 | N32: =L32-M32 -> 12000000 | O32: =N32/$P$1 -> 12000000 | P32: =IFERROR(VLOOKUP(J32,'Mã NV'!$B:$C,2,0),"") -> XE00855 | Q32: =IFERROR(VLOOKUP(I32,'Mã NV'!$J:$K,2,0),"") -> Cont 50F | S32: =L32*2% -> 241000
A33: =A32+1 -> 30 | B33: 46161 | D33: FTC | E33: FTC | F33: Tuyến chính | G33: Hải Dương | H33: Hồ Chí Minh | I33: 29E12143 | J33: Phạm Ngọc Cần | K33: XEVN | L33: 12050000 | M33: 50000 | N33: =L33-M33 -> 12000000 | O33: =N33/$P$1 -> 12000000 | P33: =IFERROR(VLOOKUP(J33,'Mã NV'!$B:$C,2,0),"") -> XE00894 | Q33: =IFERROR(VLOOKUP(I33,'Mã NV'!$J:$K,2,0),"") -> Cont 50F | S33: =L33*2% -> 241000
A34: =A33+1 -> 31 | B34: 46164 | D34: FTC | E34: FTC | F34: Tuyến chính | G34: Hải Dương | H34: Hồ Chí Minh | I34: 29E35397 | J34: Vũ Văn Tỉnh | K34: XEVN | L34: 10050000 | M34: 50000 | N34: =L34-M34 -> 10000000 | O34: =N34/$P$1 -> 10000000 | P34: =IFERROR(VLOOKUP(J34,'Mã NV'!$B:$C,2,0),"") -> XE01021 | Q34: =IFERROR(VLOOKUP(I34,'Mã NV'!$J:$K,2,0),"") -> Cont 50F | S34: =L34*2% -> 201000
A35: =A34+1 -> 32 | B35: 46164 | D35: FTC | E35: FTC | F35: Tuyến chính | G35: Hải Dương | H35: Hồ Chí Minh | I35: 29E35397 | J35: Vũ Ngọc Thường | K35: XEVN | L35: 10050000 | M35: 50000 | N35: =L35-M35 -> 10000000 | O35: =N35/$P$1 -> 10000000 | P35: =IFERROR(VLOOKUP(J35,'Mã NV'!$B:$C,2,0),"") -> XE00893 | Q35: =IFERROR(VLOOKUP(I35,'Mã NV'!$J:$K,2,0),"") -> Cont 50F | S35: =L35*2% -> 201000
A36: =A35+1 -> 33 | B36: 46169 | D36: FTC | E36: FTC | F36: Tuyến chính | G36: Hải Dương | H36: Bình Dương | I36: 29E14214 | J36: Trần Xuân Thỏa | K36: XEVN | L36: 10000000 | M36: 50000 | N36: =L36-M36 -> 9950000 | O36: =N36/$P$1 -> 9950000 | P36: =IFERROR(VLOOKUP(J36,'Mã NV'!$B:$C,2,0),"") -> XE00909 | Q36: =IFERROR(VLOOKUP(I36,'Mã NV'!$J:$K,2,0),"") -> Cont 50F | S36: =L36*2% -> 200000
A37: =A36+1 -> 34 | B37: 46169 | D37: FTC | E37: FTC | F37: Tuyến chính | G37: Hải Dương | H37: Bình Dương | I37: 29E14214 | J37: Đỗ Ngọc Chiến | K37: XEVN | L37: 10000000 | M37: 50000 | N37: =L37-M37 -> 9950000 | O37: =N37/$P$1 -> 9950000 | P37: =IFERROR(VLOOKUP(J37,'Mã NV'!$B:$C,2,0),"") -> XE00910 | Q37: =IFERROR(VLOOKUP(I37,'Mã NV'!$J:$K,2,0),"") -> Cont 50F | S37: =L37*2% -> 200000
A38: =A37+1 -> 35 | B38: 46158 | D38: Fujitank | E38: Fujitank | F38: Tuyến chính | G38: Hồ Chí Minh | H38: Đà nẵng | I38: 29B20543 | J38: Nguyễn Đức Linh | K38: XEVN | L38: 5000000 | M38: 0 | N38: =L38-M38 -> 5000000 | O38: =N38/$P$1 -> 5000000 | P38: =IFERROR(VLOOKUP(J38,'Mã NV'!$B:$C,2,0),"") -> XE01326 | Q38: =IFERROR(VLOOKUP(I38,'Mã NV'!$J:$K,2,0),"") -> 7.1t
A39: =A38+1 -> 36 | B39: 46158 | D39: Fujitank | E39: Fujitank | F39: Tuyến chính | G39: Hồ Chí Minh | H39: Đà nẵng | I39: 29B20543 | J39: Nguyễn Công Thức | K39: XEVN | L39: 5000000 | M39: 0 | N39: =L39-M39 -> 5000000 | O39: =N39/$P$1 -> 5000000 | P39: =IFERROR(VLOOKUP(J39,'Mã NV'!$B:$C,2,0),"") -> XE01325 | Q39: =IFERROR(VLOOKUP(I39,'Mã NV'!$J:$K,2,0),"") -> 7.1t
A40: =A39+1 -> 37 | B40: 46156 | D40: Ghép hàng nhanh | E40: Ghép hàng nhanh | F40: Tuyến chính | G40: Đồng Nai - Bình Định | H40: Huế | I40: 29E54261 | J40: Trịnh Cao Phong | K40: XEVN | L40: 6000000 | M40: 0 | N40: =L40-M40 -> 6000000 | O40: =N40/$P$1 -> 6000000 | P40: =IFERROR(VLOOKUP(J40,'Mã NV'!$B:$C,2,0),"") -> XE01283 | Q40: =IFERROR(VLOOKUP(I40,'Mã NV'!$J:$K,2,0),"") -> 7.1t
A41: =A40+1 -> 38 | B41: 46156 | D41: Ghép hàng nhanh | E41: Ghép hàng nhanh | F41: Tuyến chính | G41: Đồng Nai - Bình Định | H41: Huế | I41: 29E54261 | J41: Lê Thanh Sơn | K41: XEVN | L41: 6000000 | M41: 0 | N41: =L41-M41 -> 6000000 | O41: =N41/$P$1 -> 6000000 | P41: =IFERROR(VLOOKUP(J41,'Mã NV'!$B:$C,2,0),"") -> XE01541 | Q41: =IFERROR(VLOOKUP(I41,'Mã NV'!$J:$K,2,0),"") -> 7.1t
A42: =A41+1 -> 39 | B42: 46144 | D42: Gia Huy Phát | E42: Gia Huy Phát | F42: Tuyến chính | G42: Đăk Nông | H42: Bắc Ninh | I42: 29K06824 | J42: Nguyễn Trọng Đạt | K42: XEVN | L42: 6378000 | M42: 0 | N42: =L42-M42 -> 6378000 | O42: =N42/$P$1 -> 6378000 | P42: =IFERROR(VLOOKUP(J42,'Mã NV'!$B:$C,2,0),"") -> XE01263 | Q42: =IFERROR(VLOOKUP(I42,'Mã NV'!$J:$K,2,0),"") -> 8T
A43: =A42+1 -> 40 | B43: 46144 | D43: Gia Huy Phát | E43: Gia Huy Phát | F43: Tuyến chính | G43: Đăk Nông | H43: Bắc Ninh | I43: 29K06824 | J43: Phạm Văn Thưởng | K43: XEVN | L43: 6378000 | M43: 0 | N43: =L43-M43 -> 6378000 | O43: =N43/$P$1 -> 6378000 | P43: =IFERROR(VLOOKUP(J43,'Mã NV'!$B:$C,2,0),"") -> XE01149 | Q43: =IFERROR(VLOOKUP(I43,'Mã NV'!$J:$K,2,0),"") -> 8T
...

Sheet Trừ lương
A1: Bảng trừ lương tháng 05/2026
A3: Ngày | B3: Lộ trình | C3: Tem xe | D3: Tên lái | E3: BKS | F3: Nhân viên bị trừ lương | G3: Bộ Phận | H3: Trừ lương | I3: Lý do
A4: Tháng 5 | E4: 29E12420 | F4: Hà Nguyên Dậu | G4: Lái xe | H4: 667272.09 | I4: theo định mức tiêu hao dầu | J4: =IFERROR(VLOOKUP(F4,'Mã NV'!$B:$C,2,0),"") -> XE00843 | K4: ="Trừ lương lái xe "&F4&" do "&I4&" ngày "&TEXT(A4,"dd/mm/yyyy") -> Trừ lương lái xe Hà Nguyên Dậu do theo định mức tiêu hao dầu ngày Tháng 5 | L4: =RIGHT(E4,5) -> 12420
A5: Tháng 5 | E5: 29E12420 | F5: Nguyễn Thanh Bình | G5: Lái xe | H5: 667272.09 | I5: theo định mức tiêu hao dầu | J5: =IFERROR(VLOOKUP(F5,'Mã NV'!$B:$C,2,0),"") -> XE00844 | K5: ="Trừ lương lái xe "&F5&" do "&I5&" ngày "&TEXT(A5,"dd/mm/yyyy") -> Trừ lương lái xe Nguyễn Thanh Bình do theo định mức tiêu hao dầu ngày Tháng 5 | L5: =RIGHT(E5,5) -> 12420
A6: Tháng 5 | E6: 29E12143 | F6: Đỗ Văn Nam | G6: Lái xe | H6: 423073.15 | I6: theo định mức tiêu hao dầu | J6: =IFERROR(VLOOKUP(F6,'Mã NV'!$B:$C,2,0),"") -> XE00855 | K6: ="Trừ lương lái xe "&F6&" do "&I6&" ngày "&TEXT(A6,"dd/mm/yyyy") -> Trừ lương lái xe Đỗ Văn Nam do theo định mức tiêu hao dầu ngày Tháng 5 | L6: =RIGHT(E6,5) -> 12143
A7: Tháng 5 | E7: 29E12143 | F7: Phạm Ngọc Cần | G7: Lái xe | H7: 423073.15 | I7: theo định mức tiêu hao dầu | J7: =IFERROR(VLOOKUP(F7,'Mã NV'!$B:$C,2,0),"") -> XE00894 | K7: ="Trừ lương lái xe "&F7&" do "&I7&" ngày "&TEXT(A7,"dd/mm/yyyy") -> Trừ lương lái xe Phạm Ngọc Cần do theo định mức tiêu hao dầu ngày Tháng 5 | L7: =RIGHT(E7,5) -> 12143
A8: Tháng 5 | E8: 29E12333 | F8: Nguyễn Văn Mạnh | G8: Lái xe | H8: 3699593.9 | I8: theo định mức tiêu hao dầu | J8: =IFERROR(VLOOKUP(F8,'Mã NV'!$B:$C,2,0),"") -> XE00952 | K8: ="Trừ lương lái xe "&F8&" do "&I8&" ngày "&TEXT(A8,"dd/mm/yyyy") -> Trừ lương lái xe Nguyễn Văn Mạnh do theo định mức tiêu hao dầu ngày Tháng 5 | L8: =RIGHT(E8,5) -> 12333
A9: Tháng 5 | E9: 29E12333 | F9: Phạm Văn Phố | G9: Lái xe | H9: 3699593.9 | I9: theo định mức tiêu hao dầu | J9: =IFERROR(VLOOKUP(F9,'Mã NV'!$B:$C,2,0),"") -> XE01308 | K9: ="Trừ lương lái xe "&F9&" do "&I9&" ngày "&TEXT(A9,"dd/mm/yyyy") -> Trừ lương lái xe Phạm Văn Phố do theo định mức tiêu hao dầu ngày Tháng 5 | L9: =RIGHT(E9,5) -> 12333
A10: Tháng 5 | E10: 29E12412 | F10: Đỗ Ngọc Thông | G10: Lái xe | H10: 850093.95 | I10: theo định mức tiêu hao dầu | J10: =IFERROR(VLOOKUP(F10,'Mã NV'!$B:$C,2,0),"") -> XE00858 | K10: ="Trừ lương lái xe "&F10&" do "&I10&" ngày "&TEXT(A10,"dd/mm/yyyy") -> Trừ lương lái xe Đỗ Ngọc Thông do theo định mức tiêu hao dầu ngày Tháng 5 | L10: =RIGHT(E10,5) -> 12412
A11: Tháng 5 | E11: 29E12412 | F11: Nguyễn Ngọc Tịnh | G11: Lái xe | H11: 850093.95 | I11: theo định mức tiêu hao dầu | J11: =IFERROR(VLOOKUP(F11,'Mã NV'!$B:$C,2,0),"") -> XE01539 | K11: ="Trừ lương lái xe "&F11&" do "&I11&" ngày "&TEXT(A11,"dd/mm/yyyy") -> Trừ lương lái xe Nguyễn Ngọc Tịnh do theo định mức tiêu hao dầu ngày Tháng 5 | L11: =RIGHT(E11,5) -> 12412
A12: Tháng 5 | E12: 29E12120 | F12: Đào Văn Hùng | G12: Lái xe | H12: 600599.78 | I12: theo định mức tiêu hao dầu | J12: =IFERROR(VLOOKUP(F12,'Mã NV'!$B:$C,2,0),"") -> XE01303 | K12: ="Trừ lương lái xe "&F12&" do "&I12&" ngày "&TEXT(A12,"dd/mm/yyyy") -> Trừ lương lái xe Đào Văn Hùng do theo định mức tiêu hao dầu ngày Tháng 5 | L12: =RIGHT(E12,5) -> 12120
A13: Tháng 5 | B13: , | E13: 29E12120 | F13: Lê Thanh Đang | G13: Lái xe | H13: 600599.78 | I13: theo định mức tiêu hao dầu | J13: =IFERROR(VLOOKUP(F13,'Mã NV'!$B:$C,2,0),"") -> XE00853 | K13: ="Trừ lương lái xe "&F13&" do "&I13&" ngày "&TEXT(A13,"dd/mm/yyyy") -> Trừ lương lái xe Lê Thanh Đang do theo định mức tiêu hao dầu ngày Tháng 5 | L13: =RIGHT(E13,5) -> 12120
A14: Tháng 5 | E14: 29E12436 | F14: Phạm Văn Khâm | G14: Lái xe | H14: 2440530.7 | I14: theo định mức tiêu hao dầu | J14: =IFERROR(VLOOKUP(F14,'Mã NV'!$B:$C,2,0),"") -> XE00865 | K14: ="Trừ lương lái xe "&F14&" do "&I14&" ngày "&TEXT(A14,"dd/mm/yyyy") -> Trừ lương lái xe Phạm Văn Khâm do theo định mức tiêu hao dầu ngày Tháng 5 | L14: =RIGHT(E14,5) -> 12436
A15: Tháng 5 | E15: 29E12436 | F15: Vũ Văn Quân | G15: Lái xe | H15: 2440530.7 | I15: theo định mức tiêu hao dầu | J15: =IFERROR(VLOOKUP(F15,'Mã NV'!$B:$C,2,0),"") -> XE00985 | K15: ="Trừ lương lái xe "&F15&" do "&I15&" ngày "&TEXT(A15,"dd/mm/yyyy") -> Trừ lương lái xe Vũ Văn Quân do theo định mức tiêu hao dầu ngày Tháng 5 | L15: =RIGHT(E15,5) -> 12436
A16: Tháng 5 | E16: 29E14424 | F16: Mã Đức Diễn | G16: Lái xe | H16: 1516048.7 | I16: theo định mức tiêu hao dầu | J16: =IFERROR(VLOOKUP(F16,'Mã NV'!$B:$C,2,0),"") -> XE01034 | K16: ="Trừ lương lái xe "&F16&" do "&I16&" ngày "&TEXT(A16,"dd/mm/yyyy") -> Trừ lương lái xe Mã Đức Diễn do theo định mức tiêu hao dầu ngày Tháng 5 | L16: =RIGHT(E16,5) -> 14424
A17: Tháng 5 | E17: 29E14424 | F17: Phạm Tuấn Sơn | G17: Lái xe | H17: 1516048.7 | I17: theo định mức tiêu hao dầu | J17: =IFERROR(VLOOKUP(F17,'Mã NV'!$B:$C,2,0),"") -> XE01064 | K17: ="Trừ lương lái xe "&F17&" do "&I17&" ngày "&TEXT(A17,"dd/mm/yyyy") -> Trừ lương lái xe Phạm Tuấn Sơn do theo định mức tiêu hao dầu ngày Tháng 5 | L17: =RIGHT(E17,5) -> 14424
A18: Tháng 5 | E18: 29E14214 | F18: Đỗ Ngọc Chiến | G18: Lái xe | H18: 2223964 | I18: theo định mức tiêu hao dầu | J18: =IFERROR(VLOOKUP(F18,'Mã NV'!$B:$C,2,0),"") -> XE00910 | K18: ="Trừ lương lái xe "&F18&" do "&I18&" ngày "&TEXT(A18,"dd/mm/yyyy") -> Trừ lương lái xe Đỗ Ngọc Chiến do theo định mức tiêu hao dầu ngày Tháng 5 | L18: =RIGHT(E18,5) -> 14214
A19: Tháng 5 | E19: 29E14214 | F19: Trần Xuân Thỏa | G19: Lái xe | H19: 2223964 | I19: theo định mức tiêu hao dầu | J19: =IFERROR(VLOOKUP(F19,'Mã NV'!$B:$C,2,0),"") -> XE00909 | K19: ="Trừ lương lái xe "&F19&" do "&I19&" ngày "&TEXT(A19,"dd/mm/yyyy") -> Trừ lương lái xe Trần Xuân Thỏa do theo định mức tiêu hao dầu ngày Tháng 5 | L19: =RIGHT(E19,5) -> 14214
A20: Tháng 5 | E20: 29E14310 | F20: Hỏa Văn Lâm | G20: Lái xe | H20: 564233.68 | I20: theo định mức tiêu hao dầu | J20: =IFERROR(VLOOKUP(F20,'Mã NV'!$B:$C,2,0),"") -> XE00907 | K20: ="Trừ lương lái xe "&F20&" do "&I20&" ngày "&TEXT(A20,"dd/mm/yyyy") -> Trừ lương lái xe Hỏa Văn Lâm do theo định mức tiêu hao dầu ngày Tháng 5 | L20: =RIGHT(E20,5) -> 14310
A21: Tháng 5 | E21: 29E14310 | F21: Hỏa Văn Quyết | G21: Lái xe | H21: 564233.68 | I21: theo định mức tiêu hao dầu | J21: =IFERROR(VLOOKUP(F21,'Mã NV'!$B:$C,2,0),"") -> XE00908 | K21: ="Trừ lương lái xe "&F21&" do "&I21&" ngày "&TEXT(A21,"dd/mm/yyyy") -> Trừ lương lái xe Hỏa Văn Quyết do theo định mức tiêu hao dầu ngày Tháng 5 | L21: =RIGHT(E21,5) -> 14310
A22: Tháng 5 | E22: 29E35397 | F22: Vũ Ngọc Thường | G22: Lái xe | H22: 649102.56 | I22: theo định mức tiêu hao dầu | J22: =IFERROR(VLOOKUP(F22,'Mã NV'!$B:$C,2,0),"") -> XE00893 | K22: ="Trừ lương lái xe "&F22&" do "&I22&" ngày "&TEXT(A22,"dd/mm/yyyy") -> Trừ lương lái xe Vũ Ngọc Thường do theo định mức tiêu hao dầu ngày Tháng 5 | L22: =RIGHT(E22,5) -> 35397
A23: Tháng 5 | E23: 29E35397 | F23: Vũ Văn Tỉnh | G23: Lái xe | H23: 649102.56 | I23: theo định mức tiêu hao dầu | J23: =IFERROR(VLOOKUP(F23,'Mã NV'!$B:$C,2,0),"") -> XE01021 | K23: ="Trừ lương lái xe "&F23&" do "&I23&" ngày "&TEXT(A23,"dd/mm/yyyy") -> Trừ lương lái xe Vũ Văn Tỉnh do theo định mức tiêu hao dầu ngày Tháng 5 | L23: =RIGHT(E23,5) -> 35397
A24: Tháng 5 | E24: 29E35064 | F24: Nguyễn Ngọc Tịnh | G24: Lái xe | H24: 548295.41 | I24: theo định mức tiêu hao dầu | J24: =IFERROR(VLOOKUP(F24,'Mã NV'!$B:$C,2,0),"") -> XE01539 | K24: ="Trừ lương lái xe "&F24&" do "&I24&" ngày "&TEXT(A24,"dd/mm/yyyy") -> Trừ lương lái xe Nguyễn Ngọc Tịnh do theo định mức tiêu hao dầu ngày Tháng 5 | L24: =RIGHT(E24,5) -> 35064
A25: Tháng 5 | E25: 29E35064 | F25: Đào Văn Hùng | G25: Lái xe | H25: 548295.41 | I25: theo định mức tiêu hao dầu | J25: =IFERROR(VLOOKUP(F25,'Mã NV'!$B:$C,2,0),"") -> XE01303 | K25: ="Trừ lương lái xe "&F25&" do "&I25&" ngày "&TEXT(A25,"dd/mm/yyyy") -> Trừ lương lái xe Đào Văn Hùng do theo định mức tiêu hao dầu ngày Tháng 5 | L25: =RIGHT(E25,5) -> 35064
... A123: Tháng 5 | E123: 29E08175 | F123: Nguyễn Doãn Quang | G123: Lái xe | H123: 1348045.8 | I123: theo định mức tiêu hao dầu | J123: =IFERROR(VLOOKUP(F123,'Mã NV'!$B:$C,2,0),"") -> XE01645 | K123: ="Trừ lương lái xe "&F123&" do "&I123&" ngày "&TEXT(A123,"dd/mm/yyyy") -> Trừ lương lái xe Nguyễn Doãn Quang do theo định mức tiêu hao dầu ngày Tháng 5 | L123: =RIGHT(E123,5) -> 08175
A124: 46111 | B124: HÀ NỘI (LONG BIÊN) - GIA LAI - ĐẮK LẮK | C124: JBGX26033000091 | D124: Nguyễn Văn Chiến -Nguyễn Văn Thắng | E124: 29E38128 | F124: Nguyễn Văn Chiến | G124: Lái xe | H124: 100000 | I124: Thiếu Thao Tác App | J124: =IFERROR(VLOOKUP(F124,'Mã NV'!$B:$C,2,0),"") -> XE01582 | K124: ="Trừ lương lái xe "&F124&" do "&I124&" ngày "&TEXT(A124,"dd/mm/yyyy") -> Trừ lương lái xe Nguyễn Văn Chiến do Thiếu Thao Tác App ngày 30/03/2026 | L124: =RIGHT(E124,5) -> 38128
A125: 46113 | B125: HÀ NỘI đến ĐẮK LẮK | C125: DBGX26040100842 | D125: Trần Đình Mẫn -Huỳnh Tuấn Huynh | E125: 29E38331 | F125: Trần Đình Mẫn | G125: Lái xe | H125: 100000 | I125: Thiếu Thao Tác App | J125: =IFERROR(VLOOKUP(F125,'Mã NV'!$B:$C,2,0),"") -> XE01530 | K125: ="Trừ lương lái xe "&F125&" do "&I125&" ngày "&TEXT(A125,"dd/mm/yyyy") -> Trừ lương lái xe Trần Đình Mẫn do Thiếu Thao Tác App ngày 01/04/2026 | L125: =RIGHT(E125,5) -> 38331
A126: 46115 | B126: HÀ NỘI đến HỒ CHÍ MINH | C126: JBGX26040300113 | D126: Trần Xuân Thoả-Đỗ Ngọc Chiến | E126: 29E14214 | F126: Trần Xuân Thoả | G126: Lái xe | H126: 100000 | I126: Thiếu Thao Tác App | J126: =IFERROR(VLOOKUP(F126,'Mã NV'!$B:$C,2,0),"") -> XE00909 | K126: ="Trừ lương lái xe "&F126&" do "&I126&" ngày "&TEXT(A126,"dd/mm/yyyy") -> Trừ lương lái xe Trần Xuân Thoả do Thiếu Thao Tác App ngày 03/04/2026 | L126: =RIGHT(E126,5) -> 14214
A127: 46117 | B127: CẦN THƠ đến HÀ NỘI | C127: DKGX26040500817 | D127: Phạm Văn Khâm-Vũ Văn Quân | E127: 29E12436 | F127: Phạm Văn Khâm | G127: Lái xe | H127: 100000 | I127: Thiếu Thao Tác App | J127: =IFERROR(VLOOKUP(F127,'Mã NV'!$B:$C,2,0),"") -> XE00865 | K127: ="Trừ lương lái xe "&F127&" do "&I127&" ngày "&TEXT(A127,"dd/mm/yyyy") -> Trừ lương lái xe Phạm Văn Khâm do Thiếu Thao Tác App ngày 05/04/2026 | L127: =RIGHT(E127,5) -> 12436
A128: 46118 | B128: HÀ NỘI đến HỒ CHÍ MINH (GW5) | C128: DKGX26040700593 | D128: Nguyễn Thành Quang-Bùi Tiến Hưng | E128: 29K06820 | F128: Nguyễn Thành Quang | G128: Lái xe | H128: 100000 | I128: Thiếu Thao Tác App | J128: =IFERROR(VLOOKUP(F128,'Mã NV'!$B:$C,2,0),"") -> XE01389 | K128: ="Trừ lương lái xe "&F128&" do "&I128&" ngày "&TEXT(A128,"dd/mm/yyyy") -> Trừ lương lái xe Nguyễn Thành Quang do Thiếu Thao Tác App ngày 06/04/2026 | L128: =RIGHT(E128,5) -> 06820
A129: 46119 | B129: HÀ NỘI đến BÌNH DƯƠNG | C129: DBGX26040801062 | D129: Trương Cẩm Thành-Trần Thanh Đạt | E129: 29E09603 | F129: Trương Cẩm Thành | G129: Lái xe | H129: 100000 | I129: Thiếu Thao Tác App | J129: =IFERROR(VLOOKUP(F129,'Mã NV'!$B:$C,2,0),"") -> XE01390 | K129: ="Trừ lương lái xe "&F129&" do "&I129&" ngày "&TEXT(A129,"dd/mm/yyyy") -> Trừ lương lái xe Trương Cẩm Thành do Thiếu Thao Tác App ngày 07/04/2026 | L129: =RIGHT(E129,5) -> 09603
A130: 46122 | B130: HÀ NỘI đến HỒ CHÍ MINH (GW5) | C130: DKGX26041100471 | D130: Cao Hoài Tiên -Bùi Ngọc Ninh | E130: 29E12401 | F130: Cao Hoài Tiên | G130: Lái xe | H130: 100000 | I130: Thiếu Thao Tác App | J130: =IFERROR(VLOOKUP(F130,'Mã NV'!$B:$C,2,0),"") -> XE01477 | K130: ="Trừ lương lái xe "&F130&" do "&I130&" ngày "&TEXT(A130,"dd/mm/yyyy") -> Trừ lương lái xe Cao Hoài Tiên do Thiếu Thao Tác App ngày 10/04/2026 | L130: =RIGHT(E130,5) -> 12401
A131: 46124 | B131: HỒ CHÍ MINH (GW5) đến HÀ NỘI | C131: DKGX26041200602 | D131: Nguyễn Văn Toàn-Lê Văn Khiêm | E131: 29E54212 | F131: Nguyễn Văn Toàn | G131: Lái xe | H131: 100000 | I131: Thiếu Thao Tác App | J131: =IFERROR(VLOOKUP(F131,'Mã NV'!$B:$C,2,0),"") -> XE01281 | K131: ="Trừ lương lái xe "&F131&" do "&I131&" ngày "&TEXT(A131,"dd/mm/yyyy") -> Trừ lương lái xe Nguyễn Văn Toàn do Thiếu Thao Tác App ngày 12/04/2026 | L131: =RIGHT(E131,5) -> 54212
A132: 46111 | B132: HÀ NỘI (LONG BIÊN) - GIA LAI - ĐẮK LẮK | C132: JBGX26033000091 | D132: Nguyễn Văn Chiến -Nguyễn Văn Thắng | E132: 29E38128 | F132: Nguyễn Văn Thắng | G132: Lái xe | H132: 100000 | I132: Thiếu Thao Tác App | J132: =IFERROR(VLOOKUP(F132,'Mã NV'!$B:$C,2,0),"") -> XE01583 | K132: ="Trừ lương lái xe "&F132&" do "&I132&" ngày "&TEXT(A132,"dd/mm/yyyy") -> Trừ lương lái xe Nguyễn Văn Thắng do Thiếu Thao Tác App ngày 30/03/2026 | L132: =RIGHT(E132,5) -> 38128
A133: 46113 | B133: HÀ NỘI đến ĐẮK LẮK | C133: DBGX26040100842 | D133: Trần Đình Mẫn -Huỳnh Tuấn Huynh | E133: 29E38331 | F133: Huỳnh Tấn Huynh | G133: Lái xe | H133: 100000 | I133: Thiếu Thao Tác App | J133: =IFERROR(VLOOKUP(F133,'Mã NV'!$B:$C,2,0),"") -> XE01540 | K133: ="Trừ lương lái xe "&F133&" do "&I133&" ngày "&TEXT(A133,"dd/mm/yyyy") -> Trừ lương lái xe Huỳnh Tấn Huynh do Thiếu Thao Tác App ngày 01/04/2026 | L133: =RIGHT(E133,5) -> 38331
A134: 46115 | B134: HÀ NỘI đến HỒ CHÍ MINH | C134: JBGX26040300113 | D134: Trần Xuân Thoả-Đỗ Ngọc Chiến | E134: 29E14214 | F134: Đỗ Ngọc Chiến | G134: Lái xe | H134: 100000 | I134: Thiếu Thao Tác App | J134: =IFERROR(VLOOKUP(F134,'Mã NV'!$B:$C,2,0),"") -> XE00910 | K134: ="Trừ lương lái xe "&F134&" do "&I134&" ngày "&TEXT(A134,"dd/mm/yyyy") -> Trừ lương lái xe Đỗ Ngọc Chiến do Thiếu Thao Tác App ngày 03/04/2026 | L134: =RIGHT(E134,5) -> 14214
A135: 46117 | B135: CẦN THƠ đến HÀ NỘI | C135: DKGX26040500817 | D135: Phạm Văn Khâm-Vũ Văn Quân | E135: 29E12436 | F135: Vũ Văn Quân | G135: Lái xe | H135: 100000 | I135: Thiếu Thao Tác App | J135: =IFERROR(VLOOKUP(F135,'Mã NV'!$B:$C,2,0),"") -> XE00985 | K135: ="Trừ lương lái xe "&F135&" do "&I135&" ngày "&TEXT(A135,"dd/mm/yyyy") -> Trừ lương lái xe Vũ Văn Quân do Thiếu Thao Tác App ngày 05/04/2026 | L135: =RIGHT(E135,5) -> 12436
... A149: 46120 | B149: HÀ NỘI-ĐẮK LẮK | C149: DBGX26040900660 | D149: Trần Đình Mẫn -Huỳnh Tuấn Huynh | E149: 29E38331 | F149: Huỳnh Tấn Huynh | G149: Lái xe | H149: 745000 | I149: Phạt Vi Phạm Thời Hiệu | J149: =IFERROR(VLOOKUP(F149,'Mã NV'!$B:$C,2,0),"") -> XE01540 | K149: ="Trừ lương lái xe "&F149&" do "&I149&" ngày "&TEXT(A149,"dd/mm/yyyy") -> Trừ lương lái xe Huỳnh Tấn Huynh do Phạt Vi Phạm Thời Hiệu ngày 08/04/2026 | L149: =RIGHT(E149,5) -> 38331
J150: =IFERROR(VLOOKUP(F150,'Mã NV'!$B:$C,2,0),"") | K150: ="Trừ lương lái xe "&F150&" do "&I150&" ngày "&TEXT(A150,"dd/mm/yyyy") -> Trừ lương lái xe do ngày 00/01/1900 | L150: =RIGHT(E150,5)
J151: =IFERROR(VLOOKUP(F151,'Mã NV'!$B:$C,2,0),"") | K151: ="Trừ lương lái xe "&F151&" do "&I151&" ngày "&TEXT(A151,"dd/mm/yyyy") -> Trừ lương lái xe do ngày 00/01/1900 | L151: =RIGHT(E151,5)
...

Sheet Thu nhập khác
A1: Bảng thu nhập khác theo định mức dầu tháng 05/2026
A3: Ngày | B3: Lộ trình | C3: Tem xe | D3: Tên lái | E3: BKS | F3: Nhân viên | G3: Bộ Phận | H3: Cộng thu nhập | I3: Lý do
E4: 29G02349 | F4: Đinh Văn Phấn | G4: Lái xe | H4: 28455.226 | I4: theo định mức tiêu hao dầu | J4: =IFERROR(VLOOKUP(F4,'Mã NV'!$B:$C,2,0),"") | K4: ="Trừ lương lái xe "&F4&" do "&I4&" ngày "&TEXT(A4,"dd/mm/yyyy") -> Trừ lương lái xe Đinh Văn Phấn do theo định mức tiêu hao dầu ngày 00/01/1900 | L4: =RIGHT(E4,5) -> 02349
E5: 29G02349 | F5: Nguyễn Thanh Nhân | G5: Lái xe | H5: 318559.72 | I5: theo định mức tiêu hao dầu | J5: =IFERROR(VLOOKUP(F5,'Mã NV'!$B:$C,2,0),"") -> XE01574 | K5: ="Trừ lương lái xe "&F5&" do "&I5&" ngày "&TEXT(A5,"dd/mm/yyyy") -> Trừ lương lái xe Nguyễn Thanh Nhân do theo định mức tiêu hao dầu ngày 00/01/1900 | L5: =RIGHT(E5,5) -> 02349
E6: 29G02349 | F6: Phan Tấn Thành | G6: Lái xe | H6: 28455.226 | I6: theo định mức tiêu hao dầu | J6: =IFERROR(VLOOKUP(F6,'Mã NV'!$B:$C,2,0),"") -> XE01532 | K6: ="Trừ lương lái xe "&F6&" do "&I6&" ngày "&TEXT(A6,"dd/mm/yyyy") -> Trừ lương lái xe Phan Tấn Thành do theo định mức tiêu hao dầu ngày 00/01/1900 | L6: =RIGHT(E6,5) -> 02349
E7: 29G02349 | F7: Trần Phúc Đạt | G7: Lái xe | H7: 318560 | I7: theo định mức tiêu hao dầu | J7: =IFERROR(VLOOKUP(F7,'Mã NV'!$B:$C,2,0),"") -> XE01527 | K7: ="Trừ lương lái xe "&F7&" do "&I7&" ngày "&TEXT(A7,"dd/mm/yyyy") -> Trừ lương lái xe Trần Phúc Đạt do theo định mức tiêu hao dầu ngày 00/01/1900 | L7: =RIGHT(E7,5) -> 02349
E8: 29E54212 | F8: Lê Anh Tuấn | G8: Lái xe | H8: 2306228.3 | I8: theo định mức tiêu hao dầu | J8: =IFERROR(VLOOKUP(F8,'Mã NV'!$B:$C,2,0),"") -> XE01678 | K8: ="Trừ lương lái xe "&F8&" do "&I8&" ngày "&TEXT(A8,"dd/mm/yyyy") -> Trừ lương lái xe Lê Anh Tuấn do theo định mức tiêu hao dầu ngày 00/01/1900 | L8: =RIGHT(E8,5) -> 54212
E9: 29E54212 | F9: Nguyễn Tuấn Anh-tuyến chính | G9: Lái xe | H9: 2306228.3 | I9: theo định mức tiêu hao dầu | J9: =IFERROR(VLOOKUP(F9,'Mã NV'!$B:$C,2,0),"") -> XE01679 | K9: ="Trừ lương lái xe "&F9&" do "&I9&" ngày "&TEXT(A9,"dd/mm/yyyy") -> Trừ lương lái xe Nguyễn Tuấn Anh-tuyến chính do theo định mức tiêu hao dầu ngày 00/01/1900 | L9: =RIGHT(E9,5) -> 54212
E10: 29K13697 | F10: Phạm Thái Nhân | G10: Lái xe | H10: 1560719.9 | I10: theo định mức tiêu hao dầu | J10: =IFERROR(VLOOKUP(F10,'Mã NV'!$B:$C,2,0),"") -> XE00891 | K10: ="Trừ lương lái xe "&F10&" do "&I10&" ngày "&TEXT(A10,"dd/mm/yyyy") -> Trừ lương lái xe Phạm Thái Nhân do theo định mức tiêu hao dầu ngày 00/01/1900 | L10: =RIGHT(E10,5) -> 13697
E11: 29K13754 | F11: Phạm Văn Hải A | G11: Lái xe | H11: 387200.63 | I11: theo định mức tiêu hao dầu | J11: =IFERROR(VLOOKUP(F11,'Mã NV'!$B:$C,2,0),"") -> XE00449 | K11: ="Trừ lương lái xe "&F11&" do "&I11&" ngày "&TEXT(A11,"dd/mm/yyyy") -> Trừ lương lái xe Phạm Văn Hải A do theo định mức tiêu hao dầu ngày 00/01/1900 | L11: =RIGHT(E11,5) -> 13754
E12: 29E09530 | F12: Nguyễn Tiến Công | G12: Lái xe | H12: 924692.08 | I12: theo định mức tiêu hao dầu | J12: =IFERROR(VLOOKUP(F12,'Mã NV'!$B:$C,2,0),"") -> XE00779 | K12: ="Trừ lương lái xe "&F12&" do "&I12&" ngày "&TEXT(A12,"dd/mm/yyyy") -> Trừ lương lái xe Nguyễn Tiến Công do theo định mức tiêu hao dầu ngày 00/01/1900 | L12: =RIGHT(E12,5) -> 09530
A13: TỔNG | H13: =SUM(H4:H12) -> 8179099.3

Sheet Sheet1
A1: 29E38126 | B1: 29E38126
A2: 29E38126 | B2: 29E38126
A3: 29G02349 | B3: 29G02349
A4: 29G02349 | B4: 29G02349
A5: 29E38331 | B5: 29B20543
A6: 29E38331 | B6: 29B20543
A7: 29E12073 | B7: 29E38331
A8: 29E12073 | B8: 29E38331
A9: 29B20543 | B9: 29E12073
A10: 29B20543 | B10: 29E12073
A11: 29E38331 | B11: 29B20543
A12: 29E38331 | B12: 29B20543
... A14: 29K06820 | B14: 29E38331
A15: 2.9e+29 | B15: 29K06820
A16: 2.9e+29 | B16: 29K06820
A17: 29E38128 | B17: 2.9e+29
A18: 29E38128 | B18: 2.9e+29
A19: 29E54261 | B19: 29E38128
A20: 29E54261 | B20: 29E38128
A21: 29E54212 | B21: 29E54261
A22: 29E54212 | B22: 29E54261
A23: 29E12073 | B23: 29E44377
A24: 29E12073 | B24: 29E44377
A25: 29E08426 | B25: 29E54212
A26: 29E08426 | B26: 29E54212
A27: 29E54212 | B27: 29E12073
A28: 29E54212 | B28: 29E12073
A29: 29H70193 | B29: 29E08426
A30: 29H70193 | B30: 29E08426
... A42: 29E08426 | B42: 29G02349
B43: 29E08175
B44: 29E08175
B45: 29B20543
B46: 29B20543
B47: 29E54261
B48: 29E54261
B49: 29E08426
B50: 29E08426

Sheet Mã NV
A1: STT | B1: Lái xe | C1: Mã NV | D1: Tuyến | E1: Ngày sinh | F1: Tuổi | G1: Giới tính | I1: THÔNG TIN XE
A2: 1 | B2: Lê Đình Ngũ | C2: XE00979 | D2: Tuyến nhánh | E2: 34486 | F2: 31 | G2: Nam | I2: STT | J2: Xe (BKS) | K2: Tải trọng | L2: Tuyến
A3: 2 | B3: Nguyễn Văn Luận | C3: XE00975 | D3: Tuyến nhánh | E3: 28264 | F3: 48 | G3: Nam | I3: 1 | J3: 29H73703 | K3: 2.5T | L3: Tuyến nhánh
A4: 3 | B4: Trần Trung Kiên | C4: XE00977 | D4: Tuyến nhánh | E4: 38567 | F4: 20 | G4: Nam | I4: 2 | J4: 29K13511 | K4: 2.5T | L4: Tuyến nhánh
A5: 4 | B5: Đinh Mai Sơn | C5: XE00768 | D5: Tuyến nhánh | E5: 26056 | F5: 54 | G5: Nam | I5: 3 | J5: 29H84991 | K5: 3.5T | L5: Tuyến nhánh
A6: 5 | B6: Hoàng Đức Mạnh | C6: XE00777 | D6: Tuyến nhánh | E6: 35825 | F6: 27 | G6: Nam | I6: 4 | J6: 29K06711 | K6: 5.5T | L6: Tuyến nhánh
A7: 6 | B7: Nguyễn Hữu Tùng | C7: XE00730 | D7: Tuyến nhánh | E7: 27729 | F7: 49 | G7: Nam | I7: 5 | J7: 29G02319 | K7: 6.5T | L7: Tuyến nhánh
A8: 7 | B8: Mai Văn Ngọc | C8: XE00953 | D8: Tuyến nhánh | E8: 34984 | F8: 30 | G8: Nam | I8: 6 | J8: 29E18964 | K8: 6.5T | L8: Tuyến nhánh
A9: 8 | B9: Hoàng Văn Chuyền | C9: XE00832 | D9: Tuyến nhánh | E9: 28126 | F9: 48 | G9: Nam | I9: 7 | J9: 29G02320 | K9: 6.5T | L9: Tuyến nhánh
A10: 9 | B10: Đặng Văn Thắng | C10: XE00900 | D10: Tuyến nhánh | E10: 34409 | F10: 31 | G10: Nam | I10: 8 | J10: 29E12348 | K10: 6.5T | L10: Tuyến nhánh
A11: 10 | B11: Trần Văn Cương | C11: XE01004 | D11: Tuyến nhánh | E11: 32908 | F11: 35 | G11: Nam | I11: 9 | J11: 29E08058 | K11: 6.5T | L11: Tuyến nhánh
A12: 11 | B12: Lê Văn Giang | C12: XE00447 | D12: Tuyến nhánh | E12: 33772 | F12: 33 | G12: Nam | I12: 10 | J12: 29G02311 | K12: 6.5T | L12: Tuyến nhánh
A13: 12 | B13: Nguyễn Trọng Tấn | C13: XE00615 | D13: Tuyến nhánh | E13: 31053 | F13: 40 | G13: Nam | I13: 11 | J13: 29K13754 | K13: 8T | L13: Tuyến nhánh
A14: 13 | B14: Phạm Văn Hải A | C14: XE00449 | D14: Tuyến nhánh | E14: 31967 | F14: 38 | G14: Nam | I14: 12 | J14: 29K06374 | K14: 8T | L14: Tuyến nhánh
... A67: 66 | B67: Lê Văn Đông | C67: XE01215 | D67: Tuyến chính | E67: 31132 | F67: 40 | G67: Nam | I67: 65 | J67: 29B18964 | K67: 6.5T | L67: Tuyến nhánh
A68: 67 | B68: Nguyễn Thừa Vinh | C68: XE01244 | D68: Tuyến chính | E68: 29114 | F68: 46 | G68: Nam | J68: 29E00028 | K68: 8T | L68: Tuyến chính | M68: PS T11.2025
A69: 68 | B69: Trần Công Vương | C69: XE01245 | D69: Tuyến chính | E69: 31659 | F69: 39 | G69: Nam | J69: 29E47562 | K69: 2T5 Lạnh
A70: 69 | B70: Cao Văn Dương | C70: XE01246 | D70: Tuyến chính | E70: 29022 | F70: 46 | G70: Nam | J70: 29E49680 | K70: 2T5 Lạnh
A71: 70 | B71: Nguyễn Văn Trung | C71: XE01250 | D71: Tuyến chính | E71: 31782 | F71: 38 | G71: Nam | J71: 29E48524 | K71: 2T5 Lạnh
A72: 71 | B72: Vũ Văn Tường | C72: XE01247 | D72: Tuyến chính | E72: 31817 | F72: 38 | G72: Nam | J72: 29E49820 | K72: 3T5 Lạnh
A73: 72 | B73: Lại Hợp Huấn | C73: XE00862 | D73: Tuyến chính | E73: 32404 | F73: 37 | G73: Nam | J73: 29K02514 | K73: 2T5 Lạnh
A74: 73 | B74: Nguyễn Trọng Đạt | C74: XE01263 | D74: Tuyến chính | E74: 29549 | F74: 44 | G74: Nam | J74: 29E52540 | K74: 3T5 Lạnh
A75: 74 | B75: Nguyễn Văn Quý | C75: XE01276 | D75: Tuyến chính | E75: 31337 | F75: 40 | G75: Nam | J75: 29E54261 | K75: 7.1t
A76: 75 | B76: Đặng Thành Lai | C76: XE01280 | D76: Tuyến chính | E76: 26058 | F76: 54 | G76: Nam | J76: 29H80501 | K76: 7.1t
A77: 76 | B77: Nguyễn Văn Toàn | C77: XE01281 | D77: Tuyến chính | E77: 26562 | F77: 53 | G77: Nam | J77: 29B20543 | K77: 7.1t
A78: 77 | B78: Trịnh Cao Phong | C78: XE01283 | D78: Tuyến chính | E78: 35912 | F78: 27 | G78: Nam | J78: 29E44377 | K78: 7.1t
A79: 78 | B79: Lê Huy Hùng | C79: XE01284 | D79: Tuyến chính | E79: 35634 | F79: 28 | G79: Nam | J79: 29E54212 | K79: 7.1t
A80: 79 | B80: Nguyễn Hữu Thuỳ | C80: XE01294 | D80: Tuyến chính | E80: 35678 | F80: 28 | G80: Nam | J80: 29E44369 | K80: 7.1t
... A91: 90 | B91: Nguyễn Công Thức | C91: XE01325 | D91: Tuyến chính | E91: 33902 | F91: 33 | G91: Nam | J91: 29E61253 | K91: 2T5
A92: 91 | B92: Trần Văn Hà | C92: XE01328 | D92: Tuyến chính | E92: 32674 | F92: 36 | G92: Nam
A93: 92 | B93: Bùi Văn Đào | C93: XE01331 | D93: Tuyến chính | E93: 37151 | F93: 24 | G93: Nam
A94: 93 | B94: Nguyễn Như Sơn | C94: XE01332 | D94: Tuyến chính | E94: 31289 | F94: 40 | G94: Nam
A95: 94 | B95: Phạm Thanh Tuấn | C95: XE01335 | D95: Tuyến chính | E95: 28354 | F95: 48 | G95: Nam
A96: 95 | B96: Nguyễn Văn Tuấn | C96: XE01336 | D96: Tuyến chính | E96: 31771 | F96: 38 | G96: Nam
A97: 96 | B97: Nguyễn Ánh Sang | C97: XE01337 | D97: Tuyến chính | E97: 32677 | F97: 36 | G97: Nam
A98: 97 | B98: Nguyễn Quang Can | C98: XE01340 | D98: Tuyến chính | E98: 28318 | F98: 48 | G98: Nam
A99: 98 | B99: Hồ Sỹ Luân | C99: XE01341 | D99: Tuyến chính | E99: 32520 | F99: 36 | G99: Nam
A100: 99 | B100: Từ Phạm Quốc Điệp | C100: XE01360 | D100: Tuyến chính | E100: 37374 | F100: 23 | G100: Nam
A101: 100 | B101: Võ Đặng Anh Thông | C101: XE01361 | D101: Tuyến chính | E101: 36747 | F101: 25 | G101: Nam
A102: 101 | B102: Hà Nguyên Dậu | C102: XE00843 | D102: Tuyến chính | E102: 29824 | F102: 44 | G102: Nam
...
