Workbook

Sheet Kangatang_127

Sheet Kangatang_128

Sheet TLTL 112024
A1: Ngày | B1: Tên NPP | C1: QO (bao) | D1: NT (bao) | E1: BS (bao) | F1: Tổng bao | G1: Quốc Oai (T) | H1: Nguyễn Trãi (T) | I1: BS (T) | J1: Tổng Thùng | K1: Biển số xe | L1: Lái xe | M1: SĐT
A2: 45593 | B2: Trường Sơn, Thái Nguyên | C2: 300000 | F2: =E2+D2+C2 -> 300000 | G2: =ROUNDUP(C2/500,0) -> 600 | H2: =ROUNDUP(D2/500,0) -> 0 | I2: =ROUNDUP(E2/500,0) -> 0 | J2: =I2+H2+G2 -> 600 | K2: 29G-023.49 | L2: Lê Văn Giang | M2: 961571433
A3: 45593 | B3: Trường Sơn, Thái Nguyên | C3: 112500 | D3: 25000 | F3: =E3+D3+C3 -> 137500 | G3: =ROUNDUP(C3/500,0) -> 225 | H3: =ROUNDUP(D3/500,0) -> 50 | I3: =ROUNDUP(E3/500,0) -> 0 | J3: =I3+H3+G3 -> 275 | K3: 29K-067.11 | L3: Phạm Văn Hải | M3: 964343887
A4: 45595 | B4: Thủy Chính PT | C4: 11300 | D4: =140000+180000 -> 320000 | F4: =E4+D4+C4 -> 331300 | G4: =ROUNDUP(C4/500,0) -> 23 | H4: =ROUNDUP(D4/500,0) -> 640 | I4: =ROUNDUP(E4/500,0) -> 0 | J4: =I4+H4+G4 -> 663 | K4: 29G-023.25 | L4: Trần Xuân Trường | M4: 974392325
A5: 45595 | B5: Thái Dương VP | D5: 57500 | F5: =E5+D5+C5 -> 57500 | G5: =ROUNDUP(C5/500,0) -> 0 | H5: =ROUNDUP(D5/500,0) -> 115 | I5: =ROUNDUP(E5/500,0) -> 0 | J5: =I5+H5+G5 -> 115 | K5: 29G-023.49 | L5: Lê Văn Giang | M5: 961571433
A6: 45595 | B6: Hạnh Thục VP | C6: =106400+1000 -> 107400 | D6: 32000 | F6: =E6+D6+C6 -> 139400 | G6: =ROUNDUP(C6/500,0) -> 215 | H6: =ROUNDUP(D6/500,0) -> 64 | I6: =ROUNDUP(E6/500,0) -> 0 | J6: =I6+H6+G6 -> 279 | N6: Thương Mại
A7: 45595 | B7: Mai Linh VP | C7: =46600+2000 -> 48600 | F7: =E7+D7+C7 -> 48600 | G7: =ROUNDUP(C7/500,0) -> 98 | H7: =ROUNDUP(D7/500,0) -> 0 | I7: =ROUNDUP(E7/500,0) -> 0 | J7: =I7+H7+G7 -> 98 | N7: Thương Mại
A8: 45595 | B8: Minh Hải VP | C8: 91800 | D8: 15000 | F8: =E8+D8+C8 -> 106800 | G8: =ROUNDUP(C8/500,0) -> 184 | H8: =ROUNDUP(D8/500,0) -> 30 | I8: =ROUNDUP(E8/500,0) -> 0 | J8: =I8+H8+G8 -> 214
A9: 45595 | B9: Tuấn Tuyết YB | C9: 106600 | F9: =E9+D9+C9 -> 106600 | G9: =ROUNDUP(C9/500,0) -> 214 | H9: =ROUNDUP(D9/500,0) -> 0 | I9: =ROUNDUP(E9/500,0) -> 0 | J9: =I9+H9+G9 -> 214 | K9: 29K-067.11 | L9: Phạm Văn Hải | M9: 964343887
A10: 45595 | B10: Hương Giang YB | C10: 21800 | F10: =E10+D10+C10 -> 21800 | G10: =ROUNDUP(C10/500,0) -> 44 | H10: =ROUNDUP(D10/500,0) -> 0 | I10: =ROUNDUP(E10/500,0) -> 0 | J10: =I10+H10+G10 -> 44
A11: 45595 | B11: Nam Hoa PT | C11: 34300 | F11: =E11+D11+C11 -> 34300 | G11: =ROUNDUP(C11/500,0) -> 69 | H11: =ROUNDUP(D11/500,0) -> 0 | I11: =ROUNDUP(E11/500,0) -> 0 | J11: =I11+H11+G11 -> 69
A12: 45595 | B12: Thành Chung VT | C12: 51800 | F12: =E12+D12+C12 -> 51800 | G12: =ROUNDUP(C12/500,0) -> 104 | H12: =ROUNDUP(D12/500,0) -> 0 | I12: =ROUNDUP(E12/500,0) -> 0 | J12: =I12+H12+G12 -> 104 | K12: 29G-023.20 | L12: Mai Văn Long | M12: 971106882
A13: 45595 | B13: Vạn Liên PT | C13: 59000 | F13: =E13+D13+C13 -> 59000 | G13: =ROUNDUP(C13/500,0) -> 118 | H13: =ROUNDUP(D13/500,0) -> 0 | I13: =ROUNDUP(E13/500,0) -> 0 | J13: =I13+H13+G13 -> 118
A14: 45595 | B14: Nhật Nam Anh TQ | C14: 66300 | F14: =E14+D14+C14 -> 66300 | G14: =ROUNDUP(C14/500,0) -> 133 | H14: =ROUNDUP(D14/500,0) -> 0 | I14: =ROUNDUP(E14/500,0) -> 0 | J14: =I14+H14+G14 -> 133
A15: 45595 | B15: Hòa Thu TQ | C15: 22500 | F15: =E15+D15+C15 -> 22500 | G15: =ROUNDUP(C15/500,0) -> 45 | H15: =ROUNDUP(D15/500,0) -> 0 | I15: =ROUNDUP(E15/500,0) -> 0 | J15: =I15+H15+G15 -> 45
A16: 45595 | B16: Tùng Linh TQ | C16: 71500 | F16: =E16+D16+C16 -> 71500 | G16: =ROUNDUP(C16/500,0) -> 143 | H16: =ROUNDUP(D16/500,0) -> 0 | I16: =ROUNDUP(E16/500,0) -> 0 | J16: =I16+H16+G16 -> 143 | K16: 29G-023.19 | L16: Nguyễn Trọng Tấn | M16: 967884730
A17: 45595 | B17: An Lộc Phát LC | C17: 62400 | D17: 20000 | F17: =E17+D17+C17 -> 82400 | G17: =ROUNDUP(C17/500,0) -> 125 | H17: =ROUNDUP(D17/500,0) -> 40 | I17: =ROUNDUP(E17/500,0) -> 0 | J17: =I17+H17+G17 -> 165
A18: 45595 | B18: Ngọc Khang LC | C18: 52300 | F18: =E18+D18+C18 -> 52300 | G18: =ROUNDUP(C18/500,0) -> 105 | H18: =ROUNDUP(D18/500,0) -> 0 | I18: =ROUNDUP(E18/500,0) -> 0 | J18: =I18+H18+G18 -> 105
A19: 45595 | B19: Hải Yến, Hạ Long | C19: =8700+2000 -> 10700 | D19: 87900 | F19: =E19+D19+C19 -> 98600 | G19: =ROUNDUP(C19/500,0) -> 22 | H19: =ROUNDUP(D19/500,0) -> 176 | I19: =ROUNDUP(E19/500,0) -> 0 | J19: =I19+H19+G19 -> 198 | K19: 29G-023.11 | L19: Trần Văn Sơn | M19: 966120021 | N19: Thương Mại
A20: 45595 | B20: Hồng Đức, Uông Bí | C20: 82500 | F20: =E20+D20+C20 -> 82500 | G20: =ROUNDUP(C20/500,0) -> 165 | H20: =ROUNDUP(D20/500,0) -> 0 | I20: =ROUNDUP(E20/500,0) -> 0 | J20: =I20+H20+G20 -> 165
A21: 45596 | B21: Minh Hải VP | D21: 106200 | F21: =E21+D21+C21 -> 106200 | G21: =ROUNDUP(C21/500,0) -> 0 | H21: =ROUNDUP(D21/500,0) -> 213 | I21: =ROUNDUP(E21/500,0) -> 0 | J21: =I21+H21+G21 -> 213 | K21: 29G-023.20 | L21: Mai Văn Long | M21: 971106882
A22: 45596 | B22: Khánh Hòa, Hà Giang | C22: 47800 | F22: =E22+D22+C22 -> 47800 | G22: =ROUNDUP(C22/500,0) -> 96 | H22: =ROUNDUP(D22/500,0) -> 0 | I22: =ROUNDUP(E22/500,0) -> 0 | J22: =I22+H22+G22 -> 96
A23: 45596 | B23: Thủy Chính PT | C23: 1000 | F23: =E23+D23+C23 -> 1000 | G23: =ROUNDUP(C23/500,0) -> 2 | H23: =ROUNDUP(D23/500,0) -> 0 | I23: =ROUNDUP(E23/500,0) -> 0 | J23: =I23+H23+G23 -> 2 | N23: Thương Mại
A24: 45600 | B24: Kim ngân Hải Dương | C24: 29600 | F24: =E24+D24+C24 -> 29600 | G24: =ROUNDUP(C24/500,0) -> 60 | H24: =ROUNDUP(D24/500,0) -> 0 | I24: =ROUNDUP(E24/500,0) -> 0 | J24: =I24+H24+G24 -> 60 | K24: 29G-023.11 | L24: Mai Văn Long Nguyễn Ngọc Anh (bốc) | M24: 971106882
A25: 45600 | B25: Cường Trung HD | C25: 4600 | D25: 95000 | F25: =E25+D25+C25 -> 99600 | G25: =ROUNDUP(C25/500,0) -> 10 | H25: =ROUNDUP(D25/500,0) -> 190 | I25: =ROUNDUP(E25/500,0) -> 0 | J25: =I25+H25+G25 -> 200
A26: 45600 | B26: Hưng Thịnh HD | C26: 5800 | D26: 75000 | F26: =E26+D26+C26 -> 80800 | G26: =ROUNDUP(C26/500,0) -> 12 | H26: =ROUNDUP(D26/500,0) -> 150 | I26: =ROUNDUP(E26/500,0) -> 0 | J26: =I26+H26+G26 -> 162
A27: 45600 | B27: Hưng Thịnh HD | D27: 215000 | F27: =E27+D27+C27 -> 215000 | G27: =ROUNDUP(C27/500,0) -> 0 | H27: =ROUNDUP(D27/500,0) -> 430 | I27: =ROUNDUP(E27/500,0) -> 0 | J27: =I27+H27+G27 -> 430 | K27: 29B-189.64 | L27: Lê Công Vinh | M27: 949502669
A28: 45601 | B28: Thái Dương VP | C28: 3900 | D28: 60000 | F28: =E28+D28+C28 -> 63900 | G28: =ROUNDUP(C28/500,0) -> 8 | H28: =ROUNDUP(D28/500,0) -> 120 | I28: =ROUNDUP(E28/500,0) -> 0 | J28: =I28+H28+G28 -> 128 | K28: 29G-023.19 | L28: Phạm Văn Hải Bùi Văn Tuyến đi theo học việc) | M28: 964343887
A29: 45601 | B29: Hạnh Thục VP | C29: 7200 | D29: 142000 | F29: =E29+D29+C29 -> 149200 | G29: =ROUNDUP(C29/500,0) -> 15 | H29: =ROUNDUP(D29/500,0) -> 284 | I29: =ROUNDUP(E29/500,0) -> 0 | J29: =I29+H29+G29 -> 299
A30: 45601 | B30: Đạt Hà PT | D30: 57500 | F30: =E30+D30+C30 -> 57500 | G30: =ROUNDUP(C30/500,0) -> 0 | H30: =ROUNDUP(D30/500,0) -> 115 | I30: =ROUNDUP(E30/500,0) -> 0 | J30: =I30+H30+G30 -> 115 | K30: 29G-023.49 | L30: Lê Văn Giang | M30: 961571433
A31: 45601 | B31: Vạn Liên PT | D31: 81500 | F31: =E31+D31+C31 -> 81500 | G31: =ROUNDUP(C31/500,0) -> 0 | H31: =ROUNDUP(D31/500,0) -> 163 | I31: =ROUNDUP(E31/500,0) -> 0 | J31: =I31+H31+G31 -> 163
A32: 45601 | B32: Tuấn Tuyết YB | C32: 6300 | D32: 92000 | F32: =E32+D32+C32 -> 98300 | G32: =ROUNDUP(C32/500,0) -> 13 | H32: =ROUNDUP(D32/500,0) -> 184 | I32: =ROUNDUP(E32/500,0) -> 0 | J32: =I32+H32+G32 -> 197
A33: 45601 | B33: Ngọc Khang LC | C33: 5700 | D33: 47900 | F33: =E33+D33+C33 -> 53600 | G33: =ROUNDUP(C33/500,0) -> 12 | H33: =ROUNDUP(D33/500,0) -> 96 | I33: =ROUNDUP(E33/500,0) -> 0 | J33: =I33+H33+G33 -> 108
A34: 45601 | B34: An Lộc Phát LC | C34: 7600 | D34: 62500 | F34: =E34+D34+C34 -> 70100 | G34: =ROUNDUP(C34/500,0) -> 16 | H34: =ROUNDUP(D34/500,0) -> 125 | I34: =ROUNDUP(E34/500,0) -> 0 | J34: =I34+H34+G34 -> 141
A35: 45601 | B35: Đức Oanh, BG | C35: 6000 | D35: 67500 | F35: =E35+D35+C35 -> 73500 | G35: =ROUNDUP(C35/500,0) -> 12 | H35: =ROUNDUP(D35/500,0) -> 135 | I35: =ROUNDUP(E35/500,0) -> 0 | J35: =I35+H35+G35 -> 147 | K35: 29K-067.11 | L35: Hoàng Trọng Nam | M35: 948584663
A36: 45601 | B36: Thành Sơn BG | C36: 5000 | D36: 80000 | F36: =E36+D36+C36 -> 85000 | G36: =ROUNDUP(C36/500,0) -> 10 | H36: =ROUNDUP(D36/500,0) -> 160 | I36: =ROUNDUP(E36/500,0) -> 0 | J36: =I36+H36+G36 -> 170
A37: 45601 | B37: Sơn Hải BG | C37: 76900 | F37: =E37+D37+C37 -> 76900 | G37: =ROUNDUP(C37/500,0) -> 154 | H37: =ROUNDUP(D37/500,0) -> 0 | I37: =ROUNDUP(E37/500,0) -> 0 | J37: =I37+H37+G37 -> 154 | K37: 29G-023.25 | L37: Mai Văn Long (Lê Mạnh Cường đi cùng học việc) | M37: 971106882
A38: 45601 | B38: Lê Thị Viện BN | C38: 37600 | F38: =E38+D38+C38 -> 37600 | G38: =ROUNDUP(C38/500,0) -> 76 | H38: =ROUNDUP(D38/500,0) -> 0 | I38: =ROUNDUP(E38/500,0) -> 0 | J38: =I38+H38+G38 -> 76
A39: 45601 | B39: Lan Anh BN | C39: 8600 | D39: 177000 | F39: =E39+D39+C39 -> 185600 | G39: =ROUNDUP(C39/500,0) -> 18 | H39: =ROUNDUP(D39/500,0) -> 354 | I39: =ROUNDUP(E39/500,0) -> 0 | J39: =I39+H39+G39 -> 372
A40: 45601 | B40: Chiến Nhã, BN | C40: 56200 | F40: =E40+D40+C40 -> 56200 | G40: =ROUNDUP(C40/500,0) -> 113 | H40: =ROUNDUP(D40/500,0) -> 0 | I40: =ROUNDUP(E40/500,0) -> 0 | J40: =I40+H40+G40 -> 113
...

Sheet AEON
A1: Kho bốc hàng | C1: Mã cửa hàng | D1: Tên cửa hàng | E1: Địa chỉ | F1: Định vị | G1: BKS | H1: Tải trọng | I1: Họ tên lái | J1: SĐT | K1: CCCD | L1: Sức chứa CR
C2: 3002 | D2: Maxvalu ECOPARK | E2: ecopark | F2: https://maps.app.goo.gl/CkFZ5Ah2z384Cq4c9 | G2: 29H-464.01 | H2: 2.5 | I2: Chu Lê Tân | J2: 398232148 | K2: 26098005897 | L2: 23
C3: 3015 | D3: Maxvalu WESTBAY | E3: ecopark | F3: https://maps.app.goo.gl/V4XvqSCbD6nbATc57 | G3: 29H-737.03 | H3: 2.5 | I3: Nguyễn Minh Hiếu | J3: 886884883 | K3: 001202021701 | L3: 27
C4: 3030 | D4: Maxvalu SKY OASIS | E4: ecopark | F4: https://maps.app.goo.gl/vBhevvFiVH571ewYA | G4: 29K-067.25 | H4: 3.5 | I4: Nguyễn Văn Lực | J4: 966353312 | K4: 1090008150 | L4: 37
C5: 3020 | D5: Maxvalu ECOPARK 3 | E5: ecopark 3 | F5: https://maps.app.goo.gl/HbKfMAM6ZJ2cki33A | G5: 29G-023.14 | H5: 1.5 | I5: Chu Lê Tân | J5: 398232148 | K5: 26098005897 | L5: 15
C6: 3016 | D6: Maxvalu OCEAN PARK | E6: ocean park | F6: https://maps.app.goo.gl/cb3YQh3TLsTwSWVn8 | G6: 29G-023.46 | H6: 1.5 | L6: 15
C7: 3027 | D7: Maxvalu ZENPARK | E7: ocean park | F7: https://maps.app.goo.gl/upjpQVJxoECjeWUMA | G7: 29G-023.30 | H7: 1.5 | L7: 15
C8: 3031 | D8: Maxvalu SYMPHONY | E8: riverside long biên | F8: https://maps.app.goo.gl/4kxASnHEEVuKooRq5 | G8: 29LD-305.39 | H8: 1.5 | L8: 15
C9: 3023 | D9: Maxvalu KOSMO | E9: tây hồ | F9: https://maps.app.goo.gl/ok7bBzsmsChjA4sr9
C10: 3005 | D10: Maxvalu HORIZON | E10: ngoại giao đoàn | F10: https://maps.app.goo.gl/7Gcj3GRwWU6jMGVG8
C11: 3013 | D11: Maxvalu LOTUS | E11: ngoại giao đoàn | F11: https://maps.app.goo.gl/DcaBy1fNELXvJRz79
C12: 3032 | D12: Maxvalu FIVE STAR | E12: kim giang | F12: https://maps.app.goo.gl/dWzVrEQezADjS6xr8
C13: 3003 | D13: Maxvalu RIVERSIDE | E13: khương đình | F13: https://maps.app.goo.gl/wuxnYz6HHJwtPaB47
C14: 3011 | D14: Maxvalu THĂNG LONG | E14: đại lộ thăng long | F14: https://maps.app.goo.gl/wBa5ge1ERrYYzM5j8
C15: 3018 | D15: Maxvalu LĨNH NAM | E15: lĩnh nam | F15: https://maps.app.goo.gl/D7aS56u6ApgMQraJ8
C16: 3014 | D16: Maxvalu LINH ĐÀM | E16: linh đàm | F16: https://maps.app.goo.gl/xMeDLNAUwuUVZmRK8
C17: 3033 | D17: Maxvalu SAPPHIRE | E17: ocean park | F17: https://maps.app.goo.gl/9ZDNPuA3MT4eRRjT6
B18: DANH SÁCH LÁI XE VÀ BIỂN SỐ XE CHỞ HÀNG KHÔ AEON
F19: NGÀY: | G19: =TODAY()+1 -> 46214
B21: Ngày | C21: Xe | D21: BKS | E21: Tải trọng (tấn) | F21: Họ tên lái | G21: SĐT | H21: CCCD | I21: Mã Cửa Hàng | J21: Tên Cửa Hàng | K21: Số CR | L21: Thời Gian XK
B22: 45568 | C22: Truck 1 | D22: 29K-067.25 | E22: =IFERROR(VLOOKUP(D22,#REF!,6,0),"") | F22: Phan Lưu Trường | G22: =IFERROR(VLOOKUP(F22,#REF!,2,0),"") | H22: =IFERROR(VLOOKUP(F22,#REF!,3,0),"") | I22: 3020 | J22: =IFERROR(VLOOKUP(I22,#REF!,2,0),"") | K22: 9
B23: 45568 | I23: 3027 | J23: =IFERROR(VLOOKUP(I23,#REF!,2,0),"") | K23: 9
B24: 45568 | I24: 3016 | J24: =IFERROR(VLOOKUP(I24,#REF!,2,0),"") | K24: 9
B25: 45568 | C25: Truck 2 | D25: 29G-023.46 | E25: =IFERROR(VLOOKUP(D25,#REF!,6,0),"") | F25: Nguyễn Thành Hưng | G25: =IFERROR(VLOOKUP(F25,#REF!,2,0),"") | H25: =IFERROR(VLOOKUP(F25,#REF!,3,0),"") | I25: 3015 | J25: =IFERROR(VLOOKUP(I25,#REF!,2,0),"") | K25: 7
B26: 45568 | I26: 3030 | J26: =IFERROR(VLOOKUP(I26,#REF!,2,0),"") | K26: 7
B27: 45568 | C27: Truck 3 | D27: 29G-023.14 | E27: =IFERROR(VLOOKUP(D27,#REF!,6,0),"") | F27: Đầu Xuân Thành | G27: =IFERROR(VLOOKUP(F27,#REF!,2,0),"") | H27: =IFERROR(VLOOKUP(F27,#REF!,3,0),"") | I27: 3002 | J27: =IFERROR(VLOOKUP(I27,#REF!,2,0),"") | K27: 10
B28: 45568 | C28: Truck 4 | D28: 29H-464.01 | E28: =IFERROR(VLOOKUP(D28,#REF!,6,0),"") | F28: Khổng Quốc Hải | G28: =IFERROR(VLOOKUP(F28,#REF!,2,0),"") | H28: =IFERROR(VLOOKUP(F28,#REF!,3,0),"") | I28: 3003 | J28: =IFERROR(VLOOKUP(I28,#REF!,2,0),"") | K28: 8
B29: 45568 | I29: 3032 | J29: =IFERROR(VLOOKUP(I29,#REF!,2,0),"") | K29: 5
B30: 45568 | I30: 3011 | J30: =IFERROR(VLOOKUP(I30,#REF!,2,0),"") | K30: 8
B31: 45568 | C31: Truck 5 | D31: 29K-067.25 | E31: =IFERROR(VLOOKUP(D31,#REF!,6,0),"") | F31: Phan Lưu Trường | G31: =IFERROR(VLOOKUP(F31,#REF!,2,0),"") | H31: =IFERROR(VLOOKUP(F31,#REF!,3,0),"") | I31: 3031 | J31: =IFERROR(VLOOKUP(I31,#REF!,2,0),"") | K31: 6
B32: 45568 | I32: 3005 | J32: =IFERROR(VLOOKUP(I32,#REF!,2,0),"") | K32: 7
B33: 45568 | I33: 3013 | J33: =IFERROR(VLOOKUP(I33,#REF!,2,0),"") | K33: 8
B34: 45568 | I34: 3023 | J34: =IFERROR(VLOOKUP(I34,#REF!,2,0),"") | K34: 7
B35: 45568 | C35: Truck 6 | D35: 29G-023.14 | E35: =IFERROR(VLOOKUP(D35,#REF!,6,0),"") | F35: Đầu Xuân Thành | G35: =IFERROR(VLOOKUP(F35,#REF!,2,0),"") | H35: =IFERROR(VLOOKUP(F35,#REF!,3,0),"") | I35: 3018 | J35: =IFERROR(VLOOKUP(I35,#REF!,2,0),"") | K35: 6
B36: 45568 | I36: 3014 | J36: =IFERROR(VLOOKUP(I36,#REF!,2,0),"") | K36: 8
B37: 45569 | C37: Truck 1 | D37: 29K-067.25 | E37: =IFERROR(VLOOKUP(D37,#REF!,6,0),"") | F37: Phan Lưu Trường | G37: =IFERROR(VLOOKUP(F37,#REF!,2,0),"") | H37: =IFERROR(VLOOKUP(F37,#REF!,3,0),"") | I37: 3005 | J37: =IFERROR(VLOOKUP(I37,#REF!,2,0),"") | K37: 7 | L37: 0.39583333
B38: 45569 | I38: 3013 | J38: =IFERROR(VLOOKUP(I38,#REF!,2,0),"") | K38: 7
B39: 45569 | I39: 3023 | J39: =IFERROR(VLOOKUP(I39,#REF!,2,0),"") | K39: 7
B40: 45569 | I40: 3031 | J40: =IFERROR(VLOOKUP(I40,#REF!,2,0),"") | K40: 6
B41: 45569 | C41: Truck 2 | D41: 29H-464.01 | E41: =IFERROR(VLOOKUP(D41,#REF!,6,0),"") | F41: Khổng Quốc Hải | G41: =IFERROR(VLOOKUP(F41,#REF!,2,0),"") | H41: =IFERROR(VLOOKUP(F41,#REF!,3,0),"") | I41: 3027 | J41: =IFERROR(VLOOKUP(I41,#REF!,2,0),"") | K41: 10 | L41: 0.41666667
...

Sheet T12.2024
B1: Tháng | C1: 45627
C2: =COUNTA(C5:C50) -> 31 | D2: =COUNTA(D5:D50) -> 32
A3: STT | B3: Chức danh | C3: BSX | D3: Họ tên | E3: SĐT | F3: Tải trọng | G3: TLTL | H3: Dự án | I3: =+C1 -> 45627 | J3: =+I3+1 -> 45628 | K3: =+J3+1 -> 45629 | L3: =+K3+1 -> 45630 | M3: =+L3+1 -> 45631 | N3: =+M3+1 -> 45632 | O3: =+N3+1 -> 45633 | P3: =+O3+1 -> 45634 | Q3: =+P3+1 -> 45635 | ... AM3: =+AL3+1 -> 45657 | AN3: Tổng công
I4: =+IF(WEEKDAY(I3)=1, "CN", "T"&WEEKDAY(I3)) -> CN | J4: =+IF(WEEKDAY(J3)=1, "CN", "T"&WEEKDAY(J3)) -> T2 | K4: =+IF(WEEKDAY(K3)=1, "CN", "T"&WEEKDAY(K3)) -> T3 | L4: =+IF(WEEKDAY(L3)=1, "CN", "T"&WEEKDAY(L3)) -> T4 | M4: =+IF(WEEKDAY(M3)=1, "CN", "T"&WEEKDAY(M3)) -> T5 | N4: =+IF(WEEKDAY(N3)=1, "CN", "T"&WEEKDAY(N3)) -> T6 | O4: =+IF(WEEKDAY(O3)=1, "CN", "T"&WEEKDAY(O3)) -> T7 | P4: =+IF(WEEKDAY(P3)=1, "CN", "T"&WEEKDAY(P3)) -> CN | ... AM4: =+IF(WEEKDAY(AM3)=1, "CN", "T"&WEEKDAY(AM3)) -> T3
A5: =+ROW()-4 -> 1 | B5: Điều hành | D5: Vũ Thị Lâm | E5: 969387616 | I5: O | J5: X | K5: X | L5: X | M5: X | N5: X | O5: X | P5: O | Q5: X | R5: X | S5: X | T5: X | U5: X | V5: X | W5: O | X5: X | Y5: X | Z5: X | AA5: X | AB5: X | AC5: X | AD5: O | AE5: X | AF5: X | AG5: X | AH5: X | AI5: X | AJ5: O | AK5: O | AL5: X | AM5: X | AN5: =COUNTA(I5:AM5)-COUNTIF(I5:AM5,$AP$8)-COUNTIF(I5:AM5,$AP$9)-COUNTIF(I5:AM5,$AP$10)-COUNTIF(I5:AM5,$AP$18)/2 -> 25
A6: =+ROW()-4 -> 2 | B6: QLPT | D6: Nguyễn Thành Hưng | E6: 915008283 | I6: O | J6: X | K6: X | L6: X | M6: X | N6: X | O6: X | P6: O | Q6: X | R6: X | S6: X | T6: X | U6: X | V6: X | W6: O | X6: X | Y6: X | Z6: X | AA6: X | AB6: X | AC6: X | AD6: O | AE6: X | AF6: X | AG6: X | AH6: X | AI6: X | AJ6: X | AK6: O | AL6: X | AM6: X | AN6: =COUNTA(I6:AM6)-COUNTIF(I6:AM6,$AP$8)-COUNTIF(I6:AM6,$AP$9)-COUNTIF(I6:AM6,$AP$10)-COUNTIF(I6:AM6,$AP$18)/2 -> 26
A7: =+ROW()-4 -> 3 | B7: Điều hành | D7: Phan Mạnh Tân | E7: 827264994 | I7: O | J7: X | K7: X | L7: X | M7: X | N7: X | O7: X | P7: O | Q7: X | R7: X | S7: X | T7: X | U7: X | V7: X | W7: O | X7: X | Y7: X | Z7: X | AA7: X | AB7: X | AC7: X | AD7: O | AE7: X | AF7: X | AG7: X | AH7: X | AI7: X | AJ7: O | AK7: O | AL7: O | AM7: O | AN7: =COUNTA(I7:AM7)-COUNTIF(I7:AM7,$AP$8)-COUNTIF(I7:AM7,$AP$9)-COUNTIF(I7:AM7,$AP$10)-COUNTIF(I7:AM7,$AP$18)/2 -> 23
A8: =+ROW()-4 -> 4 | B8: Điều hành | D8: Đặng Thanh Tuyền | E8: 972264311 | L8: X | M8: X | N8: X | O8: X | P8: O | Q8: X | R8: X | S8: X | T8: X | U8: X | V8: X | W8: O | X8: X | Y8: X | Z8: X | AA8: X | AB8: X | AC8: X | AD8: O | AE8: X | AF8: X | AG8: X | AH8: X | AI8: X | AJ8: X | AK8: O | AL8: X | AM8: X | AN8: =COUNTA(I8:AM8)-COUNTIF(I8:AM8,$AP$8)-COUNTIF(I8:AM8,$AP$9)-COUNTIF(I8:AM8,$AP$10)-COUNTIF(I8:AM8,$AP$18)/2 -> 24 | AP8: O | AQ8: Xin nghỉ - cắt nghỉ
A9: =+ROW()-4 -> 5 | B9: Lái xe tuyến | C9: 29H-743.40 | D9: Nguyễn Xuân Thế | E9: 387151811 | F9: 1.9 | H9: NB | I9: O | J9: NN | K9: X | L9: X | M9: X | N9: X | O9: X | P9: X | Q9: X | R9: X | S9: X | T9: X | U9: X | V9: O | W9: X | X9: X | Y9: X | Z9: X | AA9: X | AB9: X | AC9: X | AD9: X | AE9: X | AF9: X | AG9: X | AH9: X | AI9: X | AJ9: X | AK9: X | AL9: X | AM9: X | AN9: =COUNTA(I9:AM9)-COUNTIF(I9:AM9,$AP$8)-COUNTIF(I9:AM9,$AP$9)-COUNTIF(I9:AM9,$AP$10)-COUNTIF(I9:AM9,$AP$18)/2 -> 28.5 | AP9: ĐC | AQ9: Đình chỉ
A10: =+ROW()-4 -> 6 | B10: Lái xe tuyến | C10: 29H-849.91 | D10: Nhâm Văn Cương | E10: 978286576 | F10: 3.5 | H10: TB-NĐ | I10: X | J10: X | K10: X | L10: X | M10: X | N10: X | O10: X | P10: X | Q10: X | R10: X | S10: X | T10: X | U10: X | V10: X | W10: O | X10: X | Y10: X | Z10: X | AA10: X | AB10: X | AC10: X | AD10: X | AE10: X | AF10: X | AG10: X | AH10: X | AI10: X | AJ10: X | AK10: X | AL10: X | AM10: X | AN10: =COUNTA(I10:AM10)-COUNTIF(I10:AM10,$AP$8)-COUNTIF(I10:AM10,$AP$9)-COUNTIF(I10:AM10,$AP$10)-COUNTIF(I10:AM10,$AP$18)/2 -> 30 | AP10: OF | AQ10: Nghỉ việc
A11: =+ROW()-4 -> 7 | B11: LX dự án | C11: 29H-737.03 | D11: Nguyễn Minh Hiếu | E11: 886884883 | F11: 2.5 | H11: AEON | I11: O | J11: X | K11: X | L11: X | M11: X | N11: X | O11: X | P11: O | Q11: X | R11: X | S11: X | T11: X | U11: X | V11: X | W11: O | X11: X | Y11: X | Z11: X | AA11: X | AB11: X | AC11: X | AD11: O | AE11: X | AF11: X | AG11: X | AH11: X | AI11: X | AJ11: X | AK11: O | AL11: X | AM11: X | AN11: =COUNTA(I11:AM11)-COUNTIF(I11:AM11,$AP$8)-COUNTIF(I11:AM11,$AP$9)-COUNTIF(I11:AM11,$AP$10)-COUNTIF(I11:AM11,$AP$18)/2 -> 26 | AP11: X | AQ11: Chạy xe cả ngày
A12: =+ROW()-4 -> 8 | B12: LX dự án | C12: 29K-067.25 | D12: Nguyễn Văn Lực | E12: 966353312 | F12: 3.5 | H12: AEON | I12: O | J12: X | K12: X | L12: X | M12: O | N12: O | O12: X | P12: O | Q12: X | R12: X | S12: O | T12: X | U12: X | V12: O | W12: O | X12: X | Y12: X | Z12: X | AA12: X | AB12: X | AC12: X | AD12: O | AE12: X | AF12: X | AG12: O | AH12: O | AI12: X | AJ12: X | AK12: O | AL12: X | AM12: X | AN12: =COUNTA(I12:AM12)-COUNTIF(I12:AM12,$AP$8)-COUNTIF(I12:AM12,$AP$9)-COUNTIF(I12:AM12,$AP$10)-COUNTIF(I12:AM12,$AP$18)/2 -> 20 | AP12: TL | AQ12: Thuốc lá
A13: 11 | B13: LX dự án | C13: 29H-464.01 | D13: Nguyễn Hữu Tùng | E13: 913500445 | F13: 2.5 | H13: AEON | Y13: X | Z13: X | AA13: X | AB13: X | AC13: X | AD13: O | AE13: X | AF13: X | AG13: X | AH13: X | AI13: X | AJ13: X | AK13: O | AL13: X | AM13: X | AP13: HC | AQ13: Hóa chất
A14: =+ROW()-4 -> 10 | B14: Bốc xếp | D14: Trần Thị Thu Khanh | E14: 971929815 | H14: AEON | I14: O | J14: X | K14: X | L14: X | M14: X | N14: X | O14: X | P14: O | Q14: X | R14: X | S14: X | T14: X | U14: X | V14: X | W14: O | X14: X | Y14: X | Z14: X | AA14: X | AB14: X | AC14: X | AD14: O | AE14: X | AF14: X | AG14: X | AH14: X | AI14: X | AJ14: X | AK14: O | AL14: X | AM14: X | AN14: =COUNTA(I14:AM14)-COUNTIF(I14:AM14,$AP$8)-COUNTIF(I14:AM14,$AP$9)-COUNTIF(I14:AM14,$AP$10)-COUNTIF(I14:AM14,$AP$18)/2 -> 26 | AP14: TT | AQ14: Từ thiện
A15: =+ROW()-4 -> 11 | B15: Bốc xếp | D15: Lưu Văn Cường | E15: 333479454 | H15: AEON | Q15: X | R15: X | S15: X | T15: X | U15: X | V15: X | W15: O | X15: X | Y15: X | Z15: X | AA15: X | AB15: X | AC15: X | AD15: O | AE15: X | AF15: X | AG15: X | AH15: X | AI15: X | AJ15: X | AK15: O | AL15: X | AM15: X | AN15: =COUNTA(I15:AM15)-COUNTIF(I15:AM15,$AP$8)-COUNTIF(I15:AM15,$AP$9)-COUNTIF(I15:AM15,$AP$10)-COUNTIF(I15:AM15,$AP$18)/2 -> 20 | AP15: TN | AQ15: Thống Nhất
A16: =+ROW()-4 -> 12 | B16: LX dự án | C16: 29K-067.11 | D16: Phan Lưu Trường | E16: 326522825 | F16: 5.5 | G16: 370 | H16: TLTL | I16: O | J16: Aeon | K16: X | L16: TL | M16: TL | N16: TL | O16: TL | P16: O | Q16: vigo | R16: aeon | S16: TL | T16: TL | U16: TL | V16: aeon | W16: O | X16: aeon | Y16: X | Z16: X | AA16: vigo | AB16: TL | AC16: X | AD16: O | AE16: aeon | AF16: TL | AG16: TL | AH16: TL | AI16: TL | AJ16: TL | AK16: TL | AL16: X | AM16: X | AN16: =COUNTA(I16:AM16)-COUNTIF(I16:AM16,$AP$8)-COUNTIF(I16:AM16,$AP$9)-COUNTIF(I16:AM16,$AP$10)-COUNTIF(I16:AM16,$AP$18)/2 -> 27 | AP16: CT | AQ16: Chạy tuyến
A17: =+ROW()-4 -> 13 | B17: LX dự án | C17: 29G-023.11 | D17: Phạm Văn Hải A | E17: 964343887 | F17: 6.5 | G17: 440 | H17: TLTL | I17: O | J17: X | K17: TL | L17: TL | M17: TL.dm | N17: TL | O17: TL | P17: O | Q17: X | R17: vinaf | S17: TL | T17: TL | U17: TL | V17: TL | W17: O | X17: TL | Y17: TL | Z17: TL | AA17: TL | AB17: TL | AC17: TC | AD17: TL | AE17: X | AF17: TL | AG17: TL | AH17: TL | AI17: X | AJ17: TL | AK17: TL | AL17: X | AM17: X | AN17: =COUNTA(I17:AM17)-COUNTIF(I17:AM17,$AP$8)-COUNTIF(I17:AM17,$AP$9)-COUNTIF(I17:AM17,$AP$10)-COUNTIF(I17:AM17,$AP$18)/2 -> 28 | AP17: HTP | AQ17: Hưng Toàn Phát
A18: =+ROW()-4 -> 14 | B18: LX dự án | C18: 29G-023.20 | D18: Lê Mạnh Cường | E18: 923453896 | F18: 6.5 | G18: 440 | H18: TLTL | I18: X | J18: Aeon | K18: TL | L18: TL | M18: TL | N18: TL | O18: CPN | P18: vinaf | Q18: aeon | R18: TL | S18: TL | T18: TL | U18: TL | V18: cpn | W18: cpn | X18: X | Y18: O | Z18: O | AA18: O | AB18: TC | AC18: TL | AD18: O | AE18: X | AF18: cpn | AG18: TL | AH18: _x001D_TL | AI18: dm | AJ18: dm | AK18: X | AL18: X | AM18: X | AN18: =COUNTA(I18:AM18)-COUNTIF(I18:AM18,$AP$8)-COUNTIF(I18:AM18,$AP$9)-COUNTIF(I18:AM18,$AP$10)-COUNTIF(I18:AM18,$AP$18)/2 -> 27 | AP18: NN | AQ18: Nửa ngày
A19: =+ROW()-4 -> 15 | B19: LX dự án | C19: 29G-023.19 | D19: Nguyễn Trọng Tấn | E19: 967884730 | F19: 6.5 | G19: 440 | H19: TLTL | I19: O | J19: X | K19: TL | L19: TL | M19: TL | N19: TL | O19: TL | P19: O | Q19: aeon | R19: TL | S19: TL | T19: TL | U19: TL | V19: O | W19: O | X19: X | Y19: TL | Z19: TL | AA19: TL | AB19: X | AC19: TC | AD19: TL | AE19: X | AF19: TL | AG19: TL | AH19: TL | AI19: TL | AJ19: X | AK19: X | AL19: X | AM19: X | AN19: =COUNTA(I19:AM19)-COUNTIF(I19:AM19,$AP$8)-COUNTIF(I19:AM19,$AP$9)-COUNTIF(I19:AM19,$AP$10)-COUNTIF(I19:AM19,$AP$18)/2 -> 27
A20: =+ROW()-4 -> 16 | B20: LX dự án | C20: 29B-189.64 | D20: Lê Công Vinh | E20: 949502669 | F20: 6.5 | G20: 440 | H20: TLTL | I20: O | J20: X | K20: TL | L20: TL | M20: aeon | N20: TL | O20: TL | P20: O | Q20: TL | R20: TL | S20: TL | T20: dm | U20: dm | V20: TL | W20: O | X20: TL | Y20: TL | Z20: TL | AA20: TL | AB20: X | AC20: TC | AD20: TL | AE20: O | AF20: TL | AG20: TL | AH20: O | AI20: X | AJ20: TL | AK20: TL | AL20: TL | AM20: X | AN20: =COUNTA(I20:AM20)-COUNTIF(I20:AM20,$AP$8)-COUNTIF(I20:AM20,$AP$9)-COUNTIF(I20:AM20,$AP$10)-COUNTIF(I20:AM20,$AP$18)/2 -> 26
A21: =+ROW()-4 -> 17 | B21: LX dự án | C21: 29G-023.25 | D21: Mai Văn Long | E21: 971106882 | F21: 8 | G21: 700 | H21: TLTL | I21: CPN | J21: X | K21: X | L21: TL | M21: TL | N21: TL | O21: vigo | P21: O | Q21: X | R21: dm | S21: TL | T21: anviet | U21: anviet | V21: TL | W21: O | X21: ps | Y21: TL | Z21: TL | AA21: đm | AB21: TL | AC21: O | AD21: TC | AE21: TL | AF21: TL | AG21: TL | AH21: TL | AI21: TL | AJ21: TL | AK21: TL | AL21: X | AM21: vigo | AN21: =COUNTA(I21:AM21)-COUNTIF(I21:AM21,$AP$8)-COUNTIF(I21:AM21,$AP$9)-COUNTIF(I21:AM21,$AP$10)-COUNTIF(I21:AM21,$AP$18)/2 -> 28
A22: =+ROW()-4 -> 18 | B22: LX dự án | C22: 29K-063.74 | D22: Lê Văn Giang | E22: 961571433 | F22: 8 | G22: 700 | H22: TLTL | I22: O | J22: X | K22: X | L22: TL | M22: TL | N22: TL | O22: TL | P22: O | Q22: X | R22: TL | S22: TL | T22: anviet | U22: anviet | V22: TL | W22: O | X22: X | Y22: TL | Z22: TL | AA22: TL | AB22: huế | AC22: huế | AD22: O | AE22: X | AF22: TL | AG22: TL | AH22: TL | AI22: TL | AJ22: TL | AK22: X | AL22: X | AM22: X | AN22: =COUNTA(I22:AM22)-COUNTIF(I22:AM22,$AP$8)-COUNTIF(I22:AM22,$AP$9)-COUNTIF(I22:AM22,$AP$10)-COUNTIF(I22:AM22,$AP$18)/2 -> 27
A23: =+ROW()-4 -> 19 | B23: LX dự án | C23: 29K-069.35 | D23: Phan Trung Thành | E23: 981636699 | F23: 8 | G23: 700 | I23: O | J23: X | K23: X | L23: TL | M23: vinaf | N23: TL | O23: TL | P23: vinaf | Q23: X | R23: TT | S23: TT | T23: dm | U23: TL | V23: O | W23: O | X23: X | Y23: X | Z23: TL | AA23: TL | AB23: X | AC23: VTL | AD23: VTL | AE23: VTL | AF23: VTL | AG23: VTL | AH23: O | AI23: O | AJ23: O | AK23: O | AL23: O | AM23: O | AN23: =COUNTA(I23:AM23)-COUNTIF(I23:AM23,$AP$8)-COUNTIF(I23:AM23,$AP$9)-COUNTIF(I23:AM23,$AP$10)-COUNTIF(I23:AM23,$AP$18)/2 -> 22
A24: =+ROW()-4 -> 20 | B24: LX dự án | D24: Nguyễn Xuân Nam | E24: 776874999 | F24: 8 | U24: vinafco | V24: X | W24: O | X24: X | Y24: TL | Z24: TL | AA24: TL | AB24: X | AC24: VTL | AD24: VTL | AE24: VTL | AF24: VTL | AG24: VTL | AH24: O | AI24: O | AJ24: O | AK24: O | AL24: O | AM24: O | AN24: =COUNTA(I24:AM24)-COUNTIF(I24:AM24,$AP$8)-COUNTIF(I24:AM24,$AP$9)-COUNTIF(I24:AM24,$AP$10)-COUNTIF(I24:AM24,$AP$18)/2 -> 12
A25: =+ROW()-4 -> 21 | B25: LX dự án | C25: 29K-068.20 | D25: Nguyễn Văn Sang | E25: 969820625 | F25: 8 | G25: 730 | M25: hoc viec | N25: TL | O25: TL | P25: O | Q25: vinaf | R25: O | S25: TL | T25: dm | U25: anviet | V25: anviet | W25: TL | X25: TL | Y25: X | Z25: TL | AA25: TL | AB25: TC | AC25: TL | AD25: O | AE25: X | AF25: X | AG25: TL | AH25: TL | AI25: hc | AJ25: hc | AK25: X | AL25: X | AM25: X | AN25: =COUNTA(I25:AM25)-COUNTIF(I25:AM25,$AP$8)-COUNTIF(I25:AM25,$AP$9)-COUNTIF(I25:AM25,$AP$10)-COUNTIF(I25:AM25,$AP$18)/2 -> 24
A26: =+ROW()-4 -> 22 | B26: LX dự án | D26: Lê Đức Bách | E26: 989852112 | F26: 8 | Z26: X | AA26: O | AB26: O | AC26: O | AD26: VTL | AE26: VTL | AF26: VTL | AG26: VTL | AH26: VTL | AI26: TL | AJ26: X | AK26: X | AL26: X | AM26: X | AN26: =COUNTA(I26:AM26)-COUNTIF(I26:AM26,$AP$8)-COUNTIF(I26:AM26,$AP$9)-COUNTIF(I26:AM26,$AP$10)-COUNTIF(I26:AM26,$AP$18)/2 -> 11
A27: =+ROW()-4 -> 23 | B27: LX dự án | C27: 29G-023.49 | D27: Hoàng Minh Thịnh | E27: 989118712 | F27: 8 | G27: 700 | R27: TL | S27: TL | T27: TL | U27: TL | V27: anviet | W27: anviet | X27: O | Y27: O | Z27: O | AA27: TL | AB27: TL | AC27: TL | AD27: VTL | AE27: VTL | AF27: VTL | AG27: VTL | AH27: VTL | AI27: TL | AJ27: TL | AK27: X | AL27: X | AM27: X | AN27: =COUNTA(I27:AM27)-COUNTIF(I27:AM27,$AP$8)-COUNTIF(I27:AM27,$AP$9)-COUNTIF(I27:AM27,$AP$10)-COUNTIF(I27:AM27,$AP$18)/2 -> 19
A28: =+ROW()-4 -> 24 | B28: LX dự án | C28: 29K-068.24 | D28: Nguyễn Văn Anh | E28: 974072826 | F28: 8 | G28: 730 | I28: X | J28: X | K28: X | L28: TL | M28: TL | N28: TL | O28: dm | P28: O | Q28: X | R28: TL | S28: dm | T28: TL | U28: TL | V28: anviet | W28: anviet | X28: X | Y28: X | Z28: TL | AA28: TL | AB28: TL | AC28: X | AD28: TL | AE28: TL | AF28: TL | AG28: TL | AH28: FTG | AI28: FTG | AJ28: FTG | AK28: FTG | AL28: FTG | AM28: FTG | AN28: =COUNTA(I28:AM28)-COUNTIF(I28:AM28,$AP$8)-COUNTIF(I28:AM28,$AP$9)-COUNTIF(I28:AM28,$AP$10)-COUNTIF(I28:AM28,$AP$18)/2 -> 30
A29: =+ROW()-4 -> 25 | B29: LX dự án | D29: Phạm Văn Hải B | E29: 379427150 | F29: 8 | AG29: X | AH29: FTG | AI29: FTG | AJ29: FTG | AK29: FTG | AL29: FTG | AM29: FTG | AN29: =COUNTA(I29:AM29)-COUNTIF(I29:AM29,$AP$8)-COUNTIF(I29:AM29,$AP$9)-COUNTIF(I29:AM29,$AP$10)-COUNTIF(I29:AM29,$AP$18)/2 -> 7
A30: =+ROW()-4 -> 26 | B30: LX dự án | C30: 29K-079.24 | D30: Trần Xuân Trường | E30: 974392325 | F30: 15 | G30: 650 | I30: X | J30: X | K30: X | L30: TL | M30: dm | N30: TL | O30: X | P30: O | Q30: X | R30: TL | S30: đm, TL | T30: TL | U30: anviet | V30: anviet | W30: TL | X30: TL | Y30: TL | Z30: O | AA30: O | AB30: O | AC30: O | AD30: O | AE30: X | AF30: TL | AG30: huế | AH30: huế | AI30: TL | AJ30: TL | AK30: X | AL30: X | AM30: X | AN30: =COUNTA(I30:AM30)-COUNTIF(I30:AM30,$AP$8)-COUNTIF(I30:AM30,$AP$9)-COUNTIF(I30:AM30,$AP$10)-COUNTIF(I30:AM30,$AP$18)/2 -> 25
A31: =+ROW()-4 -> 27 | B31: LX dự án | D31: Nguyễn Đức Thiên | E31: 974172336 | S31: aeon | T31: X | U31: vinafco | V31: TL | W31: X | X31: X | Y31: ps | Z31: O | AA31: O | AB31: O | AC31: O | AD31: X | AE31: X | AF31: TL | AG31: TL | AH31: TL | AI31: TL | AJ31: TL | AK31: TL | AL31: TL | AM31: X | AN31: =COUNTA(I31:AM31)-COUNTIF(I31:AM31,$AP$8)-COUNTIF(I31:AM31,$AP$9)-COUNTIF(I31:AM31,$AP$10)-COUNTIF(I31:AM31,$AP$18)/2 -> 17
A32: =+ROW()-4 -> 28 | B32: LX parttime | D32: Trần Trọng Văn | E32: 971162102 | H32: VINAFCO | N32: X | O32: X
A33: =+ROW()-4 -> 29 | B33: LX Limo | D33: Nguyễn Thanh Xuân | E33: 989789208 | H33: YB - PT | L33: X
A34: =+ROW()-4 -> 30 | B34: LX Limo | D34: Phạm Công Khánh | E34: 917078878 | H34: YB | T34: X
A35: =+ROW()-4 -> 31 | B35: LX dự án | D35: Nguyễn Văn Sang TB | E35: 966030118 | H35: VINAFCO | O35: aeon | P35: X | Q35: X | R35: X | S35: OF | AN35: =COUNTA(I35:AM35)-COUNTIF(I35:AM35,$AP$8)-COUNTIF(I35:AM35,$AP$9)-COUNTIF(I35:AM35,$AP$10)-COUNTIF(I35:AM35,$AP$18)/2 -> 4
A36: =+ROW()-4 -> 32 | B36: LX dự án | D36: Chu Lê Tân | E36: 398232148 | F36: 1.5 | H36: AEON | I36: O | J36: X | K36: X | L36: X | M36: X | N36: X | O36: O | P36: O | Q36: X | R36: NN | S36: NN | T36: OF | AN36: =COUNTA(I36:AM36)-COUNTIF(I36:AM36,$AP$8)-COUNTIF(I36:AM36,$AP$9)-COUNTIF(I36:AM36,$AP$10)-COUNTIF(I36:AM36,$AP$18)/2 -> 7
A37: =+ROW()-4 -> 33 | C37: 29K-139.05 | F37: 8 | G37: 730
A38: =+ROW()-4 -> 34 | C38: 29K-134.59 | F38: 8 | G38: 730
A39: =+ROW()-4 -> 35 | C39: 29K-136.97 | F39: 8 bạt | G39: 650
A40: =+ROW()-4 -> 36 | C40: 29K-137.42 | F40: 8 bạt | G40: 650
...

Sheet TLTL 122024
A1: Mai Long TN | B1: Tên NPP | C1: Tỉnh | D1: QO (bao) | E1: NT (bao) | F1: BS (bao) | G1: Thanh Hoá | H1: Tổng bao | I1: Quốc Oai (T) | J1: Nguyễn Trãi (T) | K1: BS (T) | L1: Thanh Hoá | M1: Tổng Thùng | N1: Biển số xe | O1: Lái xe | P1: SĐT | Q1: Thương Mại
A2: 45622 | B2: Trường Sơn TN | C2: =RIGHT(B2,2) -> TN | E2: 15000 | F2: =310000 -> 310000 | H2: =F2+E2+D2 -> 325000 | I2: =ROUNDUP(D2/500,0) -> 0 | J2: =ROUNDUP(E2/500,0) -> 30 | K2: =ROUNDUP(F2/500,0) -> 620 | M2: =K2+J2+I2 -> 650 | N2: 29G-023.49 | O2: Nguyễn Trọng Tấn | P2: 967884730
A3: 45622 | B3: Trường Sơn TN | C3: =RIGHT(B3,2) -> TN | D3: 5000 | E3: 30000 | H3: =F3+E3+D3 -> 35000 | I3: =ROUNDUP(D3/500,0) -> 10 | J3: =ROUNDUP(E3/500,0) -> 60 | K3: =ROUNDUP(F3/500,0) -> 0 | M3: =K3+J3+I3 -> 70 | N3: 29K-069.35 | O3: Phan Trung Thành | P3: 981636699
A4: 45622 | B4: Mai Long TN | C4: =RIGHT(B4,2) -> TN | D4: 45000 | H4: =F4+E4+D4 -> 45000 | I4: =ROUNDUP(D4/500,0) -> 90 | J4: =ROUNDUP(E4/500,0) -> 0 | K4: =ROUNDUP(F4/500,0) -> 0 | M4: =K4+J4+I4 -> 90
A5: 45622 | B5: Phúc Lộc TN | C5: =RIGHT(B5,2) -> TN | D5: 12500 | F5: 53500 | H5: =F5+E5+D5 -> 66000 | I5: =ROUNDUP(D5/500,0) -> 25 | J5: =ROUNDUP(E5/500,0) -> 0 | K5: =ROUNDUP(F5/500,0) -> 107 | M5: =K5+J5+I5 -> 132
A6: 45622 | B6: Ngọc hùng BK | C6: =RIGHT(B6,2) -> BK | D6: 41500 | H6: =F6+E6+D6 -> 41500 | I6: =ROUNDUP(D6/500,0) -> 83 | J6: =ROUNDUP(E6/500,0) -> 0 | K6: =ROUNDUP(F6/500,0) -> 0 | M6: =K6+J6+I6 -> 83
A7: 45622 | B7: Lê văn Oai CB | C7: =RIGHT(B7,2) -> CB | D7: 2500 | E7: 87500 | H7: =F7+E7+D7 -> 90000 | I7: =ROUNDUP(D7/500,0) -> 5 | J7: =ROUNDUP(E7/500,0) -> 175 | K7: =ROUNDUP(F7/500,0) -> 0 | M7: =K7+J7+I7 -> 180
A8: 45622 | B8: Tổng Hợp CB | C8: =RIGHT(B8,2) -> CB | D8: 5500 | E8: 60000 | H8: =F8+E8+D8 -> 65500 | I8: =ROUNDUP(D8/500,0) -> 11 | J8: =ROUNDUP(E8/500,0) -> 120 | K8: =ROUNDUP(F8/500,0) -> 0 | M8: =K8+J8+I8 -> 131
A9: 45622 | B9: Trung chuyển QO NT | C9: =RIGHT(B9,2) -> NT | D9: 200000 | H9: =F9+E9+D9 -> 200000 | I9: =ROUNDUP(D9/500,0) -> 400 | J9: =ROUNDUP(E9/500,0) -> 0 | K9: =ROUNDUP(F9/500,0) -> 0 | M9: =K9+J9+I9 -> 400 | N9: 29G-023.11 | O9: Nguyễn Văn Anh | P9: 974072826
A10: 45623 | B10: quốc đạt ST | C10: =RIGHT(B10,2) -> ST | E10: 110000 | H10: =F10+E10+D10 -> 110000 | I10: =ROUNDUP(D10/500,0) -> 0 | J10: =ROUNDUP(E10/500,0) -> 220 | K10: =ROUNDUP(F10/500,0) -> 0 | M10: =K10+J10+I10 -> 220 | N10: 29G-023.49 | O10: Nguyễn Trọng Tấn | P10: 967884730
A11: 45623 | B11: Anh tuấn ST | C11: =RIGHT(B11,2) -> ST | D11: 8000 | E11: 137000 | H11: =F11+E11+D11 -> 145000 | I11: =ROUNDUP(D11/500,0) -> 16 | J11: =ROUNDUP(E11/500,0) -> 274 | K11: =ROUNDUP(F11/500,0) -> 0 | M11: =K11+J11+I11 -> 290
A12: 45623 | B12: Nam Sơn ND | C12: =RIGHT(B12,2) -> ND | D12: 28500 | H12: =F12+E12+D12 -> 28500 | I12: =ROUNDUP(D12/500,0) -> 57 | J12: =ROUNDUP(E12/500,0) -> 0 | K12: =ROUNDUP(F12/500,0) -> 0 | M12: =K12+J12+I12 -> 57 | N12: 29B-189.64 | O12: Lê Công Vinh | P12: 949502669
A13: 45623 | B13: Ngọc Phượng ND | C13: =RIGHT(B13,2) -> ND | D13: 19000 | H13: =F13+E13+D13 -> 19000 | I13: =ROUNDUP(D13/500,0) -> 38 | J13: =ROUNDUP(E13/500,0) -> 0 | K13: =ROUNDUP(F13/500,0) -> 0 | M13: =K13+J13+I13 -> 38
A14: 45623 | B14: Gia Phan ND | C14: =RIGHT(B14,2) -> ND | E14: 150000 | H14: =F14+E14+D14 -> 150000 | I14: =ROUNDUP(D14/500,0) -> 0 | J14: =ROUNDUP(E14/500,0) -> 300 | K14: =ROUNDUP(F14/500,0) -> 0 | M14: =K14+J14+I14 -> 300
A15: 45623 | B15: Gia Phan ND | C15: =RIGHT(B15,2) -> ND | E15: =407600-E14 -> 257600 | F15: 52500 | H15: =F15+E15+D15 -> 310100 | I15: =ROUNDUP(D15/500,0) -> 0 | J15: =ROUNDUP(E15/500,0) -> 516 | K15: =ROUNDUP(F15/500,0) -> 105 | M15: =K15+J15+I15 -> 621 | N15: 29K-063.74 | O15: Lê Văn Giang | P15: 961571433
A16: 45623 | B16: Lan Anh BN | C16: =RIGHT(B16,2) -> BN | D16: 6500 | E16: 287000 | H16: =F16+E16+D16 -> 293500 | I16: =ROUNDUP(D16/500,0) -> 13 | J16: =ROUNDUP(E16/500,0) -> 574 | K16: =ROUNDUP(F16/500,0) -> 0 | M16: =K16+J16+I16 -> 587 | N16: 29K-079.24 | O16: Trần Xuân Trường | P16: 974392325
A17: 45623 | B17: Chiến Nga BG | C17: =RIGHT(B17,2) -> BG | D17: 20000 | E17: 67500 | H17: =F17+E17+D17 -> 87500 | I17: =ROUNDUP(D17/500,0) -> 40 | J17: =ROUNDUP(E17/500,0) -> 135 | K17: =ROUNDUP(F17/500,0) -> 0 | M17: =K17+J17+I17 -> 175 | N17: 29G-023.19 | O17: Nguyễn Văn Anh | P17: 974072826
A18: 45623 | B18: Long Hà BG | C18: =RIGHT(B18,2) -> BG | E18: 69000 | H18: =F18+E18+D18 -> 69000 | I18: =ROUNDUP(D18/500,0) -> 0 | J18: =ROUNDUP(E18/500,0) -> 138 | K18: =ROUNDUP(F18/500,0) -> 0 | M18: =K18+J18+I18 -> 138
A19: 45623 | B19: Chiến Nhã BN | C19: =RIGHT(B19,2) -> BN | E19: 52100 | H19: =F19+E19+D19 -> 52100 | I19: =ROUNDUP(D19/500,0) -> 0 | J19: =ROUNDUP(E19/500,0) -> 105 | K19: =ROUNDUP(F19/500,0) -> 0 | M19: =K19+J19+I19 -> 105
A20: 45624 | B20: Khánh hoà HG | C20: =RIGHT(B20,2) -> HG | D20: 54400 | H20: =F20+E20+D20 -> 54400 | I20: =ROUNDUP(D20/500,0) -> 109 | J20: =ROUNDUP(E20/500,0) -> 0 | K20: =ROUNDUP(F20/500,0) -> 0 | M20: =K20+J20+I20 -> 109 | N20: 29K-079.24 | O20: Trần Xuân Trường | P20: 974392325
A21: 45624 | B21: Thái Dương VP | C21: =RIGHT(B21,2) -> VP | E21: 85000 | H21: =F21+E21+D21 -> 85000 | I21: =ROUNDUP(D21/500,0) -> 0 | J21: =ROUNDUP(E21/500,0) -> 170 | K21: =ROUNDUP(F21/500,0) -> 0 | M21: =K21+J21+I21 -> 170
A22: 45624 | B22: Tùng linh TQ | C22: =RIGHT(B22,2) -> TQ | D22: 9800 | E22: 80000 | H22: =F22+E22+D22 -> 89800 | I22: =ROUNDUP(D22/500,0) -> 20 | J22: =ROUNDUP(E22/500,0) -> 160 | K22: =ROUNDUP(F22/500,0) -> 0 | M22: =K22+J22+I22 -> 180
A23: 45624 | B23: Bình Phương QTri | C23: =RIGHT(B23,2) -> ri | D23: 27500 | E23: 73500 | H23: =F23+E23+D23 -> 101000 | I23: =ROUNDUP(D23/500,0) -> 55 | J23: =ROUNDUP(E23/500,0) -> 147 | K23: =ROUNDUP(F23/500,0) -> 0 | M23: =K23+J23+I23 -> 202 | N23: 29G-023.11 | O23: Phạm Văn Hải | P23: 964343887
A24: 45624 | B24: Hoàng Gia Lộc Huế | C24: =RIGHT(B24,2) -> uế | D24: 10000 | E24: 55000 | H24: =F24+E24+D24 -> 65000 | I24: =ROUNDUP(D24/500,0) -> 20 | J24: =ROUNDUP(E24/500,0) -> 110 | K24: =ROUNDUP(F24/500,0) -> 0 | M24: =K24+J24+I24 -> 130
A25: 45624 | B25: hoàng Quân Vinh | C25: =RIGHT(B25,2) -> h | E25: 60300 | H25: =F25+E25+D25 -> 60300 | I25: =ROUNDUP(D25/500,0) -> 0 | J25: =ROUNDUP(E25/500,0) -> 121 | K25: =ROUNDUP(F25/500,0) -> 0 | M25: =K25+J25+I25 -> 121
A26: 45624 | B26: Hưng Thịnh BK | C26: =RIGHT(B26,2) -> BK | E26: 25000 | H26: =F26+E26+D26 -> 25000 | I26: =ROUNDUP(D26/500,0) -> 0 | J26: =ROUNDUP(E26/500,0) -> 50 | K26: =ROUNDUP(F26/500,0) -> 0 | M26: =K26+J26+I26 -> 50 | N26: 29K-069.35 | O26: Phan Trung Thành | P26: 981636699
A27: 45624 | B27: Thanh Tùng TN | C27: =RIGHT(B27,2) -> TN | D27: 4400 | E27: 57500 | H27: =F27+E27+D27 -> 61900 | I27: =ROUNDUP(D27/500,0) -> 9 | J27: =ROUNDUP(E27/500,0) -> 115 | K27: =ROUNDUP(F27/500,0) -> 0 | M27: =K27+J27+I27 -> 124
A28: 45624 | B28: Hồ Cúc CB | C28: =RIGHT(B28,2) -> CB | D28: 8200 | E28: 85500 | H28: =F28+E28+D28 -> 93700 | I28: =ROUNDUP(D28/500,0) -> 17 | J28: =ROUNDUP(E28/500,0) -> 171 | K28: =ROUNDUP(F28/500,0) -> 0 | M28: =K28+J28+I28 -> 188
A29: 45624 | B29: Trường Sơn TN | C29: =RIGHT(B29,2) -> TN | E29: 33100 | F29: =307500 +2000 -> 309500 | H29: =F29+E29+D29 -> 342600 | I29: =ROUNDUP(D29/500,0) -> 0 | J29: =ROUNDUP(E29/500,0) -> 67 | K29: =ROUNDUP(F29/500,0) -> 619 | M29: =K29+J29+I29 -> 686 | N29: 29G-023.25 | O29: Mai Văn Long | P29: 971106882 | Q29: Thương Mại | R29: Long
A30: 45624 | B30: Nguyệt Hằng HP | C30: =RIGHT(B30,2) -> HP | D30: =89100+3000 -> 92100 | H30: =F30+E30+D30 -> 92100 | I30: =ROUNDUP(D30/500,0) -> 185 | J30: =ROUNDUP(E30/500,0) -> 0 | K30: =ROUNDUP(F30/500,0) -> 0 | M30: =K30+J30+I30 -> 185 | N30: 29G-023.49 | O30: Nguyễn Trọng Tấn | P30: 967884730 | Q30: Thương Mại
A31: 45624 | B31: Công Nghệ Phẩm HP | C31: =RIGHT(B31,2) -> HP | D31: 14700 | E31: 185000 | H31: =F31+E31+D31 -> 199700 | I31: =ROUNDUP(D31/500,0) -> 30 | J31: =ROUNDUP(E31/500,0) -> 370 | K31: =ROUNDUP(F31/500,0) -> 0 | M31: =K31+J31+I31 -> 400
A32: 45624 | B32: Cường Trung HD | C32: =RIGHT(B32,2) -> HD | D32: 11400 | E32: 22500 | H32: =F32+E32+D32 -> 33900 | I32: =ROUNDUP(D32/500,0) -> 23 | J32: =ROUNDUP(E32/500,0) -> 45 | K32: =ROUNDUP(F32/500,0) -> 0 | M32: =K32+J32+I32 -> 68
A33: 45624 | B33: Cường Trung HD | C33: =RIGHT(B33,2) -> HD | E33: 160000 | H33: =F33+E33+D33 -> 160000 | I33: =ROUNDUP(D33/500,0) -> 0 | J33: =ROUNDUP(E33/500,0) -> 320 | K33: =ROUNDUP(F33/500,0) -> 0 | M33: =K33+J33+I33 -> 320 | N33: 29K-067.11 | O33: Nguyễn Văn Anh | P33: 974072826
A34: 45625 | B34: Bình An Nhiên NB | C34: =RIGHT(B34,2) -> NB | F34: 150000 | H34: =F34+E34+D34 -> 150000 | I34: =ROUNDUP(D34/500,0) -> 0 | J34: =ROUNDUP(E34/500,0) -> 0 | K34: =ROUNDUP(F34/500,0) -> 300 | M34: =K34+J34+I34 -> 300 | N34: 29G-023.20 | O34: Mai Văn Long | P34: 971106882
A35: 45625 | B35: Bình An Nhiên NB | C35: =RIGHT(B35,2) -> NB | D35: 43500 | H35: =F35+E35+D35 -> 43500 | I35: =ROUNDUP(D35/500,0) -> 87 | J35: =ROUNDUP(E35/500,0) -> 0 | K35: =ROUNDUP(F35/500,0) -> 0 | M35: =K35+J35+I35 -> 87 | N35: 29K-063.74 | O35: Lê Mạnh Cường | P35: 923453896
A36: 45625 | B36: Thạch Thành TH | C36: =RIGHT(B36,2) -> TH | D36: 12000 | E36: 162500 | H36: =F36+E36+D36 -> 174500 | I36: =ROUNDUP(D36/500,0) -> 24 | J36: =ROUNDUP(E36/500,0) -> 325 | K36: =ROUNDUP(F36/500,0) -> 0 | M36: =K36+J36+I36 -> 349
A37: 45626 | B37: Anh Tuấn ST | C37: =RIGHT(B37,2) -> ST | D37: 169500 | H37: =F37+E37+D37 -> 169500 | I37: =ROUNDUP(D37/500,0) -> 339 | J37: =ROUNDUP(E37/500,0) -> 0 | K37: =ROUNDUP(F37/500,0) -> 0 | M37: =K37+J37+I37 -> 339 | N37: 29K-063.74 | O37: Lê Mạnh Cường | P37: 923453896
A38: 45626 | B38: Vạn Niên PT | C38: =RIGHT(B38,2) -> PT | D38: 64500 | H38: =F38+E38+D38 -> 64500 | I38: =ROUNDUP(D38/500,0) -> 129 | J38: =ROUNDUP(E38/500,0) -> 0 | K38: =ROUNDUP(F38/500,0) -> 0 | M38: =K38+J38+I38 -> 129
A39: 45629 | B39: Nguyệt Hằng HP | C39: =RIGHT(B39,2) -> HP | D39: 64100 | H39: =F39+E39+D39 -> 64100 | I39: =ROUNDUP(D39/500,0) -> 129 | J39: =ROUNDUP(E39/500,0) -> 0 | K39: =ROUNDUP(F39/500,0) -> 0 | M39: =K39+J39+I39 -> 129 | N39: 29G-023.11 | O39: Phạm Văn Hải | P39: 964343887
A40: 45629 | B40: Việt Xô HD | C40: =RIGHT(B40,2) -> HD | D40: 92800 | H40: =F40+E40+D40 -> 92800 | I40: =ROUNDUP(D40/500,0) -> 186 | J40: =ROUNDUP(E40/500,0) -> 0 | K40: =ROUNDUP(F40/500,0) -> 0 | M40: =K40+J40+I40 -> 186
...

Sheet TLTL 012025
A1: Ngày | B1: Tên NPP | C1: QO (bao) | D1: NT | E1: BS | F1: TH | G1: Tổng | H1: QO | I1: NT | J1: BS | K1: TH | L1: Tổng | M1: Biển số xe | N1: Lái xe | O1: SĐT
A2: 45652 | B2: Mai Phuong ND | C2: 6800 | D2: 170000 | E2: 50000 | G2: =E2+D2+C2+F2 -> 226800 | H2: =ROUNDUP(C2/500,0) -> 14 | I2: =ROUNDUP(D2/500,0) -> 340 | J2: =ROUNDUP(E2/500,0) -> 100 | K2: =ROUNDUP(F2/500,0) -> 0 | L2: =SUM(H2:K2) -> 454 | M2: 29G-023.11 | N2: Phạm Văn Hải | O2: 964343887
A3: 45652 | B3: Mai Phuong ND | D3: 365000 | G3: =E3+D3+C3+F3 -> 365000 | H3: =ROUNDUP(C3/500,0) -> 0 | I3: =ROUNDUP(D3/500,0) -> 730 | J3: =ROUNDUP(E3/500,0) -> 0 | K3: =ROUNDUP(F3/500,0) -> 0 | L3: =SUM(H3:K3) -> 730 | M3: 29K-139.05 | N3: Nguyễn Trọng Tấn | O3: 967884730
A4: 45652 | B4: Huong Duyen PL | C4: 1400 | D4: 200000 | G4: =E4+D4+C4+F4 -> 201400 | H4: =ROUNDUP(C4/500,0) -> 3 | I4: =ROUNDUP(D4/500,0) -> 400 | J4: =ROUNDUP(E4/500,0) -> 0 | K4: =ROUNDUP(F4/500,0) -> 0 | L4: =SUM(H4:K4) -> 403 | M4: 29G-023.20 | N4: Nguyễn Đức Thiên | O4: 981636699
A5: 45652 | B5: Việt Hoàng Long PL | C5: 2000 | G5: =E5+D5+C5+F5 -> 2000 | H5: =ROUNDUP(C5/500,0) -> 4 | I5: =ROUNDUP(D5/500,0) -> 0 | J5: =ROUNDUP(E5/500,0) -> 0 | K5: =ROUNDUP(F5/500,0) -> 0 | L5: =SUM(H5:K5) -> 4 | M5: 29G-023.20 | N5: Nguyễn Đức Thiên | O5: 981636699
A6: 45652 | B6: Huong Duyen PL | D6: 215000 | G6: =E6+D6+C6+F6 -> 215000 | H6: =ROUNDUP(C6/500,0) -> 0 | I6: =ROUNDUP(D6/500,0) -> 430 | J6: =ROUNDUP(E6/500,0) -> 0 | K6: =ROUNDUP(F6/500,0) -> 0 | L6: =SUM(H6:K6) -> 430 | M6: 29G-023.19 | N6: Lê Mạnh Cường | O6: 923453896
A7: 45652 | B7: Huong Duyen PL | F7: 50000 | G7: =E7+D7+C7+F7 -> 50000 | H7: =ROUNDUP(C7/500,0) -> 0 | I7: =ROUNDUP(D7/500,0) -> 0 | J7: =ROUNDUP(E7/500,0) -> 0 | K7: =ROUNDUP(F7/500,0) -> 100 | L7: =SUM(H7:K7) -> 100 | M7: 29G-023.25 | N7: Mai Văn Long | O7: 971106882 | P7: chưa có biên bản, nhà phân phối kí đủ ở hóa đơn
A8: 45652 | B8: Việt Hoàng Long PL | F8: 25000 | G8: =E8+D8+C8+F8 -> 25000 | H8: =ROUNDUP(C8/500,0) -> 0 | I8: =ROUNDUP(D8/500,0) -> 0 | J8: =ROUNDUP(E8/500,0) -> 0 | K8: =ROUNDUP(F8/500,0) -> 50 | L8: =SUM(H8:K8) -> 50 | M8: 29G-023.25 | N8: Mai Văn Long | O8: 971106882 | P8: chưa có biên bản, nhà phân phối kí đủ ở hóa đơn
A9: 45652 | B9: Bình An Nhiên NB | F9: 40000 | G9: =E9+D9+C9+F9 -> 40000 | H9: =ROUNDUP(C9/500,0) -> 0 | I9: =ROUNDUP(D9/500,0) -> 0 | J9: =ROUNDUP(E9/500,0) -> 0 | K9: =ROUNDUP(F9/500,0) -> 80 | L9: =SUM(H9:K9) -> 80 | M9: 29G-023.25 | N9: Mai Văn Long | O9: 971106882 | P9: chưa có biên bản, nhà phân phối kí đủ ở hóa đơn
A10: 45653 | B10: Công Nghệ Phẩm HP | C10: 131000 | G10: =E10+D10+C10+F10 -> 131000 | H10: =ROUNDUP(C10/500,0) -> 262 | I10: =ROUNDUP(D10/500,0) -> 0 | J10: =ROUNDUP(E10/500,0) -> 0 | K10: =ROUNDUP(F10/500,0) -> 0 | L10: =SUM(H10:K10) -> 262 | M10: 29K-134.59 | N10: Phan Lưu Trường | O10: 326522825
A11: 45653 | B11: Nguyệt Hằng HP | C11: 61600 | G11: =E11+D11+C11+F11 -> 61600 | H11: =ROUNDUP(C11/500,0) -> 124 | I11: =ROUNDUP(D11/500,0) -> 0 | J11: =ROUNDUP(E11/500,0) -> 0 | K11: =ROUNDUP(F11/500,0) -> 0 | L11: =SUM(H11:K11) -> 124 | M11: 29K-134.59 | N11: Phan Lưu Trường | O11: 326522825 | P11: 3k tm
A12: 45653 | B12: Trang Hiển HP | C12: 70100 | G12: =E12+D12+C12+F12 -> 70100 | H12: =ROUNDUP(C12/500,0) -> 141 | I12: =ROUNDUP(D12/500,0) -> 0 | J12: =ROUNDUP(E12/500,0) -> 0 | K12: =ROUNDUP(F12/500,0) -> 0 | L12: =SUM(H12:K12) -> 141 | M12: 29K-134.59 | N12: Phan Lưu Trường | O12: 326522825
A13: 45653 | B13: Sơn Thái HP | D13: 100000 | G13: =E13+D13+C13+F13 -> 100000 | H13: =ROUNDUP(C13/500,0) -> 0 | I13: =ROUNDUP(D13/500,0) -> 200 | J13: =ROUNDUP(E13/500,0) -> 0 | K13: =ROUNDUP(F13/500,0) -> 0 | L13: =SUM(H13:K13) -> 200 | M13: 29K-134.59 | N13: Phan Lưu Trường | O13: 326522825
A14: 45653 | B14: Sơn Thái HP | D14: 80000 | G14: =E14+D14+C14+F14 -> 80000 | H14: =ROUNDUP(C14/500,0) -> 0 | I14: =ROUNDUP(D14/500,0) -> 160 | J14: =ROUNDUP(E14/500,0) -> 0 | K14: =ROUNDUP(F14/500,0) -> 0 | L14: =SUM(H14:K14) -> 160 | M14: 29G-023.19 | N14: Lê Đức Bách | O14: 981636699
A15: 45653 | B15: Cường Trung HD | C15: 4300 | D15: 145000 | G15: =E15+D15+C15+F15 -> 149300 | H15: =ROUNDUP(C15/500,0) -> 9 | I15: =ROUNDUP(D15/500,0) -> 290 | J15: =ROUNDUP(E15/500,0) -> 0 | K15: =ROUNDUP(F15/500,0) -> 0 | L15: =SUM(H15:K15) -> 299 | M15: 29G-023.19 | N15: Lê Đức Bách | O15: 981636699
A16: 45653 | B16: Hưng Thịnh HD | C16: 2500 | D16: 320000 | G16: =E16+D16+C16+F16 -> 322500 | H16: =ROUNDUP(C16/500,0) -> 5 | I16: =ROUNDUP(D16/500,0) -> 640 | J16: =ROUNDUP(E16/500,0) -> 0 | K16: =ROUNDUP(F16/500,0) -> 0 | L16: =SUM(H16:K16) -> 645 | M16: 29K-079.24 | N16: Trần Xuân Trường | O16: 974392325
A17: 45653 | B17: Hoàng Gia Lộc Huế | C17: 105500 | D17: 105500 | G17: =E17+D17+C17+F17 -> 211000 | H17: =ROUNDUP(C17/500,0) -> 211 | I17: =ROUNDUP(D17/500,0) -> 211 | J17: =ROUNDUP(E17/500,0) -> 0 | K17: =ROUNDUP(F17/500,0) -> 0 | L17: =SUM(H17:K17) -> 422 | M17: 29G-023.20 | N17: Nguyễn Đức Thiên | O17: 981636699
A18: 45653 | B18: Trung chuyển QO NT | C18: 300000 | G18: =E18+D18+C18+F18 -> 300000 | H18: =ROUNDUP(C18/500,0) -> 600 | I18: =ROUNDUP(D18/500,0) -> 0 | J18: =ROUNDUP(E18/500,0) -> 0 | K18: =ROUNDUP(F18/500,0) -> 0 | L18: =SUM(H18:K18) -> 600 | M18: 29K-063.74 | N18: Lê Văn Giang | O18: 961571433
A19: 45654 | B19: Trung chuyển QO NT | C19: 300000 | G19: =E19+D19+C19+F19 -> 300000 | H19: =ROUNDUP(C19/500,0) -> 600 | I19: =ROUNDUP(D19/500,0) -> 0 | J19: =ROUNDUP(E19/500,0) -> 0 | K19: =ROUNDUP(F19/500,0) -> 0 | L19: =SUM(H19:K19) -> 600 | M19: 29K-079.24 | N19: Trần Xuân Trường | O19: 974392325
A20: 45654 | B20: Trung chuyển QO NT | C20: 300000 | G20: =E20+D20+C20+F20 -> 300000 | H20: =ROUNDUP(C20/500,0) -> 600 | I20: =ROUNDUP(D20/500,0) -> 0 | J20: =ROUNDUP(E20/500,0) -> 0 | K20: =ROUNDUP(F20/500,0) -> 0 | L20: =SUM(H20:K20) -> 600 | M20: 29K-069.35 | N20: Hoàng Minh Thịnh | O20: 989118712
A21: 45654 | B21: Hai Tuan CP | C21: 50000 | G21: =E21+D21+C21+F21 -> 50000 | H21: =ROUNDUP(C21/500,0) -> 100 | I21: =ROUNDUP(D21/500,0) -> 0 | J21: =ROUNDUP(E21/500,0) -> 0 | K21: =ROUNDUP(F21/500,0) -> 0 | L21: =SUM(H21:K21) -> 100 | M21: 29B-189.64 | N21: Lê Công Vinh | O21: 949502669
A22: 45654 | B22: Toan Huyen HL | C22: 5000 | G22: =E22+D22+C22+F22 -> 5000 | H22: =ROUNDUP(C22/500,0) -> 10 | I22: =ROUNDUP(D22/500,0) -> 0 | J22: =ROUNDUP(E22/500,0) -> 0 | K22: =ROUNDUP(F22/500,0) -> 0 | L22: =SUM(H22:K22) -> 10 | M22: 29B-189.64 | N22: Lê Công Vinh | O22: 949502669
A23: 45654 | B23: Huy Bình HL | C23: 1000 | G23: =E23+D23+C23+F23 -> 1000 | H23: =ROUNDUP(C23/500,0) -> 2 | I23: =ROUNDUP(D23/500,0) -> 0 | J23: =ROUNDUP(E23/500,0) -> 0 | K23: =ROUNDUP(F23/500,0) -> 0 | L23: =SUM(H23:K23) -> 2 | M23: 29B-189.64 | N23: Lê Công Vinh | O23: 949502669
A24: 45654 | B24: Hải Yến HL | C24: 2000 | G24: =E24+D24+C24+F24 -> 2000 | H24: =ROUNDUP(C24/500,0) -> 4 | I24: =ROUNDUP(D24/500,0) -> 0 | J24: =ROUNDUP(E24/500,0) -> 0 | K24: =ROUNDUP(F24/500,0) -> 0 | L24: =SUM(H24:K24) -> 4 | M24: 29B-189.64 | N24: Lê Công Vinh | O24: 949502669
A25: 45654 | B25: Hồng Đức UB | C25: 1000 | G25: =E25+D25+C25+F25 -> 1000 | H25: =ROUNDUP(C25/500,0) -> 2 | I25: =ROUNDUP(D25/500,0) -> 0 | J25: =ROUNDUP(E25/500,0) -> 0 | K25: =ROUNDUP(F25/500,0) -> 0 | L25: =SUM(H25:K25) -> 2 | M25: 29B-189.64 | N25: Lê Công Vinh | O25: 949502669
A26: 45654 | B26: Công Nghệ Phẩm HP | C26: 150000 | G26: =E26+D26+C26+F26 -> 150000 | H26: =ROUNDUP(C26/500,0) -> 300 | I26: =ROUNDUP(D26/500,0) -> 0 | J26: =ROUNDUP(E26/500,0) -> 0 | K26: =ROUNDUP(F26/500,0) -> 0 | L26: =SUM(H26:K26) -> 300 | M26: 29B-189.64 | N26: Lê Công Vinh | O26: 949502669
A27: 45654 | B27: Thành Chung HB | D27: 75000 | G27: =E27+D27+C27+F27 -> 75000 | H27: =ROUNDUP(C27/500,0) -> 0 | I27: =ROUNDUP(D27/500,0) -> 150 | J27: =ROUNDUP(E27/500,0) -> 0 | K27: =ROUNDUP(F27/500,0) -> 0 | L27: =SUM(H27:K27) -> 150 | M27: 29G-023.25 | N27: Mai Văn Long | O27: 971106882
A28: 45654 | B28: Bình An Nhiên NB | D28: 112500 | G28: =E28+D28+C28+F28 -> 112500 | H28: =ROUNDUP(C28/500,0) -> 0 | I28: =ROUNDUP(D28/500,0) -> 225 | J28: =ROUNDUP(E28/500,0) -> 0 | K28: =ROUNDUP(F28/500,0) -> 0 | L28: =SUM(H28:K28) -> 225 | M28: 29G-023.25 | N28: Mai Văn Long | O28: 971106882
A29: 45654 | B29: Thạch Thành TH | D29: 75000 | G29: =E29+D29+C29+F29 -> 75000 | H29: =ROUNDUP(C29/500,0) -> 0 | I29: =ROUNDUP(D29/500,0) -> 150 | J29: =ROUNDUP(E29/500,0) -> 0 | K29: =ROUNDUP(F29/500,0) -> 0 | L29: =SUM(H29:K29) -> 150 | M29: 29G-023.25 | N29: Mai Văn Long | O29: 971106882
A30: 45655 | B30: Trung chuyển QO NT | C30: 300000 | G30: 300000 | H30: =ROUNDUP(C30/500,0) -> 600 | I30: =ROUNDUP(D30/500,0) -> 0 | J30: 0 | K30: =ROUNDUP(F30/500,0) -> 0 | L30: =SUM(H30:K30) -> 600 | M30: 29K-137.54 | N30: Phạm Văn Hải | O30: 964343887
A31: 45655 | B31: Trung chuyển QO NT | C31: 300000 | G31: =E31+D31+C31+F31 -> 300000 | H31: =ROUNDUP(C31/500,0) -> 600 | I31: =ROUNDUP(D31/500,0) -> 0 | J31: =ROUNDUP(E31/500,0) -> 0 | K31: =ROUNDUP(F31/500,0) -> 0 | L31: =SUM(H31:K31) -> 600 | M31: 29K-134.59 | N31: Phan Lưu Trường | O31: 326522825
A32: 45658 | B32: Trung chuyển QO NT | C32: 300000 | G32: =E32+D32+C32+F32 -> 300000 | H32: =ROUNDUP(C32/500,0) -> 600 | I32: =ROUNDUP(D32/500,0) -> 0 | J32: =ROUNDUP(E32/500,0) -> 0 | K32: =ROUNDUP(F32/500,0) -> 0 | L32: =SUM(H32:K32) -> 600 | M32: 29K-134.59 | N32: Phan Lưu Trường | O32: 326522825
A33: 45658 | B33: Trung chuyển QO NT | C33: 300000 | G33: =E33+D33+C33+F33 -> 300000 | H33: =ROUNDUP(C33/500,0) -> 600 | I33: =ROUNDUP(D33/500,0) -> 0 | J33: =ROUNDUP(E33/500,0) -> 0 | K33: =ROUNDUP(F33/500,0) -> 0 | L33: =SUM(H33:K33) -> 600 | M33: 29G-023.49 | N33: Hoàng Minh Thịnh | O33: 989118712
A34: 45658 | B34: Trung chuyển QO NT | C34: 300000 | G34: =E34+D34+C34+F34 -> 300000 | H34: =ROUNDUP(C34/500,0) -> 600 | I34: =ROUNDUP(D34/500,0) -> 0 | J34: =ROUNDUP(E34/500,0) -> 0 | K34: =ROUNDUP(F34/500,0) -> 0 | L34: =SUM(H34:K34) -> 600 | M34: 29K-079.24 | N34: Trần Xuân Trường | O34: 974392325
A35: 45659 | B35: Trung chuyển BS QO | E35: 163000 | G35: =E35+D35+C35+F35 -> 163000 | H35: =ROUNDUP(C35/500,0) -> 0 | I35: =ROUNDUP(D35/500,0) -> 0 | J35: =ROUNDUP(E35/500,0) -> 326 | K35: =ROUNDUP(F35/500,0) -> 0 | L35: =SUM(H35:K35) -> 326 | M35: 29K-067.11 | N35: Lê Công Vinh | O35: 949502669
A36: 45659 | B36: Hòa Hương HP | C36: 68700 | G36: =E36+D36+C36+F36 -> 68700 | H36: =ROUNDUP(C36/500,0) -> 138 | I36: =ROUNDUP(D36/500,0) -> 0 | J36: =ROUNDUP(E36/500,0) -> 0 | K36: =ROUNDUP(F36/500,0) -> 0 | L36: =SUM(H36:K36) -> 138 | M36: 29K-069.35 | N36: Lê Mạnh Cường | O36: 923453896
A37: 45659 | B37: Nguyệt Hằng | C37: 88600 | G37: =E37+D37+C37+F37 -> 88600 | H37: =ROUNDUP(C37/500,0) -> 178 | I37: =ROUNDUP(D37/500,0) -> 0 | J37: =ROUNDUP(E37/500,0) -> 0 | K37: =ROUNDUP(F37/500,0) -> 0 | L37: =SUM(H37:K37) -> 178 | M37: 29K-069.35 | N37: Lê Mạnh Cường | O37: 923453896
A38: 45659 | B38: Công Nghệ Phẩm HP | C38: 15090 | D38: 155400 | G38: =E38+D38+C38+F38 -> 170490 | H38: =ROUNDUP(C38/500,0) -> 31 | I38: =ROUNDUP(D38/500,0) -> 311 | J38: =ROUNDUP(E38/500,0) -> 0 | K38: =ROUNDUP(F38/500,0) -> 0 | L38: =SUM(H38:K38) -> 342 | M38: 29K-069.35 | N38: Lê Mạnh Cường | O38: 923453896
A39: 45659 | B39: Việt Xô HD | C39: 10500 | G39: =E39+D39+C39+F39 -> 10500 | H39: =ROUNDUP(C39/500,0) -> 21 | I39: =ROUNDUP(D39/500,0) -> 0 | J39: =ROUNDUP(E39/500,0) -> 0 | K39: =ROUNDUP(F39/500,0) -> 0 | L39: =SUM(H39:K39) -> 21 | M39: 29K-069.35 | N39: Lê Mạnh Cường | O39: 923453896
A40: 45659 | B40: Trung chuyển QO NT | C40: 300000 | G40: =E40+D40+C40+F40 -> 300000 | H40: =ROUNDUP(C40/500,0) -> 600 | I40: =ROUNDUP(D40/500,0) -> 0 | J40: =ROUNDUP(E40/500,0) -> 0 | K40: =ROUNDUP(F40/500,0) -> 0 | L40: =SUM(H40:K40) -> 600 | M40: 29G-023.25 | N40: Mai Văn Long | O40: 971106882
...

Sheet mẫu gửi TLTL
A2: Công ty X.E Việt Nam kính báo: Ngày 21/10/2024 Lái xe : Phạm Văn Hải Bks : 29G-023.11 Sđt : 0964343887 Sẽ vận chuyển đơn hàng 221 thùng lấy tại NT, QO như sau ạ : | B2: Công ty X.E Việt Nam kính báo: Ngày 4/11/2024 Lái xe : Lê Công Vinh Bks : 29B-189.64 Sđt : 0949502669 Sẽ vận chuyển đơn hàng 430 thùng lấy tại NT như sau ạ : | C2: Kính gửi P. AN-BV Công ty X.E Việt Nam kính báo: Hiện tại X.E Việt Nam có 2 xe biển kiểm soát 29K-069.35 và 29G-023.25 chở hàng trung chuyển từ Quốc Oai về Nguyễn Trãi nhưng chưa được hạ hàng. Công ty vận tải X.E xin đăng ký gửi tại 235 Nguyễn Trãi Nguyễn Trãi từ 18h ngày 16/11 đến sáng ngày 18/11 để trả hàng. Trân trọng cảm ơn!
A3: Công ty X.E Việt Nam kính báo: Ngày 22/10/2024 Lái xe : Phan Trung Thành Bks : 29K-069.35 Sđt : 0981636699 Sẽ vận chuyển đơn hàng 417 thùng lấy tại NT, QO như sau ạ : | B3: Công ty X.E Việt Nam kính báo: Ngày 22/10/2024 Lái xe : Nguyễn Trọng Tấn Bks : 29G-023.19 Sđt : 0967884730 Sẽ vận chuyển đơn hàng 401 thùng lấy tại NT, QO như sau ạ :
A4: Công ty X.E Việt Nam kính báo: Ngày 22/10/2024 Lái xe : Mai Văn Long Bks : 29G-023.25 Sđt : 0971106882 Sẽ vận chuyển đơn hàng 417 thùng lấy tại NT, QO như sau ạ : | B4: Công ty X.E Việt Nam kính báo: Ngày 22/10/2024 Lái xe : Phan Lưu Trường Bks : 29K-067.11 Sđt : 0326522825 Sẽ vận chuyển đơn hàng 401 thùng lấy tại NT, QO như sau ạ : | C4: THÔNG TIN XE CHẠY ANVIET NGÀY 12/12/2024 1. Xe chạy nội kho KCN VISIP Bắc Ninh Tên tài xế: Mai Văn Long Biển số xe: 29G-023.25 Số điện thoại: 0971106882 Đăng kiểm: https://drive.google.com/drive/folders/1l0um_okaiNkRH7fwiDjUv3rOIv9iXsoA?hl=vi 2. Xe chạy Thường Tín về Long Biên Tên tài xế: Nguyễn Văn Sang Biển số xe: 29K-068.20 Số điện thoại: 0969820625 Đăng kiểm: https://drive.google.com/drive/folders/1_wIpkUtAZXO0RzUVhFZGmXepKMj-M8bN?hl=vi
A5: Công ty X.E Việt Nam kính báo: Ngày 11/10/2024 Lái xe : Lê Văn Giang Bks : 29K-063.74 Sđt : 0961571433 Sẽ vận chuyển đơn hàng lấy 500 thùng tại NT , QO như sau ạ : | B5: Công ty X.E Việt Nam kính báo: Ngày 21/10/2024 Lái xe : Trần Xuân Trường Bks : 29K-079.24 Sđt : 0974392325 Sẽ vận chuyển đơn hàng 552 thùng lấy tại NT, QO như sau ạ :
A6: Công ty X.E Việt Nam kính báo: Ngày 07/11/2024 Lái xe : Lê Mạnh Cường Bks : 29G-023.20 Sđt : 0923453896 Sẽ vận chuyển đơn hàng 424 thùng lấy tại NT, QO như sau ạ : | B6: Công ty X.E Việt Nam kính báo: Ngày 04/11/2024 Lái xe : Nguyễn Văn Anh Bks : 29K-068.24 Sđt : 0974072826 Sẽ vận chuyển đơn hàng 424 thùng lấy tại NT, QO như sau ạ :
A7: Công ty X.E Việt Nam kính báo: Ngày 07/11/2024 Lái xe : Nguyễn Văn Sang Bks : 29K-068.20 Sđt : 0969820625 Sẽ vận chuyển đơn hàng 424 thùng lấy tại NT, QO như sau ạ : | B7: Công ty X.E Việt Nam kính báo: Ngày 09/12/2024 Lái xe : Hoàng Minh Thịnh Bks : 29G-023.49 Sđt : 0989118712 Sẽ vận chuyển đơn hàng 672 thùng lấy tại NT, QO như sau ạ:
A8: Công ty X.E Việt Nam kính báo: Ngày 07/11/2024 Lái xe : Nguyễn Xuân Nam Bks : 29G-023.49 Sđt : 0776874999 Sẽ vận chuyển đơn hàng 424 thùng lấy tại NT, QO như sau ạ : | B8: Công ty X.E Việt Nam kính báo: Ngày 27/12/2024 Lái xe : Lê Đức Bách Bks : 29G-023.20 Sđt : 0989852112 Sẽ vận chuyển đơn hàng 424 thùng lấy tại NT, QO như sau ạ :
A9: Công ty X.E Việt Nam kính báo: Ngày 26/12/2024 Lái xe: Nguyễn Đức Thiên Bks : 29G-023.20 Sđt : 0974172336 Sẽ vận chuyển đơn hàng 403 thùng lấy tại NT QO như sau ạ :

Sheet PS
A1: Dự án | B1: Ngày | C1: Thời gian bốc | D1: Điểm lấy hàng | E1: Điểm trả hàng | F1: BSX | G1: Lái xe | H1: SĐT | I1: Giá cước (VNĐ) | J1: Ghi chú
A2: Hưng Toàn Phát | B2: 45574 | C2: 0.625 | D2: VP TC Phạm Tu | E2: Vinh, Nghệ An | F2: 29G-023.25 | G2: Trần Xuân Trường | H2: 0974392325 | I2: 6000000
A3: TN BIKE | B3: 45574 | C3: 0.58333333 | D3: NM Thống Nhất: Cụm Công nghiệp vừa và nhỏ Từ Liêm, Lô A2CN3, Bắc Từ Liêm, Hà Nội | E3: Đường số 10, KCN Hòa Khánh, Phường Hòa Khánh Bắc, Quận Liên Chiểu, Thành phố Đà Nẵng, Việt Nam | F3: 29B-189.64 | G3: Mai Văn Long | H3: 0971106882 | I3: 14000000 | J3: PS 1tr bốc hàng ở ĐN
A4: ICCI-Hoá chất | B4: 45576 | C4: 9h-9h30 | D4: Quế Võ, Bắc Ninh | E4: Quảng Xương, Thanh Hoá | F4: 29G-023.30 | I4: 1000000 | J4: Ghép với xe MH
A5: Hưng Toàn Phát | B5: 11.10.24 | C5: 16h - 17h | D5: Nghi Long, Nghi Lộc, Nghệ An | F5: 29B-189.64 | G5: Mai Văn Long | H5: 0971106882 | I5: 1200000 | J5: Chưa biết giá, ps 120k thuê áo phản quang, dụng cụ chèn lốp
A6: Hưng Toàn Phát | B6: 45579 | C6: 13-14h | D6: Hà Đông | E6: Hồng Lĩnh + TP Hà Tĩnh | F6: 29G-023.49 | G6: Lê Văn Giang | H6: 0961571433 | I6: 6700000 | J6: Chưa biết giá chính xác
A7: Công ty | B7: 45582 | C7: 15h | D7: Mỹ Đình | E7: Phú Thọ | F7: 29H-464.01 | G7: Đầu Xuân Thành | H7: 0912283331 | J7: Hàng từ thiện
A8: VIGO-Tạp Hoá | B8: 45582 | C8: 8h | D8: Mega Thăng Long: 236 Đ. Phạm Văn Đồng, Cổ Nhuế, Bắc Từ Liêm, Hà Nội | E8: Cty TNHH Bảo Đức KM 16 QL 32 thị trấn Trạm Trôi, Hoài Đức, Hà Nội | F8: 29K-067.25 | G8: Khổng Quốc Hải | H8: 0912385576 | I8: 1000000
A9: Hưng Toàn Phát | B9: 45582 | C9: 13h | D9: 928 Bạch Đằng + Phạm Tu Hà Nội | E9: Hà Tĩnh | F9: 29G-023.49 | G9: Lê Văn Giang | H9: 0961571433 | I9: 7000000 | J9: Giá chưa chuẩn
A10: ICCI-Hoá chất | B10: 45584 | C10: 14h | D10: Quế Võ, Bắc Ninh | E10: 2 bồn gầm cầu Thăng Long HN + 3 bồn Sân bay Quảng Trị + 7 bồn đường Tránh Hồng Lĩnh, Hà Tĩnh | F10: 36H-007.91 | G10: Ma Văn Vinh | H10: 0985580241 | I10: 12500000 | J10: xe anh Long chạy
A11: VIGO-Tạp Hoá | B11: 45587 | C11: 9h30 | D11: 14 chương dương quận Hoàn Kiếm, HN | E11: Tổ 5 Phường Hữu Nghị, Thành Phố Hòa Bình, Tỉnh Hòa Bình | F11: 29K-067.25 | G11: Khổng Quốc Hải | H11: 0912385576 | I11: 1500000 | J11: 1350k tiền xe 150k tiền bốc hàng của lái xe
A12: VIGO-Tạp Hoá | B12: 45589 | C12: 8h | D12: Chị Minh : 0969805135. Đường 10, Đông hạ, Ninh Phúc, TP. Ninh Bình | E12: Tổ 5 Phường Hữu Nghị, Thành Phố Hòa Bình, Tỉnh Hòa Bình | F12: 29H-743.40 | G12: Nguyễn Xuân Thế | H12: 387151811 | I12: 1660000 | J12: 1tr6 cước và 60k công bốc
A13: Hưng Toàn Phát | B13: 45588 | C13: 10H | D13: Ngõ 118 đường Nguyễn Khánh Toàn + B2, TT9 khu đô thị mới Xuân Phương, Nam Từ Liêm, Hà Nội | E13: Số 6 ngõ 27 Chùa Thông, Sơn Lộc, thị xã Sơn Tây, Hà Nội | F13: 29G-023.14 | G13: Trần Văn Sơn | H13: 0966120021 | I13: 1080000
A14: ICCI-Hoá chất | B14: 45596 | C14: 9h | D14: Quế Võ, Bắc Ninh | E14: IC9 Phú Thọ | F14: 29K-067.11 | G14: Phạm Văn Hải | H14: 0964343887 | I14: 2500000
A15: AEON Sếp Nam | B15: 45597 | C15: 15h | D15: TP HCM | E15: Hà Nội | F15: 29K-079.24 | G15: Trần Xuân Trường | H15: 0974392325 | I15: 13500000 | J15: Chưa xuất hoá đơn, chưa nhận đc tiền
A16: AEON Sếp Nam | B16: 45597 | C16: 15h | D16: TP HCM | E16: Hà Nội | F16: 29K-063.74 | G16: Lê Văn Giang | H16: 0961571433 | I16: 13500000
A17: AEON Sếp Nam | B17: 45597 | C17: 15h | D17: TP HCM | E17: Hà Nội | F17: 29K-09.35 | G17: Nguyễn Thành Hưng | H17: 0915008283 | I17: 13500000
A18: VIGO-Tạp Hoá | B18: 45601 | C18: 9h | D18: 14 chương dương quận Hoàn Kiếm, HN - Đăng Lê 0963839484 | E18: Tổ 5 Phường Hữu Nghị, Thành Phố Hòa Bình, Tỉnh Hòa Bình | F18: 29K-067.25 | G18: Lê Công Vinh | H18: 0949502669 | I18: 1350000 | J18: 1tr350 cước hàng + 150k công bốc
A19: ICCI-Hoá chất | B19: 45607 | C19: 15h | D19: Nghệ An | E19: Quế Võ, Bắc Ninh | F19: 29G-023.49 | G19: Lê Văn Giang | H19: 0961571433 | I19: 2000000 | J19: Chưa chốt giá 10 vỏ bồn
