Workbook

Sheet Dữ liệu ứng lương T05.26
A1: Mã NV | B1: Số tiền ứng T05.26
A2: XE00499 | B2: 3000000 | C2: =+SUMIFS('Kế toán'!$F$2:$F$212,'Kế toán'!$J$2:$J$212,'Dữ liệu ứng lương T05.26'!A2) -> 3000000 | D2: =+B2-C2 -> 0
A3: XE00843 | B3: 3000000 | C3: =+SUMIFS('Kế toán'!$F$2:$F$212,'Kế toán'!$J$2:$J$212,'Dữ liệu ứng lương T05.26'!A3) -> 3000000 | D3: =+B3-C3 -> 0
A4: XE00844 | B4: 3000000 | C4: =+SUMIFS('Kế toán'!$F$2:$F$212,'Kế toán'!$J$2:$J$212,'Dữ liệu ứng lương T05.26'!A4) -> 3000000 | D4: =+B4-C4 -> 0
A5: XE00853 | B5: 6000000 | C5: =+SUMIFS('Kế toán'!$F$2:$F$212,'Kế toán'!$J$2:$J$212,'Dữ liệu ứng lương T05.26'!A5) -> 6000000 | D5: =+B5-C5 -> 0
A6: XE00854 | B6: 6000000 | C6: =+SUMIFS('Kế toán'!$F$2:$F$212,'Kế toán'!$J$2:$J$212,'Dữ liệu ứng lương T05.26'!A6) -> 6000000 | D6: =+B6-C6 -> 0
A7: XE00855 | B7: 3000000 | C7: =+SUMIFS('Kế toán'!$F$2:$F$212,'Kế toán'!$J$2:$J$212,'Dữ liệu ứng lương T05.26'!A7) -> 3000000 | D7: =+B7-C7 -> 0
A8: XE00858 | B8: 6000000 | C8: =+SUMIFS('Kế toán'!$F$2:$F$212,'Kế toán'!$J$2:$J$212,'Dữ liệu ứng lương T05.26'!A8) -> 6000000 | D8: =+B8-C8 -> 0
A9: XE00865 | B9: 6000000 | C9: =+SUMIFS('Kế toán'!$F$2:$F$212,'Kế toán'!$J$2:$J$212,'Dữ liệu ứng lương T05.26'!A9) -> 6000000 | D9: =+B9-C9 -> 0
A10: XE00873 | B10: 3000000 | C10: =+SUMIFS('Kế toán'!$F$2:$F$212,'Kế toán'!$J$2:$J$212,'Dữ liệu ứng lương T05.26'!A10) -> 3000000 | D10: =+B10-C10 -> 0
A11: XE00893 | B11: 6000000 | C11: =+SUMIFS('Kế toán'!$F$2:$F$212,'Kế toán'!$J$2:$J$212,'Dữ liệu ứng lương T05.26'!A11) -> 6000000 | D11: =+B11-C11 -> 0
A12: XE00894 | B12: 3000000 | C12: =+SUMIFS('Kế toán'!$F$2:$F$212,'Kế toán'!$J$2:$J$212,'Dữ liệu ứng lương T05.26'!A12) -> 3000000 | D12: =+B12-C12 -> 0
A13: XE00907 | B13: 6000000 | C13: =+SUMIFS('Kế toán'!$F$2:$F$212,'Kế toán'!$J$2:$J$212,'Dữ liệu ứng lương T05.26'!A13) -> 6000000 | D13: =+B13-C13 -> 0
... A85: XE01709 | B85: 3000000 | C85: =+SUMIFS('Kế toán'!$F$2:$F$212,'Kế toán'!$J$2:$J$212,'Dữ liệu ứng lương T05.26'!A85) -> 3000000 | D85: =+B85-C85 -> 0
A86: Cộng | B86: =SUM(B2:B85) -> 375000000

Sheet Kế toán
A1: Ngày hạch toán | B1: Ngày chứng từ | C1: Số chứng từ | D1: Diễn giải | E1: TK đối ứng | F1: Nợ | G1: Có | H1: Nợ | I1: Có | J1: Mã đối tượng
A2: 46150 | B2: 46150 | C2: KTHN2787 | D2: Tạm ứng chi phí đi đường cho lái xe ngày 08/05/26 - Bùi Duy Hiếu 29E38126 | E2: 1411 | F2: 1500000 | G2: 0 | H2: 0 | I2: 22728167 | J2: XE01563
A3: 46153 | B3: 46153 | C3: KTHN2784 | D3: Tạm ứng chi phí đi đường cho lái xe ngày 11/05/26 - Bùi Ngọc Ninh 29E12401 | E3: 1411 | F3: 1500000 | G3: 0 | H3: 0 | I3: 7808670 | J3: XE01670
A4: 46144 | B4: 46144 | C4: KTHN2793 | D4: Tạm ứng chi phí đi đường cho lái xe ngày 02/05/26 - Bùi Văn Đào 29E08175 | E4: 1411 | F4: 1500000 | G4: 0 | H4: 0 | I4: 29356164 | J4: XE01331
A5: 46154 | B5: 46154 | C5: KTHN2993 | D5: Tạm ứng chi phí đi đường cho lái xe ngày 12/05/26 - GH-1134 Bùi Văn Đào 29E08175 | E5: 1411 | F5: 1500000 | G5: 0 | H5: 0 | I5: 27856164 | J5: XE01331
A6: 46160 | B6: 46160 | C6: KTHN2982 | D6: Tạm ứng chi phí đi đường cho lái xe ngày 18/05/26 - DA-1284 Bùi Văn Đào 29E08175 | E6: 1411 | F6: 1500000 | G6: 0 | H6: 0 | I6: 12423435 | J6: XE01331
A7: 46153 | B7: 46153 | C7: KTHN2784 | D7: Tạm ứng chi phí đi đường cho lái xe ngày 11/05/26 - Cao Hoài Tiên 29E12401 | E7: 1411 | F7: 1500000 | G7: 0 | H7: 0 | I7: 22132869 | J7: XE01477
A8: 46151 | B8: 46151 | C8: KTHN2786 | D8: Tạm ứng chi phí đi đường cho lái xe ngày 09/05/26 - Cao Phong Anh 29E38159 | E8: 1411 | F8: 1500000 | G8: 0 | H8: 0 | I8: 16680557 | J8: XE01591
A9: 46151 | B9: 46151 | C9: KTHN2786 | D9: Tạm ứng chi phí đi đường cho lái xe ngày 09/05/26 - Cao Tuấn Anh 29E38159 | E9: 1411 | F9: 1500000 | G9: 0 | H9: 0 | I9: 18280900 | J9: XE01590
A10: 46157 | B10: 46157 | C10: KTHN2979 | D10: Tạm ứng chi phí đi đường cho lái xe ngày 15/05/26 - DA-1266 Cao Tuấn Anh 29E38159 | E10: 1411 | F10: 1500000 | G10: 0 | H10: 0 | I10: 10174119 | J10: XE01590
A11: 46167 | B11: 46167 | C11: KTHN2997 | D11: Tạm ứng chi phí đi đường cho lái xe ngày 21/05/26 DA 1306 Cao Tuấn Anh 29E38159 | E11: 1411 | F11: 1500000 | G11: 0 | H11: 0 | I11: 8674119 | J11: XE01590
A12: 46149 | B12: 46149 | C12: KTHN2788 | D12: Tạm ứng chi phí đi đường cho lái xe ngày 07/05/26 - Đặng Công Đức 29E44377 | E12: 1411 | F12: 1500000 | G12: 0 | H12: 0 | I12: 28386738 | J12: XE01417
A13: 46155 | B13: 46155 | C13: KTHN2782 | D13: Tạm ứng chi phí đi đường cho lái xe ngày 13/05/26 - Đặng Công Đức 29E44377 | E13: 1411 | F13: 1500000 | G13: 0 | H13: 0 | I13: 26886738 | J13: XE01417
... A212: 46164 | B212: 46164 | C212: KTHN2986 | D212: Tạm ứng chi phí đi đường cho lái xe ngày 22/05/26 - DA-1314 Vũ Văn Tỉnh 29E35397 | E212: 1411 | F212: 3000000 | G212: 0 | H212: 0 | I212: 21324499 | J212: XE01021

Sheet Sheet4
A3: Row Labels | B3: Sum of Số tiền TT | D3: mã nv | E3: số tiền ứng hh | F3: số kế toán | G3: cl
A4: XE00499 | B4: 3000000 | D4: XE00499 | E4: 3000000 | F4: =+SUMIFS('Kế toán'!$F$2:$F$212,'Kế toán'!$J$2:$J$212,Sheet4!D4) -> 3000000 | G4: =+E4-F4 -> 0
A5: XE00843 | B5: 3000000 | D5: XE00843 | E5: 3000000 | F5: =+SUMIFS('Kế toán'!$F$2:$F$212,'Kế toán'!$J$2:$J$212,Sheet4!D5) -> 3000000 | G5: =+E5-F5 -> 0
A6: XE00844 | B6: 3000000 | D6: XE00844 | E6: 3000000 | F6: =+SUMIFS('Kế toán'!$F$2:$F$212,'Kế toán'!$J$2:$J$212,Sheet4!D6) -> 3000000 | G6: =+E6-F6 -> 0
A7: XE00853 | B7: 6000000 | D7: XE00853 | E7: 6000000 | F7: =+SUMIFS('Kế toán'!$F$2:$F$212,'Kế toán'!$J$2:$J$212,Sheet4!D7) -> 6000000 | G7: =+E7-F7 -> 0
A8: XE00854 | B8: 6000000 | D8: XE00854 | E8: 6000000 | F8: =+SUMIFS('Kế toán'!$F$2:$F$212,'Kế toán'!$J$2:$J$212,Sheet4!D8) -> 6000000 | G8: =+E8-F8 -> 0
A9: XE00855 | B9: 3000000 | D9: XE00855 | E9: 3000000 | F9: =+SUMIFS('Kế toán'!$F$2:$F$212,'Kế toán'!$J$2:$J$212,Sheet4!D9) -> 3000000 | G9: =+E9-F9 -> 0
A10: XE00858 | B10: 6000000 | D10: XE00858 | E10: 6000000 | F10: =+SUMIFS('Kế toán'!$F$2:$F$212,'Kế toán'!$J$2:$J$212,Sheet4!D10) -> 6000000 | G10: =+E10-F10 -> 0
A11: XE00865 | B11: 6000000 | D11: XE00865 | E11: 6000000 | F11: =+SUMIFS('Kế toán'!$F$2:$F$212,'Kế toán'!$J$2:$J$212,Sheet4!D11) -> 6000000 | G11: =+E11-F11 -> 0
A12: XE00873 | B12: 3000000 | D12: XE00873 | E12: 3000000 | F12: =+SUMIFS('Kế toán'!$F$2:$F$212,'Kế toán'!$J$2:$J$212,Sheet4!D12) -> 3000000 | G12: =+E12-F12 -> 0
A13: XE00893 | B13: 6000000 | D13: XE00893 | E13: 6000000 | F13: =+SUMIFS('Kế toán'!$F$2:$F$212,'Kế toán'!$J$2:$J$212,Sheet4!D13) -> 6000000 | G13: =+E13-F13 -> 0
A14: XE00894 | B14: 3000000 | D14: XE00894 | E14: 3000000 | F14: =+SUMIFS('Kế toán'!$F$2:$F$212,'Kế toán'!$J$2:$J$212,Sheet4!D14) -> 3000000 | G14: =+E14-F14 -> 0
A15: XE00907 | B15: 6000000 | D15: XE00907 | E15: 6000000 | F15: =+SUMIFS('Kế toán'!$F$2:$F$212,'Kế toán'!$J$2:$J$212,Sheet4!D15) -> 6000000 | G15: =+E15-F15 -> 0
... A87: XE01709 | B87: 3000000 | D87: XE01709 | E87: 3000000 | F87: =+SUMIFS('Kế toán'!$F$2:$F$212,'Kế toán'!$J$2:$J$212,Sheet4!D87) -> 3000000 | G87: =+E87-F87 -> 0
A88: (blank) | E88: =SUM(E4:E87) -> 375000000 | F88: =SUM(F4:F87) -> 375000000 | G88: =SUM(G4:G87) -> 0
A89: Grand Total | B89: 375000000

Sheet phòng hàng
A1: ĐNTT | B1: Ngày | C1: Tuyến vận chuyển | D1: BKS | E1: Họ tên | F1: MNV | G1: Số TK | H1: Ngân hàng | I1: Số tiền TT
A2: 01-05-TU | B2: 46143 | C2: Hưng Yên- Bình Định- Nha Trang | D2: 29E09603 | E2: Trương Cẩm Thành | F2: XE01390 | G2: 23956793979 | H2: MB | I2: 1500000
A3: 01-05-TU | B3: 46143 | C3: Hưng Yên- Bình Định- Nha Trang | D3: 29E09603 | E3: Trần Phong Vũ
A4: 01-05-TU | B4: 46143 | C4: Hà Nội( Long Biên)- Cần Thơ | D4: 29K13459 | E4: Hoàng Văn Lợi | F4: XE01456 | G4: 04610000498774 | H4: Vietcombank | I4: 1500000
A5: 01-05-TU | B5: 46143 | C5: Hà Nội( Long Biên)- Cần Thơ | D5: 29K13459 | E5: Nguyễn Minh Trọng | F5: XE01599 | G5: 4118927 | H5: ACB | I5: 1500000
A6: 01-05-TU | B6: 46143 | C6: Ninh Bình- Đồng Nai | D6: 29E12073 | E6: Trần Xuân Trường | F6: XE00499 | G6: 0061001129391 | H6: Vietcombank | I6: 1500000
A7: 01-05-TU | B7: 46143 | C7: Ninh Bình- Đồng Nai | D7: 29E12073 | E7: Phan Văn Thành | F7: XE00934 | G7: 51010000845882 | H7: BIDV | I7: 1500000
A8: 32BS-05-TU | B8: 46143 | C8: Ninh Bình- Đak Lak | D8: 29E08426 | E8: Trần Hữu Khánh | F8: XE01470 | G8: 9804092001 | H8: MB Bank | I8: 1500000
A9: 32BS-05-TU | B9: 46143 | C9: Ninh Bình- Đak Lak | D9: 29E08426 | E9: Nguyễn Bá Bảo | F9: XE01469 | G9: 1038672108 | H9: Ngân hàng VCB | I9: 1500000
A10: 02-05-TU | B10: 46144 | C10: Hưng Yên- HCM | D10: 29E08175 | E10: Bùi Văn Đào | F10: XE01331 | G10: 1012732996 | H10: Vietcombank | I10: 1500000
A11: 02-05-TU | B11: 46144 | C11: Hưng Yên- HCM | D11: 29E08175 | E11: Nguyễn Doãn Quang | F11: XE01645 | G11: 3615205296080 | H11: Agribank | I11: 1500000
A12: 02-05-TU | B12: 46144 | C12: Hà Nội( Long Biên)- Cần Thơ | D12: 29K13905 | E12: Nguyễn Quốc Bình | F12: XE01005 | G12: 0385993666 | H12: Viettinbank | I12: 1500000
A13: 02-05-TU | B13: 46144 | C13: Hà Nội( Long Biên)- Cần Thơ | D13: 29K13905 | E13: Trịnh Văn Lực | F13: XE01164 | G13: 102871393941 | H13: Vietinbank | I13: 1500000
A14: 02-05-TU | B14: 46144 | C14: Thanh Hóa- HCM | D14: 29E44326 | E14: Tạ Quốc Vương | F14: XE01098 | G14: 1130109121983 | H14: MB Bank | I14: 1500000
A15: 02-05-TU | B15: 46144 | C15: Thanh Hóa- HCM | D15: 29E44326 | E15: Nguyễn Đức Toàn | F15: XE01600 | G15: 109873271749 | H15: Vietinbank | I15: 1500000
A16: 03-05-TU | B16: 46145 | C16: Thanh Hóa- HCM | D16: 29E12747 | E16: Phạm Thanh Tuấn | F16: XE01335 | G16: 1061644437 | H16: Vietcombank | I16: 1500000
A17: 03-05-TU | B17: 46145 | C17: Thanh Hóa- HCM | D17: 29E12747 | E17: Nguyễn Thanh Lâm | F17: XE01644 | G17: 797908032000 | H17: MB | I17: 1500000
A18: 03-05-TU | B18: 46145 | C18: Hà Nội( Long Biên)- Cần Thơ | D18: 29K06820 | E18: Nguyễn Hữu Hưởng | F18: XE01304 | G18: 0393159115 | H18: MB | I18: 1500000
A19: 03-05-TU | B19: 46145 | C19: Hà Nội( Long Biên)- Cần Thơ | D19: 29K06820 | E19: Vũ Thế An | F19: XE01305 | G19: 0332302398 | H19: Vietinbank | I19: 1500000
A20: 04-05-TU | B20: 46146 | C20: Hà Nội - HCM | D20: 29K06824 | E20: Nguyễn Trọng Đạt | F20: XE01263 | G20: 0936205372 | H20: BIDV | I20: 1500000
A21: 04-05-TU | B21: 46146 | C21: Hà Nội - HCM | D21: 29K06824 | E21: Phạm Văn Thưởng | F21: XE01149 | G21: 0934329239 | H21: MB | I21: 1500000
A22: 04-05-TU | B22: 46146 | C22: Hà Nội( Long Biên)- Cần Thơ | D22: 29H70193 | E22: Võ Minh Liệp | F22: XE01543 | G22: 9977002907 | H22: Vietcombank | I22: 1500000
A23: 04-05-TU | B23: 46146 | C23: Hà Nội( Long Biên)- Cần Thơ | D23: 29H70193 | E23: Lý Hồng Ngà | F23: XE01622 | G23: 05 888 9999 9999 | H23: MB Bank | I23: 1500000
A24: 04-05-TU | B24: 46146 | C24: Hà Nội( Long Biên)- Cần Thơ | D24: 29E44369 | E24: Lê Quốc Quân | F24: XE01434 | G24: 77999911032002 | H24: Techcombank | I24: 1500000
A25: 04-05-TU | B25: 46146 | C25: Hà Nội( Long Biên)- Cần Thơ | D25: 29E44369 | E25: Nguyễn Văn Chí | F25: XE01433 | G25: 040080953668 | H25: Sacombank | I25: 1500000
A26: 05-05-TU | B26: 46147 | C26: Bắc Ninh- Đồng Nai | D26: 29C37344 | E26: Nguyễn Duy Tuấn | F26: XE01548 | G26: 0501000189005 | H26: Vietcombank | I26: 1500000
A27: 05-05-TU | B27: 46147 | C27: Bắc Ninh- Đồng Nai | D27: 29C37344 | E27: Ngô Hoàng Vũ | F27: XE01549 | G27: 026999625555 | H27: MB | I27: 1500000
A28: 05-05-TU | B28: 46147 | C28: Hà Nội( Long Biên)- Cần Thơ | D28: 29E12047 | E28: Huỳnh Lê Trần Long | F28: XE01506 | G28: 866086379 | H28: MB | I28: 1500000
A29: 05-05-TU | B29: 46147 | C29: Hà Nội( Long Biên)- Cần Thơ | D29: 29E12047 | E29: Đặng Tuân | F29: XE01507 | G29: 957979779 | H29: Nam Á | I29: 1500000
A30: 05-05-TU | B30: 46147 | C30: Thanh Hóa- HCM | D30: 29E54261 | E30: Trịnh Cao Phong | F30: XE01283 | G30: 9343825206 | H30: Vietcombank | I30: 1500000
A31: 05-05-TU | B31: 46147 | C31: Thanh Hóa- HCM | D31: 29E54261 | E31: Lê Thanh Sơn | F31: XE01541 | G31: 0325752492 | H31: MB | I31: 1500000
A32: 05-05-TU | B32: 46147 | C32: Hà Nội- HCM | D32: 29E38128 | E32: Nguyễn Văn Chiến | F32: XE01582 | G32: 109872813241 | H32: Vietinbank | I32: 1500000
A33: 05-05-TU | B33: 46147 | C33: Hà Nội- HCM | D33: 29E38128 | E33: Nguyễn Văn Thắng | F33: XE01583 | G33: 63333266789 | H33: MB Bank | I33: 1500000
A34: 06-05-TU | B34: 46148 | C34: Hà Nội( Long Biên)- Cần Thơ | D34: 29H80501 | E34: Kiều Kim Tiến | F34: XE00873 | G34: 0793075891 | H34: BIDV | I34: 1500000
A35: 06-05-TU | B35: 46148 | C35: Hà Nội( Long Biên)- Cần Thơ | D35: 29H80501 | E35: Đỗ Văn Cường | F35: XE01672 | G35: 102344298888 | H35: Vietinbank | I35: 1500000
A36: 06-05-TU | B36: 46148 | C36: Ninh Bình- Đồng Nai | D36: 29G02349 | E36: Trần Phúc Đạt | F36: XE01527 | G36: 00006249259 | H36: TP Bank | I36: 1500000
A37: 06-05-TU | B37: 46148 | C37: Ninh Bình- Đồng Nai | D37: 29G02349 | E37: Nguyễn Thanh Nhân | F37: XE01574 | G37: 5590206300663 | H37: Agribank | I37: 1500000
A38: 06-05-TU | B38: 46148 | C38: Hà Nội- Bình Dương | D38: 29E35164 | E38: Đào Ngọc Ngà | F38: XE00991 | G38: 9327640888 | H38: Vietcombank | I38: 3000000
A39: 06-05-TU | B39: 46148 | C39: Hà Nội- Bình Dương | D39: 29E35164 | E39: Phạm Quốc Toàn | F39: XE00854 | G39: 1025238163 | H39: Vietcombank | I39: 3000000
A40: 06-05-TU | B40: 46148 | C40: Hà Nội- Bình Dương | D40: 29E12333 | E40: Phạm Văn Phố | F40: XE01308 | G40: 48810000602191 | H40: BIDV | I40: 3000000
...
