Workbook

Sheet Tóm tắt CP
A1: Tháng | B1: 01/12/2025
A3: Row Labels | B3: Sum of Chi phí khấu trừ quỹ lương tháng | C3: T1/2026 | D3: T2/2026 | E3: T3/2026 | F3: T4/2026 | G3: T5/2026
A4: CP BD, SC trích trước | B4: 17184343 | C4: 16339840 | D4: 17433355 | E4: 15286570 | F4: 17410089 | G4: =+SUMIF('Chi tiết T4'!D:D,'Tóm tắt CP'!A4,'Chi tiết T4'!N:N) -> 19392124
A5: CP liên quan đến khấu hao PT | B5: 1.7957133e+08 | C5: 178646335 | D5: 174865000 | E5: 1.8034602e+08 | F5: 179479350 | G5: =+SUMIF('Chi tiết T4'!D:D,'Tóm tắt CP'!A5,'Chi tiết T4'!N:N) -> 1.7947935e+08
A6: CP mua sắm TTB VP | B6: 1144697 | C6: 936364 | D6: 728030.33 | E6: 728030.33 | F6: 728030.33 | G6: =+SUMIF('Chi tiết T4'!D:D,'Tóm tắt CP'!A6,'Chi tiết T4'!N:N) -> 151515.17
A7: CP năng lượng/ nhiên liệu | B7: 34113370 | C7: 39459879 | D7: 33848308 | E7: 32475252 | F7: 38476445 | G7: =+SUMIF('Chi tiết T4'!D:D,'Tóm tắt CP'!A7,'Chi tiết T4'!N:N) -> 47875851
A8: CP quản lý khác | B8: 8890650 | C8: 7792758 | D8: 13781942 | E8: 7394737 | F8: 17637808 | G8: =+SUMIF('Chi tiết T4'!D:D,'Tóm tắt CP'!A8,'Chi tiết T4'!N:N) -> 12389643
A9: CP vận hành khác | B9: 4750000 | C9: 6640000 | D9: 3420000 | E9: 6086000 | F9: 4939000 | G9: =+SUMIF('Chi tiết T4'!D:D,'Tóm tắt CP'!A9,'Chi tiết T4'!N:N) -> 2770000
A10: Grand Total | B10: 2.456544e+08 | C10: =SUBTOTAL(9,C4:C9) -> 249815176 | D10: =SUBTOTAL(9,D4:D9) -> 2.4407664e+08 | E10: =SUBTOTAL(9,E4:E9) -> 242316606 | F10: =SUM(F4:F9) -> 2.5867072e+08 | G10: =SUM(G4:G9) -> 2.6205848e+08 | H10: =SUM(H4:H9) -> 0 | I10: =SUM(I4:I9) -> 0 | J10: =SUM(J4:J9) -> 0 | K10: =SUM(K4:K9) -> 0 | L10: =SUM(L4:L9) -> 0 | M10: =SUM(M4:M9) -> 0 | N10: =SUM(N4:N9) -> 0

Sheet Chi tiết T4
A1: STT | B1: Tháng | C1: Tỉnh | D1: Nhóm CP | E1: Hạng mục chi | F1: Diễn giải chi tiết | G1: Tính chất chi phí | H1: Đối tượng theo dõi (BSX) | I1: Phân loại phương tiện/ Chức danh nhân sự | J1: KM hoạt động | K1: Ngày phát sinh chi phí | L1: Tổng số tiền (VNĐ) | M1: Số tháng khấu hao | N1: Chi phí khấu trừ quỹ lương tháng | O1: Tháng tính khấu hao cuối cùng | P1: Ghi chú
A2: =SUBTOTAL(3,$B$2:B2) -> 1 | B2: 46143 | C2: YB | D2: CP liên quan đến khấu hao PT | E2: Mua xe trung chuyển | F2: CP mua xe mới | G2: Mua 1 lần, tính khấu hao hàng tháng | H2: 30L86851 | I2: Vf6 | K2: 45653 | L2: 785000000 | M2: 60 | N2: =IF(B2>O2,"",L2/M2) -> 13083333 | O2: =EDATE(K2, M2-1) -> 47449
A3: =SUBTOTAL(3,$B$2:B3) -> 2 | B3: 46143 | C3: YB | D3: CP liên quan đến khấu hao PT | E3: Mua xe trung chuyển | F3: CP mua xe mới | G3: Mua 1 lần, tính khấu hao hàng tháng | H3: 30L86704 | I3: Vf6 | K3: 45653 | L3: 785000000 | M3: 60 | N3: =IF(B3>O3,"",L3/M3) -> 13083333 | O3: =EDATE(K3, M3-1) -> 47449
A4: =SUBTOTAL(3,$B$2:B4) -> 3 | B4: 46143 | C4: YB | D4: CP liên quan đến khấu hao PT | E4: Mua xe trung chuyển | F4: CP mua xe mới | G4: Mua 1 lần, tính khấu hao hàng tháng | H4: 30L86761 | I4: Vf6 | K4: 45653 | L4: 785000000 | M4: 60 | N4: =IF(B4>O4,"",L4/M4) -> 13083333 | O4: =EDATE(K4, M4-1) -> 47449
A5: =SUBTOTAL(3,$B$2:B5) -> 4 | B5: 46143 | C5: YB | D5: CP liên quan đến khấu hao PT | E5: Mua xe trung chuyển | F5: CP mua xe mới | G5: Mua 1 lần, tính khấu hao hàng tháng | H5: 30L86763 | I5: Vf6 | K5: 45653 | L5: 785000000 | M5: 60 | N5: =IF(B5>O5,"",L5/M5) -> 13083333 | O5: =EDATE(K5, M5-1) -> 47449
A6: =SUBTOTAL(3,$B$2:B6) -> 5 | B6: 46143 | C6: YB | D6: CP liên quan đến khấu hao PT | E6: Mua xe trung chuyển | F6: CP mua xe mới | G6: Mua 1 lần, tính khấu hao hàng tháng | H6: 30L86727 | I6: Vf6 | K6: 45665 | L6: 785000000 | M6: 60 | N6: =IF(B6>O6,"",L6/M6) -> 13083333 | O6: =EDATE(K6, M6-1) -> 47460
A7: =SUBTOTAL(3,$B$2:B7) -> 6 | B7: 46143 | C7: YB | D7: CP liên quan đến khấu hao PT | E7: Mua xe trung chuyển | F7: CP mua xe mới | G7: Mua 1 lần, tính khấu hao hàng tháng | H7: 30L86964 | I7: Vf6 | K7: 45665 | L7: 785000000 | M7: 60 | N7: =IF(B7>O7,"",L7/M7) -> 13083333 | O7: =EDATE(K7, M7-1) -> 47460
A8: =SUBTOTAL(3,$B$2:B8) -> 7 | B8: 46143 | C8: YB | D8: CP liên quan đến khấu hao PT | E8: Mua xe trung chuyển | F8: CP mua xe mới | G8: Mua 1 lần, tính khấu hao hàng tháng | H8: 29B30385 | I8: Vf6 | K8: 45729 | L8: 785000000 | M8: 60 | N8: =IF(B8>O8,"",L8/M8) -> 13083333 | O8: =EDATE(K8, M8-1) -> 47527
A9: =SUBTOTAL(3,$B$2:B9) -> 8 | B9: 46143 | C9: YB | D9: CP liên quan đến khấu hao PT | E9: Mua xe trung chuyển | F9: CP mua xe mới | G9: Mua 1 lần, tính khấu hao hàng tháng | H9: 29B61137 | I9: Vf6 | K9: 45729 | L9: 785000000 | M9: 60 | N9: =IF(B9>O9,"",L9/M9) -> 13083333 | O9: =EDATE(K9, M9-1) -> 47527
A10: =SUBTOTAL(3,$B$2:B10) -> 9 | B10: 46143 | C10: YB | D10: CP liên quan đến khấu hao PT | E10: Mua xe trung chuyển | F10: CP mua xe mới | G10: Mua 1 lần, tính khấu hao hàng tháng | H10: 29B30453 | I10: Vf6 | K10: 45729 | L10: 785000000 | M10: 60 | N10: =IF(B10>O10,"",L10/M10) -> 13083333 | O10: =EDATE(K10, M10-1) -> 47527
A11: =SUBTOTAL(3,$B$2:B11) -> 10 | B11: 46143 | C11: YB | D11: CP liên quan đến khấu hao PT | E11: Mua xe trung chuyển | F11: CP mua xe mới | G11: Mua 1 lần, tính khấu hao hàng tháng | H11: 29B30407 | I11: Vf6 | K11: 45729 | L11: 785000000 | M11: 60 | N11: =IF(B11>O11,"",L11/M11) -> 13083333 | O11: =EDATE(K11, M11-1) -> 47527
A12: =SUBTOTAL(3,$B$2:B12) -> 11 | B12: 46143 | C12: YB | D12: CP liên quan đến khấu hao PT | E12: Mua xe trung chuyển | F12: CP mua xe mới | G12: Mua 1 lần, tính khấu hao hàng tháng | H12: 29B30446 | I12: Vf6 | K12: 45729 | L12: 785000000 | M12: 60 | N12: =IF(B12>O12,"",L12/M12) -> 13083333 | O12: =EDATE(K12, M12-1) -> 47527
A13: =SUBTOTAL(3,$B$2:B13) -> 12 | B13: 46143 | C13: YB | D13: CP liên quan đến khấu hao PT | E13: Mua xe trung chuyển | F13: CP mua xe mới | G13: Mua 1 lần, tính khấu hao hàng tháng | H13: 29B30409 | I13: Vf6 | K13: 45729 | L13: 785000000 | M13: 60 | N13: =IF(B13>O13,"",L13/M13) -> 13083333 | O13: =EDATE(K13, M13-1) -> 47527
... A71: =SUBTOTAL(3,$B$2:B71) -> 70 | B71: 46143 | C71: YB | D71: CP liên quan đến khấu hao PT | E71: Mua thiết bị lắp thêm | F71: Mua sim 5G | G71: Mua 1 lần, tính khấu hao hàng tháng | H71: 30L86964 | I71: Vf6 | K71: 46030 | L71: 750000 | M71: 12 | N71: =IF(B71>O71,"",L71/M71) -> 62500 | O71: =EDATE(K71, M71-1) -> 46364
A72: =SUBTOTAL(3,$B$2:B72) -> 71 | B72: 46143 | C72: YB | D72: CP liên quan đến khấu hao PT | E72: Mua thiết bị lắp thêm | F72: chi phí mua ô 2m5 x 2m5 che nắng mưa đón khách trên Yên Bái | G72: Mua 1 lần, tính khấu hao hàng tháng | K72: 45827 | L72: 2500000 | M72: 12 | N72: =IF(B72>O72,"",L72/M72) -> 208333.33 | O72: =EDATE(K72, M72-1) -> 46161
A73: =SUBTOTAL(3,$B$2:B73) -> 72 | B73: 46143 | C73: YB | D73: CP liên quan đến khấu hao PT | E73: CP mua sắm TTB VP | F73: máy chấm công Yên Bái ngày 05/02/2024 | G73: Mua 1 lần, tính khấu hao hàng tháng | K73: 45327 | L73: 2363636 | M73: 24 | N73: =IF(B73>O73,"",L73/M73) | O73: =EDATE(K73, M73-1) -> 46027
A74: =SUBTOTAL(3,$B$2:B74) -> 73 | B74: 46143 | C74: YB | D74: CP mua sắm TTB VP | E74: CP mua sắm TTB VP | F74: Màn hình máy tính 2,1 inch FHD Monitor | G74: Mua 1 lần, tính khấu hao hàng tháng | K74: 45321 | L74: 5000000 | M74: 24 | N74: =IF(B74>O74,"",L74/M74) | O74: =EDATE(K74, M74-1) -> 46021
A75: =SUBTOTAL(3,$B$2:B75) -> 74 | B75: 46143 | C75: YB | D75: CP mua sắm TTB VP | E75: CP mua sắm TTB VP | F75: Màn hình máy tính 2,1 inch FHD Monitor | G75: Mua 1 lần, tính khấu hao hàng tháng | K75: 45324 | L75: 5000000 | M75: 24 | N75: =IF(B75>O75,"",L75/M75) | O75: =EDATE(K75, M75-1) -> 46024
A76: =SUBTOTAL(3,$B$2:B76) -> 75 | B76: 46143 | C76: YB | D76: CP mua sắm TTB VP | E76: CP mua sắm TTB VP | F76: CP mua sắm TTB VP VP 263 2 bộ máy tính | G76: Mua 1 lần, tính khấu hao hàng tháng | K76: 45432 | L76: 10200000 | M76: 24 | N76: =IF(B76>O76,"",L76/M76) | O76: =EDATE(K76, M76-1) -> 46132
A77: =SUBTOTAL(3,$B$2:B77) -> 76 | B77: 46143 | C77: YB | D77: CP mua sắm TTB VP | E77: CP mua sắm TTB VP | F77: CP mua sắm TTB VP VP 263 máy in 2900 | G77: Mua 1 lần, tính khấu hao hàng tháng | K77: 45432 | L77: 3636364 | M77: 24 | N77: =IF(B77>O77,"",L77/M77) | O77: =EDATE(K77, M77-1) -> 46132
A78: =SUBTOTAL(3,$B$2:B78) -> 77 | B78: 46143 | C78: YB | D78: CP mua sắm TTB VP | E78: CP mua sắm TTB VP | F78: CP mua sắm TTB VP VP 263 máy in 2900 | G78: Mua 1 lần, tính khấu hao hàng tháng | K78: 45321 | L78: 3636364 | M78: 24 | N78: =IF(B78>O78,"",L78/M78) | O78: =EDATE(K78, M78-1) -> 46021
A79: =SUBTOTAL(3,$B$2:B79) -> 78 | B79: 46143 | C79: YB | D79: CP mua sắm TTB VP | E79: CP mua sắm TTB VP | F79: Mua chăn ga gối đệm phòng TCN mới | G79: Mua 1 lần, tính khấu hao hàng tháng | K79: 46044 | L79: 3636364 | M79: 24 | N79: =IF(B79>O79,"",L79/M79) -> 151515.17 | O79: =EDATE(K79, M79-1) -> 46743
A80: =SUBTOTAL(3,$B$2:B80) -> 79 | B80: 46143 | C80: YB | D80: CP quản lý khác | E80: CP điện thoại | F80: CP điện thoại điều hành 0868312223 | G80: CP phát sinh hàng tháng | K80: 46143 | L80: 150000 | M80: 1 | N80: =IF(B80>O80,"",L80/M80) -> 150000 | O80: =EDATE(K80, M80-1) -> 46143
A81: =SUBTOTAL(3,$B$2:B81) -> 80 | B81: 46143 | C81: YB | D81: CP quản lý khác | E81: CP điện thoại | F81: CP điện thoại văn phòng 0862890005 | G81: CP phát sinh hàng tháng | K81: 46143 | L81: 160000 | M81: 1 | N81: =IF(B81>O81,"",L81/M81) -> 160000 | O81: =EDATE(K81, M81-1) -> 46143
A82: =SUBTOTAL(3,$B$2:B82) -> 81 | B82: 46143 | C82: YB | D82: CP BD, SC trích trước | E82: BD, SC PT | F82: CP bảo dưỡng | G82: CP phát sinh trong tháng | H82: 30L86851 | I82: Vf6 | J82: 6634 | K82: 46143 | L82: =J82*SUMIFS('Đơn giá SCBD'!F:F,'Đơn giá SCBD'!A:A,'Chi tiết T4'!F82,'Đơn giá SCBD'!B:B,'Chi tiết T4'!I82) -> 768940.91 | M82: 1 | N82: =IF(B82>O82,"",L82/M82) -> 768940.91 | O82: =EDATE(K82, M82-1) -> 46143
A83: =SUBTOTAL(3,$B$2:B83) -> 82 | B83: 46143 | C83: YB | D83: CP BD, SC trích trước | E83: BD, SC PT | F83: CP bảo dưỡng | G83: CP phát sinh trong tháng | H83: 30L86704 | I83: Vf6 | J83: 5266 | K83: 46143 | L83: =J83*SUMIFS('Đơn giá SCBD'!F:F,'Đơn giá SCBD'!A:A,'Chi tiết T4'!F83,'Đơn giá SCBD'!B:B,'Chi tiết T4'!I83) -> 610377.27 | M83: 1 | N83: =IF(B83>O83,"",L83/M83) -> 610377.27 | O83: =EDATE(K83, M83-1) -> 46143
A84: =SUBTOTAL(3,$B$2:B84) -> 83 | B84: 46143 | C84: YB | D84: CP BD, SC trích trước | E84: BD, SC PT | F84: CP bảo dưỡng | G84: CP phát sinh trong tháng | H84: 30L86761 | I84: Vf6 | J84: 3400 | K84: 46143 | L84: =J84*SUMIFS('Đơn giá SCBD'!F:F,'Đơn giá SCBD'!A:A,'Chi tiết T4'!F84,'Đơn giá SCBD'!B:B,'Chi tiết T4'!I84) -> 394090.91 | M84: 1 | N84: =IF(B84>O84,"",L84/M84) -> 394090.91 | O84: =EDATE(K84, M84-1) -> 46143
A85: =SUBTOTAL(3,$B$2:B85) -> 84 | B85: 46143 | C85: YB | D85: CP BD, SC trích trước | E85: BD, SC PT | F85: CP bảo dưỡng | G85: CP phát sinh trong tháng | H85: 30L86763 | I85: Vf6 | J85: 4784 | K85: 46143 | L85: =J85*SUMIFS('Đơn giá SCBD'!F:F,'Đơn giá SCBD'!A:A,'Chi tiết T4'!F85,'Đơn giá SCBD'!B:B,'Chi tiết T4'!I85) -> 554509.09 | M85: 1 | N85: =IF(B85>O85,"",L85/M85) -> 554509.09 | O85: =EDATE(K85, M85-1) -> 46143
A86: =SUBTOTAL(3,$B$2:B86) -> 85 | B86: 46143 | C86: YB | D86: CP BD, SC trích trước | E86: BD, SC PT | F86: CP bảo dưỡng | G86: CP phát sinh trong tháng | H86: 30L86727 | I86: Vf6 | J86: 5645 | K86: 46143 | L86: =J86*SUMIFS('Đơn giá SCBD'!F:F,'Đơn giá SCBD'!A:A,'Chi tiết T4'!F86,'Đơn giá SCBD'!B:B,'Chi tiết T4'!I86) -> 654306.82 | M86: 1 | N86: =IF(B86>O86,"",L86/M86) -> 654306.82 | O86: =EDATE(K86, M86-1) -> 46143
A87: =SUBTOTAL(3,$B$2:B87) -> 86 | B87: 46143 | C87: YB | D87: CP BD, SC trích trước | E87: BD, SC PT | F87: CP bảo dưỡng | G87: CP phát sinh trong tháng | H87: 30L86964 | I87: Vf6 | J87: 4632 | K87: 46143 | L87: =J87*SUMIFS('Đơn giá SCBD'!F:F,'Đơn giá SCBD'!A:A,'Chi tiết T4'!F87,'Đơn giá SCBD'!B:B,'Chi tiết T4'!I87) -> 536890.91 | M87: 1 | N87: =IF(B87>O87,"",L87/M87) -> 536890.91 | O87: =EDATE(K87, M87-1) -> 46143
A88: =SUBTOTAL(3,$B$2:B88) -> 87 | B88: 46143 | C88: YB | D88: CP BD, SC trích trước | E88: BD, SC PT | F88: CP bảo dưỡng | G88: CP phát sinh trong tháng | H88: 29B30385 | I88: Vf6 | J88: 4952 | K88: 46143 | L88: =J88*SUMIFS('Đơn giá SCBD'!F:F,'Đơn giá SCBD'!A:A,'Chi tiết T4'!F88,'Đơn giá SCBD'!B:B,'Chi tiết T4'!I88) -> 573981.82 | M88: 1 | N88: =IF(B88>O88,"",L88/M88) -> 573981.82 | O88: =EDATE(K88, M88-1) -> 46143
A89: =SUBTOTAL(3,$B$2:B89) -> 88 | B89: 46143 | C89: YB | D89: CP BD, SC trích trước | E89: BD, SC PT | F89: CP bảo dưỡng | G89: CP phát sinh trong tháng | H89: 29B61137 | I89: Vf6 | J89: 4934 | K89: 46143 | L89: =J89*SUMIFS('Đơn giá SCBD'!F:F,'Đơn giá SCBD'!A:A,'Chi tiết T4'!F89,'Đơn giá SCBD'!B:B,'Chi tiết T4'!I89) -> 571895.45 | M89: 1 | N89: =IF(B89>O89,"",L89/M89) -> 571895.45 | O89: =EDATE(K89, M89-1) -> 46143
A90: =SUBTOTAL(3,$B$2:B90) -> 89 | B90: 46143 | C90: YB | D90: CP BD, SC trích trước | E90: BD, SC PT | F90: CP bảo dưỡng | G90: CP phát sinh trong tháng | H90: 29B30453 | I90: Vf6 | J90: 4963 | K90: 46143 | L90: =J90*SUMIFS('Đơn giá SCBD'!F:F,'Đơn giá SCBD'!A:A,'Chi tiết T4'!F90,'Đơn giá SCBD'!B:B,'Chi tiết T4'!I90) -> 575256.82 | M90: 1 | N90: =IF(B90>O90,"",L90/M90) -> 575256.82 | O90: =EDATE(K90, M90-1) -> 46143
A91: =SUBTOTAL(3,$B$2:B91) -> 90 | B91: 46143 | C91: YB | D91: CP BD, SC trích trước | E91: BD, SC PT | F91: CP bảo dưỡng | G91: CP phát sinh trong tháng | H91: 29B30407 | I91: Vf6 | J91: 5096 | K91: 46143 | L91: =J91*SUMIFS('Đơn giá SCBD'!F:F,'Đơn giá SCBD'!A:A,'Chi tiết T4'!F91,'Đơn giá SCBD'!B:B,'Chi tiết T4'!I91) -> 590672.73 | M91: 1 | N91: =IF(B91>O91,"",L91/M91) -> 590672.73 | O91: =EDATE(K91, M91-1) -> 46143
A92: =SUBTOTAL(3,$B$2:B92) -> 91 | B92: 46143 | C92: YB | D92: CP BD, SC trích trước | E92: BD, SC PT | F92: CP bảo dưỡng | G92: CP phát sinh trong tháng | H92: 29B30446 | I92: Vf6 | J92: 4690 | K92: 46143 | L92: =J92*SUMIFS('Đơn giá SCBD'!F:F,'Đơn giá SCBD'!A:A,'Chi tiết T4'!F92,'Đơn giá SCBD'!B:B,'Chi tiết T4'!I92) -> 543613.64 | M92: 1 | N92: =IF(B92>O92,"",L92/M92) -> 543613.64 | O92: =EDATE(K92, M92-1) -> 46143
A93: =SUBTOTAL(3,$B$2:B93) -> 92 | B93: 46143 | C93: YB | D93: CP BD, SC trích trước | E93: BD, SC PT | F93: CP bảo dưỡng | G93: CP phát sinh trong tháng | H93: 29B30409 | I93: Vf6 | J93: 5465 | K93: 46143 | L93: =J93*SUMIFS('Đơn giá SCBD'!F:F,'Đơn giá SCBD'!A:A,'Chi tiết T4'!F93,'Đơn giá SCBD'!B:B,'Chi tiết T4'!I93) -> 633443.18 | M93: 1 | N93: =IF(B93>O93,"",L93/M93) -> 633443.18 | O93: =EDATE(K93, M93-1) -> 46143
... A120: =SUBTOTAL(3,$B$2:B120) -> 119 | B120: 46143 | C120: YB | D120: CP BD, SC trích trước | E120: BD, SC PT | F120: CP thay ắc quy | G120: CP phát sinh trong tháng | H120: 30M36249 | I120: Vf6 | J120: 1217 | K120: 46143 | L120: =J120*SUMIFS('Đơn giá SCBD'!F:F,'Đơn giá SCBD'!A:A,'Chi tiết T4'!F120,'Đơn giá SCBD'!B:B,'Chi tiết T4'!I120) -> 22514.5 | M120: 1 | N120: =IF(B120>O120,"",L120/M120) -> 22514.5 | O120: =EDATE(K120, M120-1) -> 46143
A121: =SUBTOTAL(3,$B$2:B121) -> 120 | B121: 46143 | C121: YB | D121: CP năng lượng/ nhiên liệu | E121: Tiền điện | F121: Tiền điện | G121: CP phát sinh hàng tháng | H121: 30L86763 | I121: Vf6 | K121: 46143 | L121: 3622739 | M121: 1 | N121: =IF(B121>O121,"",L121/M121) -> 3622739 | O121: =EDATE(K121, M121-1) -> 46143
A122: =SUBTOTAL(3,$B$2:B122) -> 121 | B122: 46143 | C122: YB | D122: CP năng lượng/ nhiên liệu | E122: Tiền điện | F122: Tiền điện | G122: CP phát sinh hàng tháng | H122: 30L86761 | I122: Vf6 | K122: 46143 | L122: 2603263 | M122: 1 | N122: =IF(B122>O122,"",L122/M122) -> 2603263 | O122: =EDATE(K122, M122-1) -> 46143
A123: =SUBTOTAL(3,$B$2:B123) -> 122 | B123: 46143 | C123: YB | D123: CP năng lượng/ nhiên liệu | E123: Tiền điện | F123: Tiền điện | G123: CP phát sinh hàng tháng | H123: 30L86704 | I123: Vf6 | K123: 46143 | L123: 4228368 | M123: 1 | N123: =IF(B123>O123,"",L123/M123) -> 4228368 | O123: =EDATE(K123, M123-1) -> 46143
...

Sheet Đơn giá SCBD
A1: Stt | B1: Khoản mục | C1: Định mức thay/trích trước | D1: Đơn giá (đồng) | E1: Định ngạch sử dụng (km) | F1: Đơn giá chi phí (đ/km)
A2: CP thay dầu, nhớt | B2: Ford | C2: 9.5 | D2: 135000 | E2: 10000 | F2: =C2*D2/E2 -> 128.25
A3: CP thay dầu, nhớt | B3: Solati | C3: 7.5 | D3: 135000 | E3: 10000 | F3: =C3*D3/E3 -> 101.25
A4: CP thay dầu, nhớt | B4: Suzu | C4: 4 | D4: 140000 | E4: 10000 | F4: =C4*D4/E4 -> 56
A5: CP thay dầu, nhớt | B5: Vf6 | C5: 0
A6: CP thay lốp | B6: Ford | C6: 4 | D6: 2635000 | E6: 100000 | F6: =C6*D6/E6 -> 105.4 | G6: Lốp theo xe
A7: CP thay lốp | B7: Solati | C7: 4 | D7: 2635000 | E7: 100000 | F7: =C7*D7/E7 -> 105.4 | G7: Bridgestone
A8: CP thay lốp | B8: Suzu | C8: 4 | D8: 1360000 | E8: 80000 | F8: =C8*D8/E8 -> 68
A9: CP thay lốp | B9: Vf6 | C9: 4 | D9: 3600000 | E9: 80000 | F9: =C9*D9/E9 -> 180
A10: CP thay ắc quy | B10: Ford | C10: 1 | D10: 1850000 | E10: 100000 | F10: =C10*D10/E10 -> 18.5
A11: CP thay ắc quy | B11: Solati | C11: 1 | D11: 2950000 | E11: 100000 | F11: =C11*D11/E11 -> 29.5
A12: CP thay ắc quy | B12: Suzu | C12: 1 | D12: 1650000 | E12: 100000 | F12: =C12*D12/E12 -> 16.5
A13: CP thay ắc quy | B13: Vf6 | C13: 1 | D13: 1850000 | E13: 100000 | F13: =C13*D13/E13 -> 18.5
A14: CP bảo dưỡng | B14: Ford | C14: 0.1 | D14: 12930133 | E14: 5000 | F14: =D14*C14/E14 -> 258.60267
A15: CP bảo dưỡng | B15: Solati | C15: 0.1 | D15: 12930133 | E15: 5000 | F15: =D15*C15/E15 -> 258.60267
A16: CP bảo dưỡng | B16: Suzu | C16: 0.08 | D16: 12930133 | E16: 5000 | F16: =D16*C16/E16 -> 206.88213
A17: CP bảo dưỡng | B17: Vf6 | C17: 0.05 | D17: 11590909 | E17: 5000 | F17: =D17*C17/E17 -> 115.90909

Sheet Doanh thu CN
A1: THÁNG | B1: TỈNH | C1: SẢN LƯỢNG HK | E1: SỐ LƯỢNG PHƯƠNG TIỆN QUẢN LÝ
A2: 46143 | B2: YB | C2: Số khách | D2: 15450 | E2: Xe tuyến | F2: 22
C3: Số khách huỷ | D3: 43 | E3: Xe trung chuyển | F3: 13
C4: Số khách nội bộ | D4: 48
