Workbook

Sheet Tóm tắt CP
A1: Tháng | B1: (All)
A3: Row Labels | B3: Sum of Chi phí khấu trừ quỹ lương tháng
A4: CP BD, SC trích trước | B4: 14780712
A5: CP liên quan đến khấu hao PT | B5: 93994258
A6: CP mua sắm TTB VP | B6: 0
A7: CP năng lượng/ nhiên liệu | B7: 85092880
A8: CP quản lý khác | B8: 1150000
A9: CP vận hành khác | B9: 3540000
A10: (blank)
A11: Grand Total | B11: 1.9855785e+08

Sheet Chi tiết
A1: STT | B1: Tháng | C1: Tỉnh | D1: Nhóm CP | E1: Hạng mục chi | F1: Diễn giải chi tiết | G1: Tính chất chi phí | H1: Đối tượng theo dõi (BSX) | I1: Phân loại phương tiện/ Chức danh nhân sự | J1: KM hoạt động | K1: Ngày phát sinh chi phí | L1: Tổng số tiền (VNĐ) | M1: Số tháng khấu hao | N1: Chi phí khấu trừ quỹ lương tháng | O1: Tháng tính khấu hao cuối cùng | P1: Ghi chú
A2: =SUBTOTAL(3,$B$2:B2) -> 1 | B2: 46143 | C2: PT | D2: CP liên quan đến khấu hao PT | E2: Mua xe trung chuyển | F2: CP mua xe mới | G2: Mua 1 lần, tính khấu hao hàng tháng | H2: 29K23947 | I2: Vf6 | J2: 4873 | K2: 45729 | L2: 785000000 | M2: 60 | N2: =IF(B2>O2,"",L2/M2) -> 13083333 | O2: =EDATE(K2, M2-1) -> 47527
A3: =SUBTOTAL(3,$B$2:B3) -> 2 | B3: 46143 | C3: PT | D3: CP liên quan đến khấu hao PT | E3: Mua xe trung chuyển | F3: CP mua xe mới | G3: Mua 1 lần, tính khấu hao hàng tháng | H3: 29K23961 | I3: Vf6 | J3: 5345 | K3: 45729 | L3: 785000000 | M3: 60 | N3: =IF(B3>O3,"",L3/M3) -> 13083333 | O3: =EDATE(K3, M3-1) -> 47527
A4: =SUBTOTAL(3,$B$2:B4) -> 3 | B4: 46143 | C4: PT | D4: CP liên quan đến khấu hao PT | E4: Mua xe trung chuyển | F4: CP mua xe mới | G4: Mua 1 lần, tính khấu hao hàng tháng | H4: 29H88546 | I4: Solati | J4: 8718 | K4: 45365 | L4: 1350000000 | M4: 72 | N4: =IF(B4>O4,"",L4/M4) -> 18750000 | O4: =EDATE(K4, M4-1) -> 47528
A5: =SUBTOTAL(3,$B$2:B5) -> 4 | B5: 46143 | C5: PT | D5: CP liên quan đến khấu hao PT | E5: Mua xe trung chuyển | F5: CP mua xe mới | G5: Mua 1 lần, tính khấu hao hàng tháng | H5: 29H88577 | I5: Solati | J5: 10100 | K5: 45365 | L5: 1350000000 | M5: 72 | N5: =IF(B5>O5,"",L5/M5) -> 18750000 | O5: =EDATE(K5, M5-1) -> 47528
A6: =SUBTOTAL(3,$B$2:B6) -> 5 | B6: 46143 | C6: PT | D6: CP liên quan đến khấu hao PT | E6: Mua xe trung chuyển | F6: CP mua xe mới | G6: Mua 1 lần, tính khấu hao hàng tháng | H6: 30L86952 | I6: Vf6 | J6: 5053 | K6: 45858 | L6: 785000000 | M6: 60 | N6: =IF(B6>O6,"",L6/M6) -> 13083333 | O6: =EDATE(K6, M6-1) -> 47654
A7: =SUBTOTAL(3,$B$2:B7) -> 6 | B7: 46143 | C7: PT | D7: CP liên quan đến khấu hao PT | E7: CP mua BH | F7: BH vật chất và BH TNDS | G7: Mua 1 lần, tính khấu hao hàng tháng | H7: 29K23947 | I7: Vf6 | J7: 4873 | K7: 46094 | L7: 7365700 | M7: 12 | N7: =IF(B7>O7,"",L7/M7) -> 613808.33 | O7: =EDATE(K7, M7-1) -> 46431
A8: =SUBTOTAL(3,$B$2:B8) -> 7 | B8: 46143 | C8: PT | D8: CP liên quan đến khấu hao PT | E8: CP mua BH | F8: BH vật chất và BH TNDS | G8: Mua 1 lần, tính khấu hao hàng tháng | H8: 29K23961 | I8: Vf6 | J8: 5345 | K8: 46094 | L8: 7365700 | M8: 12 | N8: =IF(B8>O8,"",L8/M8) -> 613808.33 | O8: =EDATE(K8, M8-1) -> 46431
A9: =SUBTOTAL(3,$B$2:B9) -> 8 | B9: 46143 | C9: PT | D9: CP liên quan đến khấu hao PT | E9: CP mua BH | F9: BH vật chất và BH TNDS | G9: Mua 1 lần, tính khấu hao hàng tháng | H9: 29H88546 | I9: Solati | J9: 8718 | K9: 46095 | L9: 15084000 | M9: 12 | N9: =IF(B9>O9,"",L9/M9) -> 1257000 | O9: =EDATE(K9, M9-1) -> 46432
A10: =SUBTOTAL(3,$B$2:B10) -> 9 | B10: 46143 | C10: PT | D10: CP liên quan đến khấu hao PT | E10: CP mua BH | F10: BH vật chất và BH TNDS | G10: Mua 1 lần, tính khấu hao hàng tháng | H10: 29H88577 | I10: Solati | J10: 10100 | K10: 46095 | L10: 15084000 | M10: 12 | N10: =IF(B10>O10,"",L10/M10) -> 1257000 | O10: =EDATE(K10, M10-1) -> 46432
A11: =SUBTOTAL(3,$B$2:B11) -> 10 | B11: 46143 | C11: PT | D11: CP liên quan đến khấu hao PT | E11: CP mua BH | F11: BH vật chất và BH TNDS | G11: Mua 1 lần, tính khấu hao hàng tháng | H11: 30L86952 | I11: Vf6 | J11: 5053 | K11: 45858 | L11: 7365700 | M11: 12 | N11: =IF(B11>O11,"",L11/M11) -> 613808.33 | O11: =EDATE(K11, M11-1) -> 46193
A12: =SUBTOTAL(3,$B$2:B12) -> 11 | B12: 46143 | C12: PT | D12: CP liên quan đến khấu hao PT | E12: CP đăng kiểm, đường bộ | F12: CP đăng kiểm, bảo trì đường bộ | G12: Mua 1 lần, tính khấu hao hàng tháng | H12: 29K23947 | I12: Vf6 | J12: 4873 | K12: 46094 | L12: 2160000 | M12: 12 | N12: =IF(B12>O12,"",L12/M12) -> 180000 | O12: =EDATE(K12, M12-1) -> 46431
A13: =SUBTOTAL(3,$B$2:B13) -> 12 | B13: 46143 | C13: PT | D13: CP liên quan đến khấu hao PT | E13: CP đăng kiểm, đường bộ | F13: CP đăng kiểm, bảo trì đường bộ | G13: Mua 1 lần, tính khấu hao hàng tháng | H13: 29K23961 | I13: Vf6 | J13: 5345 | K13: 46094 | L13: 2160000 | M13: 12 | N13: =IF(B13>O13,"",L13/M13) -> 180000 | O13: =EDATE(K13, M13-1) -> 46431
... A30: =SUBTOTAL(3,$B$2:B30) -> 29 | B30: 46143 | C30: PT | D30: CP liên quan đến khấu hao PT | E30: Mua thiết bị lắp thêm | F30: Mua sim 5G | G30: Mua 1 lần, tính khấu hao hàng tháng | H30: 30L86952 | I30: Vf6 | J30: 5053 | K30: 46223 | L30: 700000 | M30: 12 | N30: =IF(B30>O30,"",L30/M30) -> 58333.333 | O30: =EDATE(K30, M30-1) -> 46558
A31: =SUBTOTAL(3,$B$2:B31) -> 30 | B31: 46143 | C31: PT | D31: CP mua sắm TTB VP | E31: Trang thiết bị VP | F31: Hạch toán mua cây máy tính mới cho điều hành Phú Thọ (chuyển từ VP Lê Duẩn lên) | G31: Mua 1 lần, tính khấu hao hàng tháng | K31: 45261 | L31: 5445454 | M31: 24 | N31: =IF(B31>O31,"",L31/M31) | O31: =EDATE(K31, M31-1) -> 45962
A32: =SUBTOTAL(3,$B$2:B32) -> 31 | B32: 46143 | C32: PT | D32: CP BD, SC trích trước | E32: BD, SC PT | F32: CP thay dầu, nhớt | G32: CP trích trước hàng tháng | H32: 29H88546 | I32: Solati | J32: 8718 | K32: 46143 | L32: =J32*SUMIFS('Đơn giá SCBD'!F:F,'Đơn giá SCBD'!A:A,'Chi tiết'!F32,'Đơn giá SCBD'!B:B,'Chi tiết'!I32) -> 882697.5 | M32: 1 | N32: =IF(B32>O32,"",L32/M32) -> 882697.5 | O32: =EDATE(K32, M32-1) -> 46143
A33: =SUBTOTAL(3,$B$2:B33) -> 32 | B33: 46143 | C33: PT | D33: CP BD, SC trích trước | E33: BD, SC PT | F33: CP thay dầu, nhớt | G33: CP trích trước hàng tháng | H33: 29H88577 | I33: Solati | J33: 10100 | K33: 46143 | L33: =J33*SUMIFS('Đơn giá SCBD'!F:F,'Đơn giá SCBD'!A:A,'Chi tiết'!F33,'Đơn giá SCBD'!B:B,'Chi tiết'!I33) -> 1022625 | M33: 1 | N33: =IF(B33>O33,"",L33/M33) -> 1022625 | O33: =EDATE(K33, M33-1) -> 46143
A34: =SUBTOTAL(3,$B$2:B34) -> 33 | B34: 46143 | C34: PT | D34: CP BD, SC trích trước | E34: BD, SC PT | F34: CP thay lốp | G34: CP trích trước hàng tháng | H34: 29K23947 | I34: Vf6 | J34: 4873 | K34: 46143 | L34: =J34*SUMIFS('Đơn giá SCBD'!F:F,'Đơn giá SCBD'!A:A,'Chi tiết'!F34,'Đơn giá SCBD'!B:B,'Chi tiết'!I34) -> 877140 | M34: 1 | N34: =IF(B34>O34,"",L34/M34) -> 877140 | O34: =EDATE(K34, M34-1) -> 46143
A35: =SUBTOTAL(3,$B$2:B35) -> 34 | B35: 46143 | C35: PT | D35: CP BD, SC trích trước | E35: BD, SC PT | F35: CP thay lốp | G35: CP trích trước hàng tháng | H35: 29K23961 | I35: Vf6 | J35: 5345 | K35: 46143 | L35: =J35*SUMIFS('Đơn giá SCBD'!F:F,'Đơn giá SCBD'!A:A,'Chi tiết'!F35,'Đơn giá SCBD'!B:B,'Chi tiết'!I35) -> 962100 | M35: 1 | N35: =IF(B35>O35,"",L35/M35) -> 962100 | O35: =EDATE(K35, M35-1) -> 46143
A36: =SUBTOTAL(3,$B$2:B36) -> 35 | B36: 46143 | C36: PT | D36: CP BD, SC trích trước | E36: BD, SC PT | F36: CP thay lốp | G36: CP trích trước hàng tháng | H36: 29H88546 | I36: Solati | J36: 8718 | K36: 46143 | L36: =J36*SUMIFS('Đơn giá SCBD'!F:F,'Đơn giá SCBD'!A:A,'Chi tiết'!F36,'Đơn giá SCBD'!B:B,'Chi tiết'!I36) -> 918877.2 | M36: 1 | N36: =IF(B36>O36,"",L36/M36) -> 918877.2 | O36: =EDATE(K36, M36-1) -> 46143
A37: =SUBTOTAL(3,$B$2:B37) -> 36 | B37: 46143 | C37: PT | D37: CP BD, SC trích trước | E37: BD, SC PT | F37: CP thay lốp | G37: CP trích trước hàng tháng | H37: 29H88577 | I37: Solati | J37: 10100 | K37: 46143 | L37: =J37*SUMIFS('Đơn giá SCBD'!F:F,'Đơn giá SCBD'!A:A,'Chi tiết'!F37,'Đơn giá SCBD'!B:B,'Chi tiết'!I37) -> 1064540 | M37: 1 | N37: =IF(B37>O37,"",L37/M37) -> 1064540 | O37: =EDATE(K37, M37-1) -> 46143
A38: =SUBTOTAL(3,$B$2:B38) -> 37 | B38: 46143 | C38: PT | D38: CP BD, SC trích trước | E38: BD, SC PT | F38: CP thay lốp | G38: CP trích trước hàng tháng | H38: 30L86952 | I38: Vf6 | J38: 5053 | K38: 46143 | L38: =J38*SUMIFS('Đơn giá SCBD'!F:F,'Đơn giá SCBD'!A:A,'Chi tiết'!F38,'Đơn giá SCBD'!B:B,'Chi tiết'!I38) -> 909540 | M38: 1 | N38: =IF(B38>O38,"",L38/M38) -> 909540 | O38: =EDATE(K38, M38-1) -> 46143
A39: =SUBTOTAL(3,$B$2:B39) -> 38 | B39: 46143 | C39: PT | D39: CP BD, SC trích trước | E39: BD, SC PT | F39: CP thay ắc quy | G39: CP trích trước hàng tháng | H39: 29K23947 | I39: Vf6 | J39: 4873 | K39: 46143 | L39: =J39*SUMIFS('Đơn giá SCBD'!F:F,'Đơn giá SCBD'!A:A,'Chi tiết'!F39,'Đơn giá SCBD'!B:B,'Chi tiết'!I39) -> 90150.5 | M39: 1 | N39: =IF(B39>O39,"",L39/M39) -> 90150.5 | O39: =EDATE(K39, M39-1) -> 46143
A40: =SUBTOTAL(3,$B$2:B40) -> 39 | B40: 46143 | C40: PT | D40: CP BD, SC trích trước | E40: BD, SC PT | F40: CP thay ắc quy | G40: CP trích trước hàng tháng | H40: 29K23961 | I40: Vf6 | J40: 5345 | K40: 46143 | L40: =J40*SUMIFS('Đơn giá SCBD'!F:F,'Đơn giá SCBD'!A:A,'Chi tiết'!F40,'Đơn giá SCBD'!B:B,'Chi tiết'!I40) -> 98882.5 | M40: 1 | N40: =IF(B40>O40,"",L40/M40) -> 98882.5 | O40: =EDATE(K40, M40-1) -> 46143
A41: =SUBTOTAL(3,$B$2:B41) -> 40 | B41: 46143 | C41: PT | D41: CP BD, SC trích trước | E41: BD, SC PT | F41: CP thay ắc quy | G41: CP trích trước hàng tháng | H41: 29H88546 | I41: Solati | J41: 8718 | K41: 46143 | L41: =J41*SUMIFS('Đơn giá SCBD'!F:F,'Đơn giá SCBD'!A:A,'Chi tiết'!F41,'Đơn giá SCBD'!B:B,'Chi tiết'!I41) -> 257181 | M41: 1 | N41: =IF(B41>O41,"",L41/M41) -> 257181 | O41: =EDATE(K41, M41-1) -> 46143
A42: =SUBTOTAL(3,$B$2:B42) -> 41 | B42: 46143 | C42: PT | D42: CP BD, SC trích trước | E42: BD, SC PT | F42: CP thay ắc quy | G42: CP trích trước hàng tháng | H42: 29H88577 | I42: Solati | J42: 10100 | K42: 46143 | L42: =J42*SUMIFS('Đơn giá SCBD'!F:F,'Đơn giá SCBD'!A:A,'Chi tiết'!F42,'Đơn giá SCBD'!B:B,'Chi tiết'!I42) -> 297950 | M42: 1 | N42: =IF(B42>O42,"",L42/M42) -> 297950 | O42: =EDATE(K42, M42-1) -> 46143
A43: =SUBTOTAL(3,$B$2:B43) -> 42 | B43: 46143 | C43: PT | D43: CP BD, SC trích trước | E43: BD, SC PT | F43: CP thay ắc quy | G43: CP trích trước hàng tháng | H43: 30L86952 | I43: Vf6 | J43: 5053 | K43: 46143 | L43: =J43*SUMIFS('Đơn giá SCBD'!F:F,'Đơn giá SCBD'!A:A,'Chi tiết'!F43,'Đơn giá SCBD'!B:B,'Chi tiết'!I43) -> 93480.5 | M43: 1 | N43: =IF(B43>O43,"",L43/M43) -> 93480.5 | O43: =EDATE(K43, M43-1) -> 46143
... A48: =SUBTOTAL(3,$B$2:B48) -> 47 | B48: 46143 | C48: PT | D48: CP BD, SC trích trước | E48: BD, SC PT | F48: CP bảo dưỡng | G48: CP trích trước hàng tháng | H48: 30L86952 | I48: Vf6 | J48: 5053 | K48: 46143 | L48: =J48*SUMIFS('Đơn giá SCBD'!F:F,'Đơn giá SCBD'!A:A,'Chi tiết'!F48,'Đơn giá SCBD'!B:B,'Chi tiết'!I48) -> 585688.64 | M48: 1 | N48: =IF(B48>O48,"",L48/M48) -> 585688.64 | O48: =EDATE(K48, M48-1) -> 46143
A49: =SUBTOTAL(3,$B$2:B49) -> 48 | B49: 46143 | C49: PT | D49: CP năng lượng/ nhiên liệu | E49: Tiền dầu | F49: Tiền dầu | G49: CP phát sinh hàng tháng | H49: 29H88546 | I49: Solati | J49: 8718 | K49: 46143 | L49: 1857700 | M49: 1 | N49: =IF(B49>O49,"",L49/M49) -> 1857700 | O49: =EDATE(K49, M49-1) -> 46143
A50: =SUBTOTAL(3,$B$2:B50) -> 49 | B50: 46143 | C50: PT | D50: CP năng lượng/ nhiên liệu | E50: Tiền dầu | F50: Tiền dầu | G50: CP phát sinh hàng tháng | H50: 29H88577 | I50: Solati | J50: 10100 | K50: 46143 | L50: 1714800 | M50: 1 | N50: =IF(B50>O50,"",L50/M50) -> 1714800 | O50: =EDATE(K50, M50-1) -> 46143
A51: =SUBTOTAL(3,$B$2:B51) -> 50 | B51: 46143 | C51: PT | D51: CP năng lượng/ nhiên liệu | E51: Tiền dầu | F51: Tiền dầu | G51: CP phát sinh hàng tháng | H51: 29H88546 | I51: Solati | J51: 8718 | K51: 46144 | L51: 1829120 | M51: 1 | N51: =IF(B51>O51,"",L51/M51) -> 1829120 | O51: =EDATE(K51, M51-1) -> 46144
A52: =SUBTOTAL(3,$B$2:B52) -> 51 | B52: 46143 | C52: PT | D52: CP năng lượng/ nhiên liệu | E52: Tiền dầu | F52: Tiền dầu | G52: CP phát sinh hàng tháng | H52: 29H88577 | I52: Solati | J52: 10100 | K52: 46144 | L52: 1714800 | M52: 1 | N52: =IF(B52>O52,"",L52/M52) -> 1714800 | O52: =EDATE(K52, M52-1) -> 46144
A53: =SUBTOTAL(3,$B$2:B53) -> 52 | B53: 46143 | C53: PT | D53: CP năng lượng/ nhiên liệu | E53: Tiền dầu | F53: Tiền dầu | G53: CP phát sinh hàng tháng | H53: 29H88546 | I53: Solati | J53: 8718 | K53: 46145 | L53: 1714800 | M53: 1 | N53: =IF(B53>O53,"",L53/M53) -> 1714800 | O53: =EDATE(K53, M53-1) -> 46145
A54: =SUBTOTAL(3,$B$2:B54) -> 53 | B54: 46143 | C54: PT | D54: CP năng lượng/ nhiên liệu | E54: Tiền dầu | F54: Tiền dầu | G54: CP phát sinh hàng tháng | H54: 29H88577 | I54: Solati | J54: 10100 | K54: 46145 | L54: 1714800 | M54: 1 | N54: =IF(B54>O54,"",L54/M54) -> 1714800 | O54: =EDATE(K54, M54-1) -> 46145
A55: =SUBTOTAL(3,$B$2:B55) -> 54 | B55: 46143 | C55: PT | D55: CP năng lượng/ nhiên liệu | E55: Tiền dầu | F55: Tiền dầu | G55: CP phát sinh hàng tháng | H55: 29H88577 | I55: Solati | J55: 10100 | K55: 46147 | L55: 1714800 | M55: 1 | N55: =IF(B55>O55,"",L55/M55) -> 1714800 | O55: =EDATE(K55, M55-1) -> 46147
A56: =SUBTOTAL(3,$B$2:B56) -> 55 | B56: 46143 | C56: PT | D56: CP năng lượng/ nhiên liệu | E56: Tiền dầu | F56: Tiền dầu | G56: CP phát sinh hàng tháng | H56: 29H88546 | I56: Solati | J56: 8718 | K56: 46147 | L56: 1947298 | M56: 1 | N56: =IF(B56>O56,"",L56/M56) -> 1947298 | O56: =EDATE(K56, M56-1) -> 46147
A57: =SUBTOTAL(3,$B$2:B57) -> 56 | B57: 46143 | C57: PT | D57: CP năng lượng/ nhiên liệu | E57: Tiền dầu | F57: Tiền dầu | G57: CP phát sinh hàng tháng | H57: 29H88577 | I57: Solati | J57: 10100 | K57: 46149 | L57: 1714800 | M57: 1 | N57: =IF(B57>O57,"",L57/M57) -> 1714800 | O57: =EDATE(K57, M57-1) -> 46149
A58: =SUBTOTAL(3,$B$2:B58) -> 57 | B58: 46143 | C58: PT | D58: CP năng lượng/ nhiên liệu | E58: Tiền dầu | F58: Tiền dầu | G58: CP phát sinh hàng tháng | H58: 29H88546 | I58: Solati | J58: 8718 | K58: 46150 | L58: 1672800 | M58: 1 | N58: =IF(B58>O58,"",L58/M58) -> 1672800 | O58: =EDATE(K58, M58-1) -> 46150
A59: =SUBTOTAL(3,$B$2:B59) -> 58 | B59: 46143 | C59: PT | D59: CP năng lượng/ nhiên liệu | E59: Tiền dầu | F59: Tiền dầu | G59: CP phát sinh hàng tháng | H59: 29H88577 | I59: Solati | J59: 10100 | K59: 46150 | L59: 1672800 | M59: 1 | N59: =IF(B59>O59,"",L59/M59) -> 1672800 | O59: =EDATE(K59, M59-1) -> 46150
A60: =SUBTOTAL(3,$B$2:B60) -> 59 | B60: 46143 | C60: PT | D60: CP năng lượng/ nhiên liệu | E60: Tiền dầu | F60: Tiền dầu | G60: CP phát sinh hàng tháng | H60: 29H88546 | I60: Solati | J60: 8718 | K60: 46151 | L60: 1812200 | M60: 1 | N60: =IF(B60>O60,"",L60/M60) -> 1812200 | O60: =EDATE(K60, M60-1) -> 46151
...

Sheet Đơn giá SCBD
A1: Stt | B1: Khoản mục | C1: Định mức thay/trích trước | D1: Đơn giá (đồng) | E1: Định ngạch sử dụng (km) | F1: Đơn giá chi phí (đ/km)
A2: CP thay dầu, nhớt | B2: Ford | C2: 9.5 | D2: 135000 | E2: 10000 | F2: =C2*D2/E2 -> 128.25
A3: CP thay dầu, nhớt | B3: Solati | C3: 7.5 | D3: 135000 | E3: 10000 | F3: =C3*D3/E3 -> 101.25
A4: CP thay dầu, nhớt | B4: Suzu | C4: 4 | D4: 140000 | E4: 10000 | F4: =C4*D4/E4 -> 56
A5: CP thay dầu, nhớt | B5: Vf6 | C5: 0
A6: CP thay lốp | B6: Ford | C6: 4 | D6: 2635000 | E6: 100000 | F6: =C6*D6/E6 -> 105.4 | G6: Lốp theo xe
A7: CP thay lốp | B7: Solati | C7: 4 | D7: 2635000 | E7: 100000 | F7: =C7*D7/E7 -> 105.4 | G7: Bridgestone
A8: CP thay lốp | B8: Suzu | C8: 4 | D8: 1360000 | E8: 80000 | F8: =C8*D8/E8 -> 68
A9: CP thay lốp | B9: Vf6 | C9: 4 | D9: 3600000 | E9: 80000 | F9: =C9*D9/E9 -> 180
A10: CP thay ắc quy | B10: Ford | C10: 1 | D10: 1850000 | E10: 100000 | F10: =C10*D10/E10 -> 18.5
A11: CP thay ắc quy | B11: Solati | C11: 1 | D11: 2950000 | E11: 100000 | F11: =C11*D11/E11 -> 29.5
A12: CP thay ắc quy | B12: Suzu | C12: 1 | D12: 1650000 | E12: 100000 | F12: =C12*D12/E12 -> 16.5
A13: CP thay ắc quy | B13: Vf6 | C13: 1 | D13: 1850000 | E13: 100000 | F13: =C13*D13/E13 -> 18.5
A14: CP bảo dưỡng | B14: Ford | C14: 0.1 | D14: 12930133 | E14: 5000 | F14: =D14*C14/E14 -> 258.60267
A15: CP bảo dưỡng | B15: Solati | C15: 0.1 | D15: 12930133 | E15: 5000 | F15: =D15*C15/E15 -> 258.60267
A16: CP bảo dưỡng | B16: Suzu | C16: 0.08 | D16: 12930133 | E16: 5000 | F16: =D16*C16/E16 -> 206.88213
A17: CP bảo dưỡng | B17: Vf6 | C17: 0.05 | D17: 11590909 | E17: 5000 | F17: =D17*C17/E17 -> 115.90909

Sheet Doanh thu CN
A1: THÁNG | B1: TỈNH | C1: SẢN LƯỢNG HK | D1: SỐ LƯỢNG PHƯƠNG TIỆN QUẢN LÝ
A2: 46143 | B2: PT | C2: =14393-1072-987 -> 12334 | D2: 28
