Workbook

Sheet Tóm tắt CP
A1: Tháng | B1: (All)
A3: Row Labels | B3: Sum of Chi phí khấu trừ quỹ lương tháng
A4: CP BD, SC trích trước | B4: 25917510
A5: CP liên quan đến khấu hao PT | B5: 3.0189996e+08
A6: CP mua sắm TTB VP | B6: 528257.75
A7: CP năng lượng/ nhiên liệu | B7: 115937852
A8: CP quản lý khác | B8: 9131852
A9: CP vận hành khác | B9: 5289900
A10: Grand Total | B10: 4.5870533e+08

Sheet Chi tiết
A1: STT | B1: Tháng | C1: Tỉnh | D1: Nhóm CP | E1: Hạng mục chi | F1: Diễn giải chi tiết | G1: Tính chất chi phí | H1: Đối tượng theo dõi (BSX) | I1: Phân loại phương tiện/ Chức danh nhân sự | J1: KM hoạt động | K1: Ngày phát sinh chi phí | L1: Tổng số tiền (VNĐ) | M1: Số tháng khấu hao | N1: Chi phí khấu trừ quỹ lương tháng | O1: Tháng tính khấu hao cuối cùng | P1: Ghi chú
A2: =SUBTOTAL(3,$B$2:B2) -> 1 | B2: 46143 | C2: NĐ | D2: CP liên quan đến khấu hao PT | E2: Mua xe trung chuyển | F2: CP mua xe mới | G2: Mua 1 lần, tính khấu hao hàng tháng | H2: 29K00496 | I2: Ford | K2: 45408 | L2: 7.75808e+08 | M2: 60 | N2: =IF(B2>O2,"",L2/M2) -> 12930133 | O2: =EDATE(K2, M2-1) -> 47203
A3: =SUBTOTAL(3,$B$2:B3) -> 2 | B3: 46143 | C3: NĐ | D3: CP liên quan đến khấu hao PT | E3: Mua xe trung chuyển | F3: CP mua xe mới | G3: Mua 1 lần, tính khấu hao hàng tháng | H3: 29K00498 | I3: Ford | K3: 45408 | L3: 7.75808e+08 | M3: 60 | N3: =IF(B3>O3,"",L3/M3) -> 12930133 | O3: =EDATE(K3, M3-1) -> 47203
A4: =SUBTOTAL(3,$B$2:B4) -> 3 | B4: 46143 | C4: NĐ | D4: CP liên quan đến khấu hao PT | E4: Mua xe trung chuyển | F4: CP mua xe mới | G4: Mua 1 lần, tính khấu hao hàng tháng | H4: 30L15572 | I4: Vf6 | K4: 45530 | L4: 785000000 | M4: 60 | N4: =IF(B4>O4,"",L4/M4) -> 13083333 | O4: =EDATE(K4, M4-1) -> 47325
A5: =SUBTOTAL(3,$B$2:B5) -> 4 | B5: 46143 | C5: NĐ | D5: CP liên quan đến khấu hao PT | E5: Mua xe trung chuyển | F5: CP mua xe mới | G5: Mua 1 lần, tính khấu hao hàng tháng | H5: 30L28391 | I5: Vf6 | K5: 45530 | L5: 785000000 | M5: 60 | N5: =IF(B5>O5,"",L5/M5) -> 13083333 | O5: =EDATE(K5, M5-1) -> 47325
A6: =SUBTOTAL(3,$B$2:B6) -> 5 | B6: 46143 | C6: NĐ | D6: CP liên quan đến khấu hao PT | E6: Mua xe trung chuyển | F6: CP mua xe mới | G6: Mua 1 lần, tính khấu hao hàng tháng | H6: 30L28310 | I6: Vf6 | K6: 45530 | L6: 785000000 | M6: 60 | N6: =IF(B6>O6,"",L6/M6) -> 13083333 | O6: =EDATE(K6, M6-1) -> 47325
A7: =SUBTOTAL(3,$B$2:B7) -> 6 | B7: 46143 | C7: NĐ | D7: CP liên quan đến khấu hao PT | E7: Mua xe trung chuyển | F7: CP mua xe mới | G7: Mua 1 lần, tính khấu hao hàng tháng | H7: 30L28412 | I7: Vf6 | K7: 45530 | L7: 785000000 | M7: 60 | N7: =IF(B7>O7,"",L7/M7) -> 13083333 | O7: =EDATE(K7, M7-1) -> 47325
A8: =SUBTOTAL(3,$B$2:B8) -> 7 | B8: 46143 | C8: NĐ | D8: CP liên quan đến khấu hao PT | E8: Mua xe trung chuyển | F8: CP mua xe mới | G8: Mua 1 lần, tính khấu hao hàng tháng | H8: 30E44501 | I8: Vf6 | K8: 45530 | L8: 785000000 | M8: 60 | N8: =IF(B8>O8,"",L8/M8) -> 13083333 | O8: =EDATE(K8, M8-1) -> 47325
A9: =SUBTOTAL(3,$B$2:B9) -> 8 | B9: 46143 | C9: NĐ | D9: CP liên quan đến khấu hao PT | E9: Mua xe trung chuyển | F9: CP mua xe mới | G9: Mua 1 lần, tính khấu hao hàng tháng | H9: 30L28164 | I9: Vf6 | K9: 45530 | L9: 785000000 | M9: 60 | N9: =IF(B9>O9,"",L9/M9) -> 13083333 | O9: =EDATE(K9, M9-1) -> 47325
A10: =SUBTOTAL(3,$B$2:B10) -> 9 | B10: 46143 | C10: NĐ | D10: CP liên quan đến khấu hao PT | E10: Mua xe trung chuyển | F10: CP mua xe mới | G10: Mua 1 lần, tính khấu hao hàng tháng | H10: 30L28227 | I10: Vf6 | K10: 45530 | L10: 785000000 | M10: 60 | N10: =IF(B10>O10,"",L10/M10) -> 13083333 | O10: =EDATE(K10, M10-1) -> 47325
A11: =SUBTOTAL(3,$B$2:B11) -> 10 | B11: 46143 | C11: NĐ | D11: CP liên quan đến khấu hao PT | E11: Mua xe trung chuyển | F11: CP mua xe mới | G11: Mua 1 lần, tính khấu hao hàng tháng | H11: 30L28487 | I11: Vf6 | K11: 45530 | L11: 785000000 | M11: 60 | N11: =IF(B11>O11,"",L11/M11) -> 13083333 | O11: =EDATE(K11, M11-1) -> 47325
A12: =SUBTOTAL(3,$B$2:B12) -> 11 | B12: 46143 | C12: NĐ | D12: CP liên quan đến khấu hao PT | E12: Mua xe trung chuyển | F12: CP mua xe mới | G12: Mua 1 lần, tính khấu hao hàng tháng | H12: 30L28152 | I12: Vf6 | K12: 45530 | L12: 785000000 | M12: 60 | N12: =IF(B12>O12,"",L12/M12) -> 13083333 | O12: =EDATE(K12, M12-1) -> 47325
A13: =SUBTOTAL(3,$B$2:B13) -> 12 | B13: 46143 | C13: NĐ | D13: CP liên quan đến khấu hao PT | E13: Mua xe trung chuyển | F13: CP mua xe mới | G13: Mua 1 lần, tính khấu hao hàng tháng | H13: 30L28237 | I13: Vf6 | K13: 45530 | L13: 785000000 | M13: 60 | N13: =IF(B13>O13,"",L13/M13) -> 13083333 | O13: =EDATE(K13, M13-1) -> 47325
... A19: =SUBTOTAL(3,$B$2:B19) -> 18 | B19: 46143 | C19: NĐ | D19: CP liên quan đến khấu hao PT | E19: Mua xe trung chuyển | F19: CP mua xe mới | G19: Mua 1 lần, tính khấu hao hàng tháng | H19: 29K00927 | I19: Vf6 | K19: 45408 | L19: 7.75808e+08 | M19: 60 | N19: =IF(B19>O19,"",L19/M19) -> 12930133 | O19: =EDATE(K19, M19-1) -> 47203
A20: =SUBTOTAL(3,$B$2:B20) -> 19 | B20: 46143 | C20: NĐ | D20: CP liên quan đến khấu hao PT | E20: Mua xe trung chuyển | F20: CP mua xe mới (xe hoán cải từ 11 chỗ lên 16 chỗ) | G20: Mua 1 lần, tính khấu hao hàng tháng | H20: 29K05170 | I20: Solati | K20: 46143 | L20: =535500000 -> 535500000 | M20: 36 | N20: =IF(B20>O20,"",L20/M20) -> 14875000 | O20: =EDATE(K20, M20-1) -> 47209
A21: =SUBTOTAL(3,$B$2:B21) -> 20 | B21: 46143 | C21: NĐ | D21: CP liên quan đến khấu hao PT | E21: Mua xe trung chuyển | F21: CP mua xe mới (xe hoán cải từ 11 chỗ lên 16 chỗ) | G21: Mua 1 lần, tính khấu hao hàng tháng | H21: 29K05144 | I21: Solati | K21: 46143 | L21: =535500000 -> 535500000 | M21: 36 | N21: =IF(B21>O21,"",L21/M21) -> 14875000 | O21: =EDATE(K21, M21-1) -> 47209
A22: =SUBTOTAL(3,$B$2:B22) -> 21 | B22: 46143 | C22: NĐ | D22: CP liên quan đến khấu hao PT | E22: Mua xe trung chuyển | F22: CP mua xe mới (xe hoán cải từ 11 chỗ lên 16 chỗ) | G22: Mua 1 lần, tính khấu hao hàng tháng | H22: 29K05187 | I22: Solati | K22: 46143 | L22: =535500000 -> 535500000 | M22: 36 | N22: =IF(B22>O22,"",L22/M22) -> 14875000 | O22: =EDATE(K22, M22-1) -> 47209
A23: =SUBTOTAL(3,$B$2:B23) -> 22 | B23: 46143 | C23: NĐ | D23: CP liên quan đến khấu hao PT | E23: CP mua BH | F23: BH vật chất và BH TNDS | G23: Mua 1 lần, tính khấu hao hàng tháng | H23: 30L15572 | I23: Vf6 | K23: 45895 | L23: 7322000 | M23: 12 | N23: =IF(B23>O23,"",L23/M23) -> 610166.67 | O23: =EDATE(K23, M23-1) -> 46229
A24: =SUBTOTAL(3,$B$2:B24) -> 23 | B24: 46143 | C24: NĐ | D24: CP liên quan đến khấu hao PT | E24: CP mua BH | F24: BH vật chất và BH TNDS | G24: Mua 1 lần, tính khấu hao hàng tháng | H24: 30L28391 | I24: Vf6 | K24: 45895 | L24: 7322000 | M24: 12 | N24: =IF(B24>O24,"",L24/M24) -> 610166.67 | O24: =EDATE(K24, M24-1) -> 46229
A25: =SUBTOTAL(3,$B$2:B25) -> 24 | B25: 46143 | C25: NĐ | D25: CP liên quan đến khấu hao PT | E25: CP mua BH | F25: BH vật chất và BH TNDS | G25: Mua 1 lần, tính khấu hao hàng tháng | H25: 30L28310 | I25: Vf7 | K25: 45895 | L25: 7322000 | M25: 12 | N25: =IF(B25>O25,"",L25/M25) -> 610166.67 | O25: =EDATE(K25, M25-1) -> 46229
A26: =SUBTOTAL(3,$B$2:B26) -> 25 | B26: 46143 | C26: NĐ | D26: CP liên quan đến khấu hao PT | E26: CP mua BH | F26: BH vật chất và BH TNDS | G26: Mua 1 lần, tính khấu hao hàng tháng | H26: 30L28412 | I26: Vf6 | K26: 45895 | L26: 7322000 | M26: 12 | N26: =IF(B26>O26,"",L26/M26) -> 610166.67 | O26: =EDATE(K26, M26-1) -> 46229
A27: =SUBTOTAL(3,$B$2:B27) -> 26 | B27: 46143 | C27: NĐ | D27: CP liên quan đến khấu hao PT | E27: CP mua BH | F27: BH vật chất và BH TNDS | G27: Mua 1 lần, tính khấu hao hàng tháng | H27: 30E44501 | I27: Vf6 | K27: 45895 | L27: 7322000 | M27: 12 | N27: =IF(B27>O27,"",L27/M27) -> 610166.67 | O27: =EDATE(K27, M27-1) -> 46229
A28: =SUBTOTAL(3,$B$2:B28) -> 27 | B28: 46143 | C28: NĐ | D28: CP liên quan đến khấu hao PT | E28: CP mua BH | F28: BH vật chất và BH TNDS | G28: Mua 1 lần, tính khấu hao hàng tháng | H28: 30L28164 | I28: Vf6 | K28: 45895 | L28: 7322000 | M28: 12 | N28: =IF(B28>O28,"",L28/M28) -> 610166.67 | O28: =EDATE(K28, M28-1) -> 46229
A29: =SUBTOTAL(3,$B$2:B29) -> 28 | B29: 46143 | C29: NĐ | D29: CP liên quan đến khấu hao PT | E29: CP mua BH | F29: BH vật chất và BH TNDS | G29: Mua 1 lần, tính khấu hao hàng tháng | H29: 30L28227 | I29: Vf6 | K29: 45895 | L29: 7322000 | M29: 12 | N29: =IF(B29>O29,"",L29/M29) -> 610166.67 | O29: =EDATE(K29, M29-1) -> 46229
A30: =SUBTOTAL(3,$B$2:B30) -> 29 | B30: 46143 | C30: NĐ | D30: CP liên quan đến khấu hao PT | E30: CP mua BH | F30: BH vật chất và BH TNDS | G30: Mua 1 lần, tính khấu hao hàng tháng | H30: 30L28487 | I30: Vf6 | K30: 45895 | L30: 7322000 | M30: 12 | N30: =IF(B30>O30,"",L30/M30) -> 610166.67 | O30: =EDATE(K30, M30-1) -> 46229
A31: =SUBTOTAL(3,$B$2:B31) -> 30 | B31: 46143 | C31: NĐ | D31: CP liên quan đến khấu hao PT | E31: CP mua BH | F31: BH vật chất và BH TNDS | G31: Mua 1 lần, tính khấu hao hàng tháng | H31: 30L28152 | I31: Vf6 | K31: 45895 | L31: 7322000 | M31: 12 | N31: =IF(B31>O31,"",L31/M31) -> 610166.67 | O31: =EDATE(K31, M31-1) -> 46229
A32: =SUBTOTAL(3,$B$2:B32) -> 31 | B32: 46143 | C32: NĐ | D32: CP liên quan đến khấu hao PT | E32: CP mua BH | F32: BH vật chất và BH TNDS | G32: Mua 1 lần, tính khấu hao hàng tháng | H32: 30L28237 | I32: Vf6 | K32: 45895 | L32: 7322000 | M32: 12 | N32: =IF(B32>O32,"",L32/M32) -> 610166.67 | O32: =EDATE(K32, M32-1) -> 46229
A33: =SUBTOTAL(3,$B$2:B33) -> 32 | B33: 46143 | C33: NĐ | D33: CP liên quan đến khấu hao PT | E33: CP mua BH | F33: BH vật chất và BH TNDS | G33: Mua 1 lần, tính khấu hao hàng tháng | H33: 29K00496 | I33: Ford | K33: 46113 | L33: 11544000 | M33: 12 | N33: =IF(B33>O33,"",L33/M33) -> 962000 | O33: =EDATE(K33, M33-1) -> 46447
A34: =SUBTOTAL(3,$B$2:B34) -> 33 | B34: 46143 | C34: NĐ | D34: CP liên quan đến khấu hao PT | E34: CP mua BH | F34: BH vật chất và BH TNDS | G34: Mua 1 lần, tính khấu hao hàng tháng | H34: 29K00498 | I34: Ford | K34: 46113 | L34: 11544000 | M34: 12 | N34: =IF(B34>O34,"",L34/M34) -> 962000 | O34: =EDATE(K34, M34-1) -> 46447
... A115: =SUBTOTAL(3,$B$2:B115) -> 114 | B115: 46143 | C115: NĐ | D115: CP liên quan đến khấu hao PT | E115: Mua thiết bị lắp thêm | F115: Mua sim 5G | G115: Mua 1 lần, tính khấu hao hàng tháng | H115: 29K00927 | I115: Ford | K115: 46113 | L115: 700000 | M115: 12 | N115: =IF(B115>O115,"",L115/M115) -> 58333.333 | O115: =EDATE(K115, M115-1) -> 46447
A116: =SUBTOTAL(3,$B$2:B116) -> 115 | B116: 46143 | C116: NĐ | D116: CP mua sắm TTB VP | E116: Trang thiết bị VP | F116: Công lắp đặt điều hoà (HĐ số 128 ngày 07/05) (Phân bổ 24 tháng từ tháng 5/2024) | G116: Mua 1 lần, tính khấu hao hàng tháng | K116: 45413 | L116: 7440000 | M116: 24 | N116: =IF(B116>O116,"",L116/M116) | O116: =EDATE(K116, M116-1) -> 46113
A117: =SUBTOTAL(3,$B$2:B117) -> 116 | B117: 46143 | C117: NĐ | D117: CP mua sắm TTB VP | E117: Trang thiết bị VP | F117: Chi tiền mua 2 điều hòa Casper (Phân bổ 24 tháng từ tháng 5/2024) | G117: Mua 1 lần, tính khấu hao hàng tháng | K117: 45413 | L117: 18800000 | M117: 24 | N117: =IF(B117>O117,"",L117/M117) | O117: =EDATE(K117, M117-1) -> 46113
A118: =SUBTOTAL(3,$B$2:B118) -> 117 | B118: 46143 | C118: NĐ | D118: CP mua sắm TTB VP | E118: Trang thiết bị VP | F118: Hạch toán mua máy tính cho điều hành | G118: Mua 1 lần, tính khấu hao hàng tháng | K118: 45566 | L118: 8993000 | M118: 24 | N118: =IF(B118>O118,"",L118/M118) -> 374708.33 | O118: =EDATE(K118, M118-1) -> 46266
A119: =SUBTOTAL(3,$B$2:B119) -> 118 | B119: 46143 | C119: NĐ | D119: CP mua sắm TTB VP | E119: Trang thiết bị VP | F119: Hạch toán cây nước nóng lạnh Sunhouse SHD9546 - VP Nam Định | G119: Mua 1 lần, tính khấu hao hàng tháng | K119: 45962 | L119: 1842593 | M119: 12 | N119: =IF(B119>O119,"",L119/M119) -> 153549.42 | O119: =EDATE(K119, M119-1) -> 46296
A120: =SUBTOTAL(3,$B$2:B120) -> 119 | B120: 46143 | C120: NĐ | D120: CP BD, SC trích trước | E120: BD, SC PT | F120: CP thay dầu, nhớt | G120: CP trích trước hàng tháng | H120: 29K00496 | I120: Ford | J120: =VLOOKUP(H120,'KM sử dụng T5'!A:H,8,0) -> 3064.95 | K120: 46143 | L120: =J120*SUMIFS('Đơn giá SCBD'!F:F,'Đơn giá SCBD'!A:A,'Chi tiết'!F120,'Đơn giá SCBD'!B:B,'Chi tiết'!I120) -> 393079.84 | M120: 1 | N120: =IF(B120>O120,"",L120/M120) -> 393079.84 | O120: =EDATE(K120, M120-1) -> 46143
A121: =SUBTOTAL(3,$B$2:B121) -> 120 | B121: 46143 | C121: NĐ | D121: CP BD, SC trích trước | E121: BD, SC PT | F121: CP thay dầu, nhớt | G121: CP trích trước hàng tháng | H121: 29K00498 | I121: Ford | J121: =VLOOKUP(H121,'KM sử dụng T5'!A:H,8,0) -> 2453 | K121: 46143 | L121: =J121*SUMIFS('Đơn giá SCBD'!F:F,'Đơn giá SCBD'!A:A,'Chi tiết'!F121,'Đơn giá SCBD'!B:B,'Chi tiết'!I121) -> 314597.25 | M121: 1 | N121: =IF(B121>O121,"",L121/M121) -> 314597.25 | O121: =EDATE(K121, M121-1) -> 46143
A122: =SUBTOTAL(3,$B$2:B122) -> 121 | B122: 46143 | C122: NĐ | D122: CP BD, SC trích trước | E122: BD, SC PT | F122: CP thay dầu, nhớt | G122: CP trích trước hàng tháng | H122: 29K00927 | I122: Ford | J122: =VLOOKUP(H122,'KM sử dụng T5'!A:H,8,0) -> 1487 | K122: 46143 | L122: =J122*SUMIFS('Đơn giá SCBD'!F:F,'Đơn giá SCBD'!A:A,'Chi tiết'!F122,'Đơn giá SCBD'!B:B,'Chi tiết'!I122) -> 190707.75 | M122: 1 | N122: =IF(B122>O122,"",L122/M122) -> 190707.75 | O122: =EDATE(K122, M122-1) -> 46143
A123: =SUBTOTAL(3,$B$2:B123) -> 122 | B123: 46143 | C123: NĐ | D123: CP BD, SC trích trước | E123: BD, SC PT | F123: CP thay dầu, nhớt | G123: CP trích trước hàng tháng | H123: 29K05170 | I123: Solati | J123: =VLOOKUP(H123,'KM sử dụng T5'!A:H,8,0) -> 1818.57 | K123: 46143 | L123: =J123*SUMIFS('Đơn giá SCBD'!F:F,'Đơn giá SCBD'!A:A,'Chi tiết'!F123,'Đơn giá SCBD'!B:B,'Chi tiết'!I123) -> 184130.21 | M123: 1 | N123: =IF(B123>O123,"",L123/M123) -> 184130.21 | O123: =EDATE(K123, M123-1) -> 46143
A124: =SUBTOTAL(3,$B$2:B124) -> 123 | B124: 46143 | C124: NĐ | D124: CP BD, SC trích trước | E124: BD, SC PT | F124: CP thay dầu, nhớt | G124: CP trích trước hàng tháng | H124: 29K05144 | I124: Solati | J124: =VLOOKUP(H124,'KM sử dụng T5'!A:H,8,0) -> 2432.14 | K124: 46143 | L124: =J124*SUMIFS('Đơn giá SCBD'!F:F,'Đơn giá SCBD'!A:A,'Chi tiết'!F124,'Đơn giá SCBD'!B:B,'Chi tiết'!I124) -> 246254.18 | M124: 1 | N124: =IF(B124>O124,"",L124/M124) -> 246254.18 | O124: =EDATE(K124, M124-1) -> 46143
A125: =SUBTOTAL(3,$B$2:B125) -> 124 | B125: 46143 | C125: NĐ | D125: CP BD, SC trích trước | E125: BD, SC PT | F125: CP thay dầu, nhớt | G125: CP trích trước hàng tháng | H125: 29K05187 | I125: Solati | J125: =VLOOKUP(H125,'KM sử dụng T5'!A:H,8,0) -> 2838.37 | K125: 46143 | L125: =J125*SUMIFS('Đơn giá SCBD'!F:F,'Đơn giá SCBD'!A:A,'Chi tiết'!F125,'Đơn giá SCBD'!B:B,'Chi tiết'!I125) -> 287384.96 | M125: 1 | N125: =IF(B125>O125,"",L125/M125) -> 287384.96 | O125: =EDATE(K125, M125-1) -> 46143
...

Sheet Doanh thu CN
A1: THÁNG | B1: TỈNH | C1: SẢN LƯỢNG HK | D1: SỐ LƯỢNG PHƯƠNG TIỆN QUẢN LÝ
A2: 46143 | B2: NĐ | C2: 40125 | D2: 65 | H2: Số khách: | I2: 40746
H3: Khách nguyên chuyến: | I3: 173
H4: khách TB ghép NĐ: | I4: 15
H5: Khách NĐ ghép TB: | I5: 10 | M5: =I2-I3-I4+I5-I6 -> 40125 | N5: Tổng số KH
H6: khách chênh lệch dthu | I6: 443

Sheet KM sử dụng T5
A1: BKS | B1: Loại xe | C1: Năm sản xuất | D1: Định biên | E1: Đơn vị sử dụng cuối tháng 5/2026 | F1: Km đầu tháng | G1: Km cuối tháng | H1: Km sử dụng trong tháng | I1: Km Skysoft/DSS | J1: Chênh lệch | K1: Họ và tên | L1: Xe tuyến/ Xe Trung chuyển
A2: 30E44501 | B2: Vinfast VF6S | C2: 2024 | D2: Nam Định | E2: Nam Định | F2: 94055 | G2: 99564 | H2: 5509 | I2: 5569.369 | J2: -60.369 | K2: Trần Ngọc Ánh | L2: Xe Trung chuyển | N2: 3811.361 | O2: =+N2-H2 -> -1697.639
A3: 30L15572 | B3: Vinfast VF6S | C3: 2024 | D3: Nam Định | E3: Nam Định | F3: 91656 | G3: 96572 | H3: 4916 | I3: 4852.629 | J3: 63.371 | K3: Trần Ngọc Ánh | L3: Xe Trung chuyển | N3: 4900 | O3: =+N3-H3 -> -16
A4: 30L28152 | B4: Vinfast VF6S | C4: 2024 | D4: Nam Định | E4: Nam Định | F4: 63075 | G4: 66139 | H4: 3064 | I4: 3072.195 | J4: -8.195 | K4: Trần Ngọc Ánh | L4: Xe Trung chuyển | N4: 2707 | O4: =+N4-H4 -> -357
A5: 30L28164 | B5: Vinfast VF6S | C5: 2024 | D5: Nam Định | E5: Nam Định | F5: 79569 | G5: 84399 | H5: 4830 | I5: 4845.171 | J5: -15.171 | K5: Trần Ngọc Ánh | L5: Xe Trung chuyển | N5: 4613 | O5: =+N5-H5 -> -217
A6: 30L28227 | B6: Vinfast VF6S | C6: 2024 | D6: Nam Định | E6: Nam Định | F6: 77315 | G6: 81468 | H6: 4153 | I6: 4118.893 | J6: 34.107 | K6: Trần Ngọc Ánh | L6: Xe Trung chuyển | N6: 4053 | O6: =+N6-H6 -> -100
A7: 30L28237 | B7: Vinfast VF6S | C7: 2024 | D7: Nam Định | E7: Nam Định | F7: 73268.33 | G7: 73925 | H7: 656.67 | I7: 633.897 | J7: 22.773 | K7: Trần Ngọc Ánh | L7: Xe Trung chuyển | N7: 1379.33 | O7: =+N7-H7 -> 722.66
A8: 30L28310 | B8: Vinfast VF6S | C8: 2024 | D8: Nam Định | E8: Nam Định | F8: 87190 | G8: 91704 | H8: 4514 | I8: 4519.982 | J8: -5.982 | K8: Trần Ngọc Ánh | L8: Xe Trung chuyển | N8: 3586 | O8: =+N8-H8 -> -928
A9: 30L28391 | B9: Vinfast VF6S | C9: 2024 | D9: Nam Định | E9: Nam Định | F9: 75339 | G9: 78736 | H9: 3397 | I9: 3374.689 | J9: 22.311 | K9: Trần Ngọc Ánh | L9: Xe Trung chuyển | N9: 4835 | O9: =+N9-H9 -> 1438
A10: 30L28412 | B10: Vinfast VF6S | C10: 2024 | D10: Nam Định | E10: Nam Định | F10: 61633 | G10: 64861 | H10: 3228 | I10: 3217.668 | J10: 10.332 | K10: Trần Ngọc Ánh | L10: Xe Trung chuyển | N10: 3742 | O10: =+N10-H10 -> 514
A11: 30L28487 | B11: Vinfast VF6S | C11: 2024 | D11: Nam Định | E11: Nam Định | F11: 75088 | G11: 78305 | H11: 3217 | I11: 3224.976 | J11: -7.976 | K11: Trần Ngọc Ánh | L11: Xe Trung chuyển | N11: 4455 | O11: =+N11-H11 -> 1238
A12: 29B30798 | B12: Vinfast VF6S | C12: 2025 | D12: Nam Định | E12: Nam Định | F12: 69560 | G12: 74678 | H12: 5118 | I12: 5188.75 | J12: -70.75 | K12: Trần Ngọc Ánh | L12: Xe Trung chuyển | N12: 4471.489 | O12: =+N12-H12 -> -646.511
A13: 29B30595 | B13: Vinfast VF6S | C13: 2025 | D13: Nam Định | E13: Nam Định | F13: 67716 | G13: 72407 | H13: 4691 | I13: 4598.414 | J13: 92.586 | K13: Trần Ngọc Ánh | L13: Xe Trung chuyển | N13: 5140 | O13: =+N13-H13 -> 449
... A19: 29K00927 | B19: Xe Ford- 16 chỗ | C19: 2024 | D19: Nam Định | E19: Nam Định | F19: 100650 | G19: 102137 | H19: 1487 | I19: 1499.225 | J19: -12.225 | K19: Trần Ngọc Ánh | L19: Xe Trung chuyển | N19: 3479 | O19: =+N19-H19 -> 1992
A20: 29K05170 | B20: Huyndai Solati | C20: 2019 | D20: Nam Định | E20: Nam Định | F20: 556326.43 | G20: 558145 | H20: 1818.57 | I20: 1351.708 | J20: 466.862 | K20: Trần Ngọc Ánh | L20: Xe Trung chuyển
A21: 29K05144 | B21: Huyndai Solati | C21: 2019 | D21: Nam Định | E21: Nam Định | F21: 554952.86 | G21: 557385 | H21: 2432.14 | I21: 2080.603 | J21: 351.537 | K21: Trần Ngọc Ánh | L21: Xe Trung chuyển
A22: 29K05187 | B22: Huyndai Solati | C22: 2019 | D22: Nam Định | E22: Nam Định | F22: 540228.63 | G22: 543067 | H22: 2838.37 | I22: 2767.671 | J22: 70.699 | K22: Trần Ngọc Ánh | L22: Xe Trung chuyển

Sheet Đơn giá SCBD
A1: Stt | B1: Khoản mục | C1: Định mức thay/trích trước | D1: Đơn giá (đồng) | E1: Định ngạch sử dụng (km) | F1: Đơn giá chi phí (đ/km)
A2: CP thay dầu, nhớt | B2: Ford | C2: 9.5 | D2: 135000 | E2: 10000 | F2: =C2*D2/E2 -> 128.25
A3: CP thay dầu, nhớt | B3: Solati | C3: 7.5 | D3: 135000 | E3: 10000 | F3: =C3*D3/E3 -> 101.25
A4: CP thay dầu, nhớt | B4: Suzu | C4: 4 | D4: 140000 | E4: 10000 | F4: =C4*D4/E4 -> 56
A5: CP thay dầu, nhớt | B5: Vf6 | C5: 0
A6: CP thay lốp | B6: Ford | C6: 4 | D6: 2635000 | E6: 100000 | F6: =C6*D6/E6 -> 105.4 | G6: Lốp theo xe
A7: CP thay lốp | B7: Solati | C7: 4 | D7: 2635000 | E7: 100000 | F7: =C7*D7/E7 -> 105.4 | G7: Bridgestone
A8: CP thay lốp | B8: Suzu | C8: 4 | D8: 1360000 | E8: 80000 | F8: =C8*D8/E8 -> 68
A9: CP thay lốp | B9: Vf6 | C9: 4 | D9: 3600000 | E9: 80000 | F9: =C9*D9/E9 -> 180
A10: CP thay ắc quy | B10: Ford | C10: 1 | D10: 1850000 | E10: 100000 | F10: =C10*D10/E10 -> 18.5
A11: CP thay ắc quy | B11: Solati | C11: 1 | D11: 2950000 | E11: 100000 | F11: =C11*D11/E11 -> 29.5
A12: CP thay ắc quy | B12: Suzu | C12: 1 | D12: 1650000 | E12: 100000 | F12: =C12*D12/E12 -> 16.5
A13: CP thay ắc quy | B13: Vf6 | C13: 1 | D13: 1850000 | E13: 100000 | F13: =C13*D13/E13 -> 18.5
A14: CP bảo dưỡng | B14: Ford | C14: 0.1 | D14: 12930133 | E14: 5000 | F14: =D14*C14/E14 -> 258.60267
A15: CP bảo dưỡng | B15: Solati | C15: 0.1 | D15: 12930133 | E15: 5000 | F15: =D15*C15/E15 -> 258.60267
A16: CP bảo dưỡng | B16: Suzu | C16: 0.08 | D16: 12930133 | E16: 5000 | F16: =D16*C16/E16 -> 206.88213
A17: CP bảo dưỡng | B17: Vf6 | C17: 0.05 | D17: 11590909 | E17: 5000 | F17: =D17*C17/E17 -> 115.90909

Sheet VPP
A1: STT | B1: Ngày | C1: Tháng | D1: Năm | E1: Hướng nhập/xuất | F1: Chứng từ Nhập/xuất | G1: Chứng từ Xuất | H1: Nhóm VT | I1: Mã VT | J1: Tên vật tư | K1: Đơn vị | L1: Số lượng nhập | M1: Đơn giá nhập | N1: Thành tiền nhập | O1: Số lượng xuất | P1: Đơn giá xuất | Q1: Thành tiền xuất | R1: Bộ phận/ Phòng ban | S1: Người nhận
A2: 1038 | B2: 46152 | C2: 5 | D2: 2026 | G2: PX919 | H2: VPP | I2: VPP91 | J2: Giấy vệ sinh công nghiệp | K2: Kg | N2: 0 | O2: 9 | P2: 25920 | Q2: 233280 | R2: VP 85 Nam Định | S2: Lễ tân
A3: 1040 | B3: 46152 | C3: 5 | D3: 2026 | G3: PX833 | H3: VPP | I3: VPP83 | J3: Nước lau sàn | K3: Can | N3: 0 | O3: 3 | P3: 75000 | Q3: 225000 | R3: VP 85 Nam Định | S3: Lễ tân
A4: 1041 | B4: 46152 | C4: 5 | D4: 2026 | G4: PX811 | H4: VPP | I4: VPP81 | J4: Nước rửa chén | K4: Lọ | N4: 0 | O4: 1 | P4: 28000 | Q4: 28000 | R4: VP 85 Nam Định | S4: Lễ tân
A5: 998 | B5: 46152 | C5: 5 | D5: 2026 | G5: PX802 | H5: VPP | I5: VPP80 | J5: Nước rửa tay | K5: Lọ | N5: 0 | O5: 2 | P5: 78000 | Q5: 156000 | R5: VP 85 Nam Định | S5: Lễ tân
A6: 1042 | B6: 46152 | C6: 5 | D6: 2026 | G6: PX2201 | H6: VPP | I6: VPP220 | J6: Nước lau kính Gift 500ml | K6: Tệp | N6: 0 | O6: 1 | P6: 23760 | Q6: 23760 | R6: VP 85 Nam Định | S6: Lễ tân
A7: 1043 | B7: 46152 | C7: 5 | D7: 2026 | G7: PX882 | H7: VPP | I7: VPP88 | J7: Nước tẩy vệ sinh Vim | K7: Chai | N7: 0 | O7: 2 | P7: 32400 | Q7: 64800 | R7: VP 85 Nam Định | S7: Lễ tân
A8: 1044 | B8: 46152 | C8: 5 | D8: 2026 | G8: PX373 | H8: VPP | I8: VPP37 | J8: Giấy in A4 | K8: Ram | N8: 0 | O8: 3 | P8: 58000 | Q8: 174000 | R8: VP 85 Nam Định | S8: Lễ tân
A9: 1045 | B9: 46152 | C9: 5 | D9: 2026 | G9: PX383 | H9: VPP | I9: VPP38 | J9: Giấy in A5 | K9: Ram | N9: 0 | O9: 3 | P9: 27491 | Q9: 82473 | R9: VP 85 Nam Định | S9: Lễ tân
A10: 1046 | B10: 46152 | C10: 5 | D10: 2026 | G10: PX1872 | H10: VPP | I10: VPP187 | J10: Túi bóng đen 5kg | K10: Kg | N10: 0 | O10: 2 | P10: 43200 | Q10: 86400 | R10: VP 85 Nam Định | S10: Lễ tân
A11: 1047 | B11: 46152 | C11: 5 | D11: 2026 | G11: PX892 | H11: VPP | I11: VPP89 | J11: Túi đựng rác Size 10 cân | K11: Kg | N11: 0 | O11: 2 | P11: 43200 | Q11: 86400 | R11: VP 85 Nam Định | S11: Lễ tân
A12: 1048 | B12: 46152 | C12: 5 | D12: 2026 | G12: PX1992 | H12: VPP | I12: VPP199 | J12: Túi bóng đen 90*140 | K12: Kg | N12: 0 | O12: 2 | P12: 43200 | Q12: 86400 | R12: VP 85 Nam Định | S12: Lễ tân
A13: 1049 | B13: 46152 | C13: 5 | D13: 2026 | G13: PX1694 | H13: VPP | I13: VPP169 | J13: Túi bóng trắng | K13: Kg | N13: 0 | O13: 4 | P13: 54000 | Q13: 216000 | R13: VP 85 Nam Định | S13: Lễ tân
... A17: 1053 | B17: 46152 | C17: 5 | D17: 2026 | G17: PX265 | H17: VPP | I17: VPP26 | J17: Bút bi xanh nét to 0.7 | K17: Cái | N17: 0 | O17: 5 | P17: 3500 | Q17: 17500 | R17: VP 85 Nam Định | S17: Lễ tân
A18: 1208 | B18: 46152 | C18: 5 | D18: 2026 | G18: PX1732 | H18: VPP | I18: VPP173 | J18: Chổi vệ sinh xe 160cm | K18: Chiếc | O18: 2 | P18: 85000 | Q18: 170000 | R18: VP 85 Nam Định | S18: Lễ tân
Q23: =SUM(Q2:Q22) -> 1778713

Sheet PTQL
A1: TT | B1: BKS | C1: Loại xe | D1: Năm sản xuất | E1: Định biên | F1: Đơn vị sử dụng cuối tháng 5/2026 | G1: Km đầu tháng | H1: Km cuối tháng | I1: Km sử dụng trong tháng | J1: Km Skysoft/DSS | K1: Chênh lệch | L1: Họ và tên | M1: Xe tuyến/ Xe Trung chuyển
A2: 1 | B2: 29E03207 | C2: Huyndai Solati | D2: 2023 | E2: Nam Định | F2: Nam Định | G2: 343695 | H2: 354967 | I2: 11272 | J2: 11155.664 | K2: 116.336 | L2: Phạm Văn Vũ | M2: Xe tuyến
A3: 2 | B3: 29E03463 | C3: Huyndai Solati | D3: 2023 | E3: Nam Định | F3: Nam Định | G3: 341409 | H3: 352343 | I3: 10934 | J3: 10700.646 | K3: 233.354 | L3: Trần Đình Thắng | M3: Xe tuyến
A4: 3 | B4: 29E03468 | C4: Huyndai Solati | D4: 2023 | E4: Nam Định | F4: Nam Định | G4: 350340 | H4: 361503 | I4: 11163 | J4: 11097.828 | K4: 65.172 | L4: Đỗ Tuấn Anh (NĐ) | M4: Xe tuyến
A5: 4 | B5: 29E03480 | C5: Huyndai Solati | D5: 2023 | E5: Nam Định | F5: Nam Định | G5: 322078 | H5: 331598 | I5: 9520 | J5: 9321.214 | K5: 198.786 | L5: Phạm Văn Sớm | M5: Xe tuyến
A6: 5 | B6: 29E07842 | C6: Huyndai Solati | D6: 2023 | E6: Nam Định | F6: Nam Định | G6: 365094 | H6: 376118 | I6: 11024 | J6: 10932.905 | K6: 91.095 | L6: Nguyễn Văn Chiến | M6: Xe tuyến
A7: 6 | B7: 29E74362 | C7: Huyndai Solati | D7: 2022 | E7: Nam Định | F7: Nam Định | G7: 567219 | H7: 570938 | I7: 3719 | J7: 3555.156 | K7: 163.844 | L7: Lê Minh Đức | M7: Xe tuyến
A8: 7 | B8: 29E73314 | C8: Huyndai Solati | D8: 2022 | E8: Nam Định | F8: Nam Định | G8: 555242 | H8: 560711 | I8: 5469 | J8: 5112.623 | K8: 356.377 | L8: Trần Quốc Phong | M8: Xe tuyến
A9: 8 | B9: 29E74062 | C9: Huyndai Solati | D9: 2022 | E9: Nam Định | F9: Nam Định | G9: 576137.89 | H9: 582403 | I9: 6265.11 | J9: 6145.118 | K9: 119.992 | L9: Trần Mạnh Thắng | M9: Xe tuyến
A10: 9 | B10: 29E73531 | C10: Huyndai Solati | D10: 2022 | E10: Nam Định | F10: Nam Định | G10: 552630 | H10: 556664 | I10: 4034 | J10: 3837.013 | K10: 196.987 | L10: Bùi Xuân Bắc | M10: Xe tuyến
A11: 10 | B11: 29E74031 | C11: Huyndai Solati | D11: 2022 | E11: Nam Định | F11: Nam Định | G11: 547583.84 | H11: 551327 | I11: 3743.16 | J11: 3651.904 | K11: 91.256 | L11: Nguyễn Mạnh Cường | M11: Xe tuyến
A12: 11 | B12: 29F02595 | C12: Huyndai Solati | D12: 2023 | E12: Nam Định | F12: Nam Định | G12: 366662 | H12: 376910 | I12: 10248 | J12: 10202.963 | K12: 45.037 | L12: Nguyễn Trung Trọng | M12: Xe tuyến
A13: 12 | B13: 29F02597 | C13: Huyndai Solati | D13: 2023 | E13: Nam Định | F13: Nam Định | G13: 385469 | H13: 395283 | I13: 9814 | J13: 9776.302 | K13: 37.698 | L13: Phạm Văn Chính | M13: Xe tuyến
... A66: 65 | B66: 29G00711 | C66: Huyndai Solati | D66: 2023 | E66: Nam Định | F66: Nam Định | G66: 382448 | H66: 391834 | I66: 9386 | J66: 9193.446 | K66: 192.554 | L66: Cồ Văn Tiển | M66: Xe tuyến
