Workbook

Sheet Tóm tắt CP
A1: Tháng | B1: 46143
A3: Row Labels | B3: Sum of Chi phí khấu trừ quỹ lương tháng
A4: CP BD, SC trích trước | B4: 11035649
A5: CP liên quan đến khấu hao PT | B5: 1.1068907e+08
A6: CP mua sắm TTB VP | B6: 21301.775
A7: CP năng lượng/ nhiên liệu | B7: 43485513
A8: CP quản lý khác | B8: 4522762
A9: Grand Total | B9: 1.697543e+08

Sheet Chi tiết
A1: STT | B1: Tháng | C1: Tỉnh | D1: Nhóm CP | E1: Hạng mục chi | F1: Diễn giải chi tiết | G1: Tính chất chi phí | H1: Đối tượng theo dõi (BSX) | I1: Phân loại phương tiện/ Chức danh nhân sự | J1: KM hoạt động | K1: Ngày phát sinh chi phí | L1: Tổng số tiền (VNĐ) | M1: Số tháng khấu hao | N1: Chi phí khấu trừ quỹ lương tháng | O1: Tháng tính khấu hao cuối cùng | P1: Ghi chú
A2: =SUBTOTAL(3,$B$2:B2) -> 1 | B2: 46143 | C2: VT | D2: CP liên quan đến khấu hao PT | E2: Mua xe trung chuyển | F2: CP mua xe mới | G2: Mua 1 lần, tính khấu hao hàng tháng | H2: 29B19481 | I2: Vf6 | K2: 45722 | L2: 785000000 | M2: 60 | N2: =IF(B2>O2,"",L2/M2) -> 13083333 | O2: =EDATE(K2, M2-1) -> 47520
A3: =SUBTOTAL(3,$B$2:B3) -> 2 | B3: 46143 | C3: VT | D3: CP liên quan đến khấu hao PT | E3: Mua xe trung chuyển | F3: CP mua xe mới | G3: Mua 1 lần, tính khấu hao hàng tháng | H3: 29B30465 | I3: Vf6 | K3: 45722 | L3: 785000000 | M3: 60 | N3: =IF(B3>O3,"",L3/M3) -> 13083333 | O3: =EDATE(K3, M3-1) -> 47520
A4: =SUBTOTAL(3,$B$2:B4) -> 3 | B4: 46143 | C4: VT | D4: CP liên quan đến khấu hao PT | E4: Mua xe trung chuyển | F4: CP mua xe mới | G4: Mua 1 lần, tính khấu hao hàng tháng | H4: 29H02773 | I4: Vf6 | K4: 45722 | L4: 785000000 | M4: 60 | N4: =IF(B4>O4,"",L4/M4) -> 13083333 | O4: =EDATE(K4, M4-1) -> 47520
A5: =SUBTOTAL(3,$B$2:B5) -> 4 | B5: 46143 | C5: VT | D5: CP liên quan đến khấu hao PT | E5: Mua xe trung chuyển | F5: CP mua xe mới | G5: Mua 1 lần, tính khấu hao hàng tháng | H5: 30M36244 | I5: Vf6 | K5: 45854 | L5: 681240000 | M5: 60 | N5: =IF(B5>O5,"",L5/M5) -> 11354000 | O5: =EDATE(K5, M5-1) -> 47650
A6: =SUBTOTAL(3,$B$2:B6) -> 5 | B6: 46143 | C6: VT | D6: CP liên quan đến khấu hao PT | E6: Mua xe trung chuyển | F6: CP mua xe mới | G6: Mua 1 lần, tính khấu hao hàng tháng | H6: 30M36207 | I6: Vf6 | K6: 45854 | L6: 681240000 | M6: 60 | N6: =IF(B6>O6,"",L6/M6) -> 11354000 | O6: =EDATE(K6, M6-1) -> 47650
A7: =SUBTOTAL(3,$B$2:B7) -> 6 | B7: 46143 | C7: VT | D7: CP liên quan đến khấu hao PT | E7: Mua xe trung chuyển | F7: CP mua xe mới | G7: Mua 1 lần, tính khấu hao hàng tháng | H7: 30M36240 | I7: Vf6 | K7: 45854 | L7: 681240000 | M7: 60 | N7: =IF(B7>O7,"",L7/M7) -> 11354000 | O7: =EDATE(K7, M7-1) -> 47650
A8: =SUBTOTAL(3,$B$2:B8) -> 7 | B8: 46143 | C8: VT | D8: CP liên quan đến khấu hao PT | E8: Mua xe trung chuyển | F8: CP mua xe mới | G8: Mua 1 lần, tính khấu hao hàng tháng | H8: 29K01796 | I8: Ford | K8: 45463 | L8: 7.75808e+08 | M8: 60 | N8: =IF(B8>O8,"",L8/M8) -> 12930133 | O8: =EDATE(K8, M8-1) -> 47258
A9: =SUBTOTAL(3,$B$2:B9) -> 8 | B9: 46143 | C9: VT | D9: CP liên quan đến khấu hao PT | E9: Mua xe trung chuyển | F9: CP mua xe mới | G9: Mua 1 lần, tính khấu hao hàng tháng | H9: 29K00192 | I9: Ford | K9: 45408 | L9: 7.75808e+08 | M9: 60 | N9: =IF(B9>O9,"",L9/M9) -> 12930133 | O9: =EDATE(K9, M9-1) -> 47203
A10: =SUBTOTAL(3,$B$2:B10) -> 9 | B10: 46143 | C10: VT | D10: CP liên quan đến khấu hao PT | E10: CP mua BH | F10: BH vật chất và BH TNDS | G10: Mua 1 lần, tính khấu hao hàng tháng | H10: 29B19481 | I10: Vf6 | K10: 46081 | L10: 7365700 | M10: 12 | N10: =IF(B10>O10,"",L10/M10) -> 613808.33 | O10: =EDATE(K10, M10-1) -> 46415
A11: =SUBTOTAL(3,$B$2:B11) -> 10 | B11: 46143 | C11: VT | D11: CP liên quan đến khấu hao PT | E11: CP mua BH | F11: BH vật chất và BH TNDS | G11: Mua 1 lần, tính khấu hao hàng tháng | H11: 29B30465 | I11: Vf6 | K11: 46082 | L11: 7365700 | M11: 12 | N11: =IF(B11>O11,"",L11/M11) -> 613808.33 | O11: =EDATE(K11, M11-1) -> 46419
A12: =SUBTOTAL(3,$B$2:B12) -> 11 | B12: 46143 | C12: VT | D12: CP liên quan đến khấu hao PT | E12: CP mua BH | F12: BH vật chất và BH TNDS | G12: Mua 1 lần, tính khấu hao hàng tháng | H12: 29H02773 | I12: Vf6 | K12: 46081 | L12: 7365700 | M12: 12 | N12: =IF(B12>O12,"",L12/M12) -> 613808.33 | O12: =EDATE(K12, M12-1) -> 46415
A13: =SUBTOTAL(3,$B$2:B13) -> 12 | B13: 46143 | C13: VT | D13: CP liên quan đến khấu hao PT | E13: CP mua BH | F13: BH vật chất và BH TNDS | G13: Mua 1 lần, tính khấu hao hàng tháng | H13: 30M36244 | I13: Vf6 | K13: 45870 | L13: 7365700 | M13: 12 | N13: =IF(B13>O13,"",L13/M13) -> 613808.33 | O13: =EDATE(K13, M13-1) -> 46204
... A53: =SUBTOTAL(3,$B$2:B53) -> 52 | B53: 46143 | C53: VT | D53: CP liên quan đến khấu hao PT | E53: Mua thiết bị lắp thêm | F53: Mua sim 5G | G53: Mua 1 lần, tính khấu hao hàng tháng | H53: 29K00192 | I53: Ford | K53: 46143 | L53: 700000 | M53: 12 | N53: =IF(B53>O53,"",L53/M53) -> 58333.333 | O53: =EDATE(K53, M53-1) -> 46478
A54: =SUBTOTAL(3,$B$2:B54) -> 53 | B54: 46143 | C54: VT | D54: CP mua sắm TTB VP | E54: Trang thiết bị VP | F54: Chi phí cước mạng internet VP Việt trì 13 tháng từ 01/7/2025-31/7/2026 | G54: Mua 1 lần, tính khấu hao hàng tháng | K54: 45839 | L54: 276923.08 | M54: 13 | N54: =IF(B54>O54,"",L54/M54) -> 21301.775 | O54: =EDATE(K54, M54-1) -> 46204
A55: =SUBTOTAL(3,$B$2:B55) -> 54 | B55: 46143 | C55: VT | D55: CP BD, SC trích trước | E55: BD, SC PT | F55: CP thay dầu, nhớt | G55: CP trích trước hàng tháng | H55: 29K01796 | I55: Ford | J55: 3036 | K55: 46143 | L55: =J55*SUMIFS('Đơn giá SCBD'!F:F,'Đơn giá SCBD'!A:A,'Chi tiết'!F55,'Đơn giá SCBD'!B:B,'Chi tiết'!I55) -> 389367 | M55: 1 | N55: =IF(B55>O55,"",L55/M55) -> 389367 | O55: 46143
A56: =SUBTOTAL(3,$B$2:B56) -> 55 | B56: 46143 | C56: VT | D56: CP BD, SC trích trước | E56: BD, SC PT | F56: CP thay dầu, nhớt | G56: CP trích trước hàng tháng | H56: 29K00192 | I56: Ford | J56: 2528 | K56: 46143 | L56: =J56*SUMIFS('Đơn giá SCBD'!F:F,'Đơn giá SCBD'!A:A,'Chi tiết'!F56,'Đơn giá SCBD'!B:B,'Chi tiết'!I56) -> 324216 | M56: 1 | N56: =IF(B56>O56,"",L56/M56) -> 324216 | O56: 46143
A57: =SUBTOTAL(3,$B$2:B57) -> 56 | B57: 46143 | C57: VT | D57: CP BD, SC trích trước | E57: BD, SC PT | F57: CP thay lốp | G57: CP trích trước hàng tháng | H57: 29B19481 | I57: Vf6 | J57: 4312 | K57: 46143 | L57: =J57*SUMIFS('Đơn giá SCBD'!F:F,'Đơn giá SCBD'!A:A,'Chi tiết'!F57,'Đơn giá SCBD'!B:B,'Chi tiết'!I57) -> 776160 | M57: 1 | N57: =IF(B57>O57,"",L57/M57) -> 776160 | O57: 46143
A58: =SUBTOTAL(3,$B$2:B58) -> 57 | B58: 46143 | C58: VT | D58: CP BD, SC trích trước | E58: BD, SC PT | F58: CP thay lốp | G58: CP trích trước hàng tháng | H58: 29B30465 | I58: Vf6 | J58: 5142 | K58: 46143 | L58: =J58*SUMIFS('Đơn giá SCBD'!F:F,'Đơn giá SCBD'!A:A,'Chi tiết'!F58,'Đơn giá SCBD'!B:B,'Chi tiết'!I58) -> 925560 | M58: 1 | N58: =IF(B58>O58,"",L58/M58) -> 925560 | O58: 46143
A59: =SUBTOTAL(3,$B$2:B59) -> 58 | B59: 46143 | C59: VT | D59: CP BD, SC trích trước | E59: BD, SC PT | F59: CP thay lốp | G59: CP trích trước hàng tháng | H59: 29H02773 | I59: Vf6 | J59: 4990 | K59: 46143 | L59: =J59*SUMIFS('Đơn giá SCBD'!F:F,'Đơn giá SCBD'!A:A,'Chi tiết'!F59,'Đơn giá SCBD'!B:B,'Chi tiết'!I59) -> 898200 | M59: 1 | N59: =IF(B59>O59,"",L59/M59) -> 898200 | O59: 46143
A60: =SUBTOTAL(3,$B$2:B60) -> 59 | B60: 46143 | C60: VT | D60: CP BD, SC trích trước | E60: BD, SC PT | F60: CP thay lốp | G60: CP trích trước hàng tháng | H60: 30M36244 | I60: Vf6 | J60: 5511 | K60: 46143 | L60: =J60*SUMIFS('Đơn giá SCBD'!F:F,'Đơn giá SCBD'!A:A,'Chi tiết'!F60,'Đơn giá SCBD'!B:B,'Chi tiết'!I60) -> 991980 | M60: 1 | N60: =IF(B60>O60,"",L60/M60) -> 991980 | O60: 46143
A61: =SUBTOTAL(3,$B$2:B61) -> 60 | B61: 46143 | C61: VT | D61: CP BD, SC trích trước | E61: BD, SC PT | F61: CP thay lốp | G61: CP trích trước hàng tháng | H61: 30M36207 | I61: Vf6 | J61: 750.02 | K61: 46143 | L61: =J61*SUMIFS('Đơn giá SCBD'!F:F,'Đơn giá SCBD'!A:A,'Chi tiết'!F61,'Đơn giá SCBD'!B:B,'Chi tiết'!I61) -> 135003.6 | M61: 1 | N61: =IF(B61>O61,"",L61/M61) -> 135003.6 | O61: 46143
A62: =SUBTOTAL(3,$B$2:B62) -> 61 | B62: 46143 | C62: VT | D62: CP BD, SC trích trước | E62: BD, SC PT | F62: CP thay lốp | G62: CP trích trước hàng tháng | H62: 30M36240 | I62: Vf6 | J62: 5356 | K62: 46143 | L62: =J62*SUMIFS('Đơn giá SCBD'!F:F,'Đơn giá SCBD'!A:A,'Chi tiết'!F62,'Đơn giá SCBD'!B:B,'Chi tiết'!I62) -> 964080 | M62: 1 | N62: =IF(B62>O62,"",L62/M62) -> 964080 | O62: 46143
A63: =SUBTOTAL(3,$B$2:B63) -> 62 | B63: 46143 | C63: VT | D63: CP BD, SC trích trước | E63: BD, SC PT | F63: CP thay lốp | G63: CP trích trước hàng tháng | H63: 29K01796 | I63: Ford | J63: 3036 | K63: 46143 | L63: =J63*SUMIFS('Đơn giá SCBD'!F:F,'Đơn giá SCBD'!A:A,'Chi tiết'!F63,'Đơn giá SCBD'!B:B,'Chi tiết'!I63) -> 319994.4 | M63: 1 | N63: =IF(B63>O63,"",L63/M63) -> 319994.4 | O63: 46143
A64: =SUBTOTAL(3,$B$2:B64) -> 63 | B64: 46143 | C64: VT | D64: CP BD, SC trích trước | E64: BD, SC PT | F64: CP thay lốp | G64: CP trích trước hàng tháng | H64: 29K00192 | I64: Ford | J64: 2528 | K64: 46143 | L64: =J64*SUMIFS('Đơn giá SCBD'!F:F,'Đơn giá SCBD'!A:A,'Chi tiết'!F64,'Đơn giá SCBD'!B:B,'Chi tiết'!I64) -> 266451.2 | M64: 1 | N64: =IF(B64>O64,"",L64/M64) -> 266451.2 | O64: 46143
A65: =SUBTOTAL(3,$B$2:B65) -> 64 | B65: 46143 | C65: VT | D65: CP BD, SC trích trước | E65: BD, SC PT | F65: CP thay ắc quy | G65: CP trích trước hàng tháng | H65: 29B19481 | I65: Vf6 | J65: 4312 | K65: 46143 | L65: =J65*SUMIFS('Đơn giá SCBD'!F:F,'Đơn giá SCBD'!A:A,'Chi tiết'!F65,'Đơn giá SCBD'!B:B,'Chi tiết'!I65) -> 79772 | M65: 1 | N65: =IF(B65>O65,"",L65/M65) -> 79772 | O65: 46143
A66: =SUBTOTAL(3,$B$2:B66) -> 65 | B66: 46143 | C66: VT | D66: CP BD, SC trích trước | E66: BD, SC PT | F66: CP thay ắc quy | G66: CP trích trước hàng tháng | H66: 29B30465 | I66: Vf6 | J66: 5142 | K66: 46143 | L66: =J66*SUMIFS('Đơn giá SCBD'!F:F,'Đơn giá SCBD'!A:A,'Chi tiết'!F66,'Đơn giá SCBD'!B:B,'Chi tiết'!I66) -> 95127 | M66: 1 | N66: =IF(B66>O66,"",L66/M66) -> 95127 | O66: 46143
... A80: =SUBTOTAL(3,$B$2:B80) -> 79 | B80: 46143 | C80: VT | D80: CP BD, SC trích trước | E80: BD, SC PT | F80: CP bảo dưỡng | G80: CP trích trước hàng tháng | H80: 29K00192 | I80: Ford | J80: 2528 | K80: 46143 | L80: =J80*SUMIFS('Đơn giá SCBD'!F:F,'Đơn giá SCBD'!A:A,'Chi tiết'!F80,'Đơn giá SCBD'!B:B,'Chi tiết'!I80) -> 653747.54 | M80: 1 | N80: =IF(B80>O80,"",L80/M80) -> 653747.54 | O80: 46143
A81: =SUBTOTAL(3,$B$2:B81) -> 80 | B81: 46143 | C81: VT | D81: CP năng lượng/ nhiên liệu | E81: Tiền dầu | F81: Tiền dầu | G81: CP phát sinh hàng tháng | H81: 29K01796 | I81: Ford | K81: 46143 | L81: 1702020 | M81: 1 | N81: =IF(B81>O81,"",L81/M81) -> 1702020 | O81: 46143
A82: =SUBTOTAL(3,$B$2:B82) -> 81 | B82: 46143 | C82: VT | D82: CP năng lượng/ nhiên liệu | E82: Tiền dầu | F82: Tiền dầu | G82: CP phát sinh hàng tháng | H82: 29K01796 | I82: Ford | K82: 46145 | L82: 1612768 | M82: 1 | N82: =IF(B82>O82,"",L82/M82) -> 1612768 | O82: 46143
A83: =SUBTOTAL(3,$B$2:B83) -> 82 | B83: 46143 | C83: VT | D83: CP năng lượng/ nhiên liệu | E83: Tiền dầu | F83: Tiền dầu | G83: CP phát sinh hàng tháng | H83: 29K00192 | I83: Ford | K83: 46150 | L83: 1516928 | M83: 1 | N83: =IF(B83>O83,"",L83/M83) -> 1516928 | O83: 46143
A84: =SUBTOTAL(3,$B$2:B84) -> 83 | B84: 46143 | C84: VT | D84: CP năng lượng/ nhiên liệu | E84: Tiền dầu | F84: Tiền dầu | G84: CP phát sinh hàng tháng | H84: 29K01796 | I84: Ford | K84: 46153 | L84: 1925395 | M84: 1 | N84: =IF(B84>O84,"",L84/M84) -> 1925395 | O84: 46143
A85: =SUBTOTAL(3,$B$2:B85) -> 84 | B85: 46143 | C85: VT | D85: CP năng lượng/ nhiên liệu | E85: Tiền dầu | F85: Tiền dầu | G85: CP phát sinh hàng tháng | H85: 29K00192 | I85: Ford | K85: 46154 | L85: 1605954 | M85: 1 | N85: =IF(B85>O85,"",L85/M85) -> 1605954 | O85: 46143
A86: =SUBTOTAL(3,$B$2:B86) -> 85 | B86: 46143 | C86: VT | D86: CP năng lượng/ nhiên liệu | E86: Tiền dầu | F86: Tiền dầu | G86: CP phát sinh hàng tháng | H86: 29K00192 | I86: Ford | K86: 46160 | L86: 1733487 | M86: 1 | N86: =IF(B86>O86,"",L86/M86) -> 1733487 | O86: 46143
A87: =SUBTOTAL(3,$B$2:B87) -> 86 | B87: 46143 | C87: VT | D87: CP năng lượng/ nhiên liệu | E87: Tiền dầu | F87: Tiền dầu | G87: CP phát sinh hàng tháng | H87: 29K01796 | I87: Ford | K87: 46160 | L87: 1849047 | M87: 1 | N87: =IF(B87>O87,"",L87/M87) -> 1849047 | O87: 46143
A88: =SUBTOTAL(3,$B$2:B88) -> 87 | B88: 46143 | C88: VT | D88: CP năng lượng/ nhiên liệu | E88: Tiền dầu | F88: Tiền dầu | G88: CP phát sinh hàng tháng | H88: 29K00192 | I88: Ford | K88: 46165 | L88: 1767351 | M88: 1 | N88: =IF(B88>O88,"",L88/M88) -> 1767351 | O88: 46143
A89: =SUBTOTAL(3,$B$2:B89) -> 88 | B89: 46143 | C89: VT | D89: CP năng lượng/ nhiên liệu | E89: Tiền dầu | F89: Tiền dầu | G89: CP phát sinh hàng tháng | H89: 29K01796 | I89: Ford | K89: 46165 | L89: 1767656 | M89: 1 | N89: =IF(B89>O89,"",L89/M89) -> 1767656 | O89: 46143
A90: =SUBTOTAL(3,$B$2:B90) -> 89 | B90: 46143 | C90: VT | D90: CP năng lượng/ nhiên liệu | E90: Tiền dầu | F90: Tiền dầu | G90: CP phát sinh hàng tháng | H90: 29K00192 | I90: Ford | K90: 46167 | L90: 1706929 | M90: 1 | N90: =IF(B90>O90,"",L90/M90) -> 1706929 | O90: 46143
A91: =SUBTOTAL(3,$B$2:B91) -> 90 | B91: 46143 | C91: VT | D91: CP năng lượng/ nhiên liệu | E91: Tiền dầu | F91: Tiền dầu | G91: CP phát sinh hàng tháng | H91: 29K01796 | I91: Ford | K91: 46171 | L91: 1818460 | M91: 1 | N91: =IF(B91>O91,"",L91/M91) -> 1818460 | O91: 46143
A92: =SUBTOTAL(3,$B$2:B92) -> 91 | B92: 46143 | C92: VT | D92: CP năng lượng/ nhiên liệu | E92: Tiền dầu | F92: Tiền dầu | G92: CP phát sinh hàng tháng | H92: 29K00192 | I92: Ford | K92: 46172 | L92: 1495830 | M92: 1 | N92: =IF(B92>O92,"",L92/M92) -> 1495830 | O92: 46143
...

Sheet Đơn giá SCBD
A1: Stt | B1: Khoản mục | C1: Định mức thay/trích trước | D1: Đơn giá (đồng) | E1: Định ngạch sử dụng (km) | F1: Đơn giá chi phí (đ/km)
A2: CP thay dầu, nhớt | B2: Ford | C2: 9.5 | D2: 135000 | E2: 10000 | F2: =C2*D2/E2 -> 128.25
A3: CP thay dầu, nhớt | B3: Solati | C3: 7.5 | D3: 135000 | E3: 10000 | F3: =C3*D3/E3 -> 101.25
A4: CP thay dầu, nhớt | B4: Suzu | C4: 4 | D4: 140000 | E4: 10000 | F4: =C4*D4/E4 -> 56
A5: CP thay dầu, nhớt | B5: Vf6 | C5: 0
A6: CP thay lốp | B6: Ford | C6: 4 | D6: 2635000 | E6: 100000 | F6: =C6*D6/E6 -> 105.4 | G6: Lốp theo xe
A7: CP thay lốp | B7: Solati | C7: 4 | D7: 2635000 | E7: 100000 | F7: =C7*D7/E7 -> 105.4 | G7: Bridgestone
A8: CP thay lốp | B8: Suzu | C8: 4 | D8: 1360000 | E8: 80000 | F8: =C8*D8/E8 -> 68
A9: CP thay lốp | B9: Vf6 | C9: 4 | D9: 3600000 | E9: 80000 | F9: =C9*D9/E9 -> 180
A10: CP thay ắc quy | B10: Ford | C10: 1 | D10: 1850000 | E10: 100000 | F10: =C10*D10/E10 -> 18.5
A11: CP thay ắc quy | B11: Solati | C11: 1 | D11: 2950000 | E11: 100000 | F11: =C11*D11/E11 -> 29.5
A12: CP thay ắc quy | B12: Suzu | C12: 1 | D12: 1650000 | E12: 100000 | F12: =C12*D12/E12 -> 16.5
A13: CP thay ắc quy | B13: Vf6 | C13: 1 | D13: 1850000 | E13: 100000 | F13: =C13*D13/E13 -> 18.5
A14: CP bảo dưỡng | B14: Ford | C14: 0.1 | D14: 12930133 | E14: 5000 | F14: =D14*C14/E14 -> 258.60267
A15: CP bảo dưỡng | B15: Solati | C15: 0.1 | D15: 12930133 | E15: 5000 | F15: =D15*C15/E15 -> 258.60267
A16: CP bảo dưỡng | B16: Suzu | C16: 0.08 | D16: 12930133 | E16: 5000 | F16: =D16*C16/E16 -> 206.88213
A17: CP bảo dưỡng | B17: Vf6 | C17: 0.05 | D17: 11590909 | E17: 5000 | F17: =D17*C17/E17 -> 115.90909

Sheet Doanh thu CN
A1: THÁNG | B1: TỈNH | C1: SẢN LƯỢNG HK | D1: SỐ KHÁCH NỘI BỘ | E1: SỐ KHÁCH HUỶ | F1: SỐ KHÁCH HĐ NGUYÊN CHUYẾN | G1: SẢN LƯỢNG HK THỰC TẾ | H1: SỐ LƯỢNG PHƯƠNG TIỆN QUẢN LÝ
A2: ='Tóm tắt CP'!B1 -> 46143 | B2: VT | C2: 12230 | D2: 61 | E2: 42 | F2: 122 | G2: =C2-D2-E2-F2 -> 12005 | H2: 26
